Workbook

Sheet 目   錄
A1: 2017年綜合報表目錄
A2: 序號 | B2: 項目 | C2: 備注
A3: 1 | B3: 1.月份產能總表
A4: 2 | B4: 2.1年度品牌報表
B5: 2.2月份預計出貨數量
A6: 3 | B6: 3-1.人員刷卡出勤
B7: 3.2.A1廠人均時產能-針車
B8: 3.3.A2廠人均時產能-針車
B9: 3.4.A1廠人均時產能-成型
B10: 3.5.A2廠人均時產能-成型
B11: 3.6.A廠總計產能
B12: 3.7.A廠人員分攤POH產能
A13: 5 | B13: 5.1.全廠線均產能

Sheet 1.月份產能總表
A1: 回到首頁
A2: 2017年度04月份產量達成狀況明細表
A3: 單位項目 | C3: 總計 | D3: 日類計 | E3: 日平均 | F3: 1 | G3: 2 | H3: 3 | I3: 4 | J3: 5 | K3: 6 | L3: 7 | M3: 8 | N3: 9 | O3: 10 | P3: 11 | Q3: 12 | R3: 13 | S3: 14 | T3: 15 | U3: 16 | V3: 17 | W3: 18 | X3: 19 | Y3: 20 | Z3: 21 | AA3: 22 | AB3: 23 | AC3: 24 | AD3: 25 | AE3: 26 | AF3: 27 | AG3: 28 | AH3: 29 | AI3: 30
A4: A1廠成型 | B4: 標準產量 | C4: 170576 | D4: 170576 | E4: 28429.3 | H4: 28872 | I4: 28928 | J4: 28776 | L4: 28624 | M4: 28656 | O4: 26720
B5: 目標產量 | C5: 158952 | D5: 183884 | E5: 26492 | H5: 26992 | I5: 26992 | J5: 26992 | L5: 26992 | M5: 26332 | O5: 24652 | P5: 24932 | Q5: 25232 | R5: 24952 | S5: 24572 | T5: 24632 | V5: 25232 | W5: 25232 | X5: 25232 | Y5: 25112 | Z5: 25112 | AC5: 25132 | AD5: 24952 | AE5: 25632 | AF5: 25972 | AG5: 26352
B6: 實際產量 | C6: 153270 | D6: 153270 | E6: 25545 | H6: 26908 | I6: 25457 | J6: 25758 | L6: 26588 | M6: 25624 | O6: 22935
B7: 目標與實際差異 | C7: -5682 | D7: -30614 | E7: -947 | H7: -84 | I7: -1535 | J7: -1234 | L7: -404 | M7: -708 | O7: -1717
B8: 標準與實際差異 | C8: -17306 | D8: -17306 | E8: -2884.3 | H8: -1964 | I8: -3471 | J8: -3018 | L8: -2036 | M8: -3032 | O8: -3785
B9: 目標與實際達成率 | C9: 96 | D9: 83 | E9: 96 | H9: 99 | I9: 94 | J9: 95 | L9: 98 | M9: 97 | O9: 93 | P9: 0 | Q9: 0 | R9: 0 | S9: 0 | T9: 0 | V9: 0 | W9: 0 | X9: 0 | Y9: 0 | Z9: 0 | AC9: 0 | AD9: 0 | AE9: 0 | AF9: 0 | AG9: 0
B10: 標準與實際達成率 | C10: 89 | D10: 89 | E10: 89 | H10: 93 | I10: 88 | J10: 89 | L10: 92 | M10: 89 | O10: 85
A11: A2廠成型 | B11: 標準產量 | C11: 157648 | D11: 157648 | E11: 26274.7 | H11: 26736 | I11: 26576 | J11: 26560 | L11: 26544 | M11: 26528 | O11: 24704
B12: 目標產量 | C12: 145740 | D12: 168420 | E12: 24290 | H12: 24240 | I12: 25360 | J12: 24460 | L12: 24370 | M12: 24710 | O12: 22600 | P12: 22680 | Q12: 23040 | R12: 23160 | S12: 23160 | T12: 22800 | V12: 22600 | W12: 22100 | X12: 22160 | Y12: 23000 | Z12: 23420 | AC12: 23300 | AD12: 23780 | AE12: 24260 | AF12: 24040 | AG12: 24040
B13: 實際產量 | C13: 142075 | D13: 142075 | E13: 23679.2 | H13: 24248 | I13: 25090 | J13: 22585 | L13: 23810 | M13: 24162 | O13: 22180
B14: 目標與實際差異 | C14: -3665 | D14: -26345 | E14: -610.8 | H14: 8 | I14: -270 | J14: -1875 | L14: -560 | M14: -548 | O14: -420
B15: 標準與實際差異 | C15: -15573 | D15: -15573 | E15: -2595.5 | H15: -2488 | I15: -1486 | J15: -3975 | L15: -2734 | M15: -2366 | O15: -2524
B16: 目標與實際達成率 | C16: 97 | D16: 84 | E16: 97 | H16: 100 | I16: 98 | J16: 92 | L16: 97 | M16: 97 | O16: 98 | P16: 0 | Q16: 0 | R16: 0 | S16: 0 | T16: 0 | V16: 0 | W16: 0 | X16: 0 | Y16: 0 | Z16: 0 | AC16: 0 | AD16: 0 | AE16: 0 | AF16: 0 | AG16: 0
B17: 標準與實際達成率 | C17: 90 | D17: 90 | E17: 90 | H17: 90 | I17: 94 | J17: 85 | L17: 89 | M17: 91 | O17: 89
A18: A1.2廠樣品室 | B18: 標準產量 | C18: 0 | D18: 0 | E18: 0
B19: 目標產量 | C19: 0 | D19: 0 | E19: 0
B20: 實際產量 | C20: 1236 | D20: 1236 | E20: 412 | J20: 480 | L20: 384 | M20: 372
B21: 目標與實際差異 | C21: 1236 | D21: 0 | E21: 412
B22: 標準與實際差異 | C22: 1236 | D22: 1236 | E22: 412 | J22: 480 | L22: 384 | M22: 372
B23: 目標與實際達成率 | C23: 0 | D23: 0 | E23: 0
B24: 標準與實際達成率 | C24: 0 | D24: 0 | E24: 0
A25: A廠區小計 | B25: 標準產量 | C25: 328224 | D25: 328224 | E25: 54704 | H25: 55608 | I25: 55504 | J25: 55336 | L25: 55168 | M25: 55184 | O25: 51424
B26: 目標產量 | C26: 304692 | D26: 352304 | E26: 50782 | H26: 51232 | I26: 52352 | J26: 51452 | L26: 51362 | M26: 51042 | O26: 47252 | P26: 47612 | Q26: 48272 | R26: 48112 | S26: 47732 | T26: 47432 | V26: 47832 | W26: 47332 | X26: 47392 | Y26: 48112 | Z26: 48532 | AC26: 48432 | AD26: 48732 | AE26: 49892 | AF26: 50012 | AG26: 50392
B27: 實際產量 | C27: 296581 | D27: 296581 | E27: 49636.2 | H27: 51156 | I27: 50547 | J27: 48823 | L27: 50782 | M27: 50158 | O27: 45115
B28: 目標與實際差異 | C28: -8111 | D28: -55723 | E28: -1145.8 | H28: -76 | I28: -1805 | J28: -2629 | L28: -580 | M28: -884 | O28: -2137
B29: 標準與實際差異 | C29: -31643 | D29: -31643 | E29: -5067.8 | H29: -4452 | I29: -4957 | J29: -6513 | L29: -4386 | M29: -5026 | O29: -6309
B30: 目標與實際達成率 | C30: 97 | D30: 84 | E30: 97 | H30: 99 | I30: 96 | J30: 94 | L30: 98 | M30: 98 | O30: 95 | P30: 0 | Q30: 0 | R30: 0 | S30: 0 | T30: 0 | V30: 0 | W30: 0 | X30: 0 | Y30: 0 | Z30: 0 | AC30: 0 | AD30: 0 | AE30: 0 | AF30: 0 | AG30: 0
B31: 標準與實際達成率 | C31: 90 | D31: 90 | E31: 90 | H31: 91 | I31: 91 | J31: 88 | L31: 92 | M31: 90 | O31: 87

Sheet 2.1年度品牌報表
A1: 回到首頁
A2: 2017年度品牌接單生產報表-每天更新（以月份訂單統計）
A3: 品牌 | B3: 項目 | C3: 01月 | D3: 02月 | E3: 03月 | F3: 04月 | G3: 05月 | H3: 06月 | I3: 07月 | J3: 08月 | K3: 09月 | L3: 10月 | M3: 11月 | N3: 12月 | O3: 小計
A4: CONS外銷 | B4: 接單雙數 | C4: 923173 | D4: 930123 | E4: 1181962 | F4: 2090296 | G4: 1346198 | H4: 826167 | I4: 375480 | J4: 37086 | K4: 0 | L4: 0 | M4: 0 | N4: 0 | O4: 7710485
B5: 完成雙數 | C5: 126310 | D5: 225104 | E5: 82504 | F5: 218346 | G5: 0 | H5: 0 | I5: 0 | J5: 0 | K5: 0 | L5: 0 | M5: 0 | N5: 0 | O5: 652264
B6: 提前生產 | C6: 796863 | D6: 705019 | E6: 1099458 | F6: 1675811 | G6: 309712 | H6: 31499 | I6: 0 | J6: 0 | K6: 0 | L6: 0 | M6: 0 | N6: 0 | O6: 4618362
B7: 欠數 | C7: 0 | D7: 0 | E7: 0 | F7: 196139 | G7: 1036486 | H7: 794668 | I7: 375480 | J7: 37086 | K7: 0 | L7: 0 | M7: 0 | N7: 0 | O7: 2439859
A8: CONS內銷 | B8: 接單雙數 | C8: 14280 | D8: 14520 | E8: 960 | F8: 7620 | G8: 16140 | H8: 11160 | I8: 16860 | J8: 0 | K8: 0 | L8: 0 | M8: 0 | N8: 0 | O8: 81540
B9: 完成雙數 | C9: 1847 | D9: 1164 | E9: 960 | F9: 0 | G9: 0 | H9: 0 | I9: 0 | J9: 0 | K9: 0 | L9: 0 | M9: 0 | N9: 0 | O9: 3971
B10: 提前生產 | C10: 12433 | D10: 13169 | E10: 0 | F10: 7620 | G10: 10320 | H10: 0 | I10: 0 | J10: 0 | K10: 0 | L10: 0 | M10: 0 | N10: 0 | O10: 43542
B11: 欠數 | C11: 0 | D11: 187 | E11: 0 | F11: 0 | G11: 5820 | H11: 11160 | I11: 16860 | J11: 0 | K11: 0 | L11: 0 | M11: 0 | N11: 0 | O11: 34027
A13: 備註：

Sheet 2.2月份預計出貨數量
A1: 回到首頁
A2: 各品牌月份預計出貨
A3: 4月份 | B3: 出貨階段 | C3: Total | D3: 1 | E3: 3 | F3: 4 | G3: 5 | H3: 6 | I3: 7 | J3: 8 | K3: 9 | L3: 10 | M3: 11 | N3: 12 | O3: 13 | P3: 14 | Q3: 15 | R3: 16 | S3: 17 | T3: 18 | U3: 19 | V3: 20 | W3: 21 | X3: 22 | Y3: 24 | Z3: 25 | AA3: 26 | AB3: 28 | AC3: 29 | AD3: 30
B4: 客人
A5: Converse | B5: 預計出貨數 | C5: 2097929 | D5: 141819 | E5: 40500 | F5: 45432 | G5: 244848 | H5: 31920 | I5: 128076 | J5: 29700 | K5: 3600 | L5: 319876 | M5: 744 | N5: 7764 | O5: 2556 | P5: 73414 | Q5: 20285 | R5: 122280 | S5: 67956 | T5: 25500 | U5: 46553 | V5: 2868 | W5: 52809 | X5: 25380 | Y5: 161448 | Z5: 36864 | AA5: 358060 | AB5: 42781 | AC5: 58452 | AD5: 6444
B6: 實際出貨數 | C6: 324136 | E6: 98976 | F6: 27780 | I6: 49276 | J6: 5148 | L6: 136860 | M6: 6096
B7: 差異數 | C7: 240192 | E7: -58476 | F7: 17652 | I7: 78800 | J7: 24552 | L7: 183016 | M7: -5352

Sheet 3-1.人員刷卡出勤
A1: 回到首頁
A2: 04月人事刷卡出勤報表
A3: 廠別 | B3: 項目 | C3: 1 | D3: 2 | E3: 3 | F3: 4 | G3: 5 | H3: 6 | I3: 7 | J3: 8 | K3: 9 | L3: 10 | M3: 11 | N3: 12 | O3: 13 | P3: 14 | Q3: 15 | R3: 16 | S3: 17 | T3: 18 | U3: 19 | V3: 20 | W3: 21 | X3: 22 | Y3: 23 | Z3: 24 | AA3: 25 | AB3: 26 | AC3: 27 | AD3: 28 | AE3: 29 | AF3: 30
A4: 總計 | B4: 刷卡總數 | C4: 10227 | D4: 66 | E4: 19802 | F4: 19861 | G4: 18949 | H4: 62 | I4: 19543 | J4: 19636 | K4: 76 | L4: 19464
B5: 刷卡直工 | C5: 8251 | D5: 0 | E5: 16539 | F5: 16586 | G5: 15846 | H5: 0 | I5: 16322 | J5: 16433 | K5: 0 | L5: 16286
B6: 刷卡間工 | C6: 1976 | D6: 66 | E6: 3263 | F6: 3275 | G6: 3103 | H6: 62 | I6: 3221 | J6: 3203 | K6: 76 | L6: 3178
A7: 總公司 | B7: 刷卡總數 | C7: 348 | D7: 66 | E7: 406 | F7: 408 | G7: 391 | H7: 62 | I7: 403 | J7: 396 | K7: 76 | L7: 395
B8: 刷卡直工 | C8: 1 | D8: 0 | E8: 1 | F8: 1 | G8: 1 | H8: 0 | I8: 1 | J8: 1 | K8: 0 | L8: 1
B9: 刷卡間工 | C9: 347 | D9: 66 | E9: 405 | F9: 407 | G9: 390 | H9: 62 | I9: 402 | J9: 395 | K9: 76 | L9: 394
A10: R3 | B10: 刷卡總數 | C10: 0 | D10: 0 | E10: 563 | F10: 566 | G10: 391 | H10: 0 | I10: 553 | J10: 557 | K10: 0 | L10: 556
B11: 刷卡直工 | C11: 0 | D11: 0 | E11: 440 | F11: 443 | G11: 295 | H11: 0 | I11: 433 | J11: 435 | K11: 0 | L11: 434
B12: 刷卡間工 | C12: 0 | D12: 0 | E12: 123 | F12: 123 | G12: 96 | H12: 0 | I12: 120 | J12: 122 | K12: 0 | L12: 122
A13: R2 | B13: 刷卡總數 | C13: 0 | D13: 0 | E13: 242 | F13: 239 | G13: 173 | H13: 0 | I13: 241 | J13: 239 | K13: 0 | L13: 242
B14: 刷卡直工 | C14: 0 | D14: 0 | E14: 194 | F14: 191 | G14: 133 | H14: 0 | I14: 194 | J14: 192 | K14: 0 | L14: 194
B15: 刷卡間工 | C15: 0 | D15: 0 | E15: 48 | F15: 48 | G15: 40 | H15: 0 | I15: 47 | J15: 47 | K15: 0 | L15: 48
A16: R1 | B16: 刷卡總數 | C16: 0 | D16: 0 | E16: 12 | F16: 13 | G16: 13 | H16: 0 | I16: 13 | J16: 13 | K16: 0 | L16: 12
B17: 刷卡直工 | C17: 0 | D17: 0 | E17: 12 | F17: 12 | G17: 12 | H17: 0 | I17: 12 | J17: 12 | K17: 0 | L17: 11
B18: 刷卡間工 | C18: 0 | D18: 0 | E18: 0 | F18: 1 | G18: 1 | H18: 0 | I18: 1 | J18: 1 | K18: 0 | L18: 1
A19: GC | B19: 刷卡總數 | C19: 0 | D19: 0 | E19: 407 | F19: 409 | G19: 397 | H19: 0 | I19: 402 | J19: 409 | K19: 0 | L19: 404
B20: 刷卡直工 | C20: 0 | D20: 0 | E20: 351 | F20: 353 | G20: 343 | H20: 0 | I20: 346 | J20: 350 | K20: 0 | L20: 347
B21: 刷卡間工 | C21: 0 | D21: 0 | E21: 56 | F21: 56 | G21: 54 | H21: 0 | I21: 56 | J21: 59 | K21: 0 | L21: 57
A22: BR2 | B22: 刷卡總數 | C22: 703 | D22: 0 | E22: 697 | F22: 706 | G22: 692 | H22: 0 | I22: 702 | J22: 720 | K22: 0 | L22: 715
B23: 刷卡直工 | C23: 678 | D23: 0 | E23: 671 | F23: 680 | G23: 666 | H23: 0 | I23: 678 | J23: 695 | K23: 0 | L23: 690
B24: 刷卡間工 | C24: 25 | D24: 0 | E24: 26 | F24: 26 | G24: 26 | H24: 0 | I24: 24 | J24: 25 | K24: 0 | L24: 25
A25: BR1 | B25: 刷卡總數 | C25: 21 | D25: 0 | E25: 21 | F25: 20 | G25: 22 | H25: 0 | I25: 22 | J25: 22 | K25: 0 | L25: 21
B26: 刷卡直工 | C26: 18 | D26: 0 | E26: 18 | F26: 18 | G26: 19 | H26: 0 | I26: 19 | J26: 19 | K26: 0 | L26: 18
B27: 刷卡間工 | C27: 3 | D27: 0 | E27: 3 | F27: 2 | G27: 3 | H27: 0 | I27: 3 | J27: 3 | K27: 0 | L27: 3
A28: BP | B28: 刷卡總數 | C28: 539 | D28: 0 | E28: 566 | F28: 570 | G28: 468 | H28: 0 | I28: 579 | J28: 574 | K28: 0 | L28: 576
B29: 刷卡直工 | C29: 503 | D29: 0 | E29: 531 | F29: 536 | G29: 442 | H29: 0 | I29: 546 | J29: 544 | K29: 0 | L29: 542
B30: 刷卡間工 | C30: 36 | D30: 0 | E30: 35 | F30: 34 | G30: 26 | H30: 0 | I30: 33 | J30: 30 | K30: 0 | L30: 34
A31: B7 | B31: 刷卡總數 | C31: 3208 | D31: 0 | E31: 3250 | F31: 3263 | G31: 3177 | H31: 0 | I31: 3197 | J31: 3209 | K31: 0 | L31: 3163
B32: 刷卡直工 | C32: 2914 | D32: 0 | E32: 2950 | F32: 2964 | G32: 2897 | H32: 0 | I32: 2897 | J32: 2912 | K32: 0 | L32: 2874
B33: 刷卡間工 | C33: 294 | D33: 0 | E33: 300 | F33: 299 | G33: 280 | H33: 0 | I33: 300 | J33: 297 | K33: 0 | L33: 289
A34: B6 | B34: 刷卡總數 | C34: 552 | D34: 0 | E34: 554 | F34: 553 | G34: 379 | H34: 0 | I34: 548 | J34: 545 | K34: 0 | L34: 548
B35: 刷卡直工 | C35: 507 | D35: 0 | E35: 508 | F35: 507 | G35: 345 | H35: 0 | I35: 503 | J35: 501 | K35: 0 | L35: 506
B36: 刷卡間工 | C36: 45 | D36: 0 | E36: 46 | F36: 46 | G36: 34 | H36: 0 | I36: 45 | J36: 44 | K36: 0 | L36: 42
A37: B5 | B37: 刷卡總數 | C37: 668 | D37: 0 | E37: 668 | F37: 669 | G37: 647 | H37: 0 | I37: 655 | J37: 665 | K37: 0 | L37: 660
B38: 刷卡直工 | C38: 629 | D38: 0 | E38: 628 | F38: 629 | G38: 608 | H38: 0 | I38: 614 | J38: 625 | K38: 0 | L38: 622
B39: 刷卡間工 | C39: 39 | D39: 0 | E39: 40 | F39: 40 | G39: 39 | H39: 0 | I39: 41 | J39: 40 | K39: 0 | L39: 38
A40: B1 | B40: 刷卡總數 | C40: 2806 | D40: 0 | E40: 2815 | F40: 2830 | G40: 2774 | H40: 0 | I40: 2783 | J40: 2797 | K40: 0 | L40: 2750
...

Sheet 3.2.A1廠人均時產能-針車
A1: 回到首頁
A2: 2017/04月針車人均時產能報表
A3: Lean線 | B3: 項目 | C3: 總計 | D3: 日平均 | E3: 1 | F3: 2 | G3: 3 | H3: 4 | I3: 5 | J3: 6 | K3: 7 | L3: 8 | M3: 9 | N3: 10 | O3: 11 | P3: 12 | Q3: 13 | R3: 14 | S3: 15 | T3: 16 | U3: 17 | V3: 18 | W3: 19 | X3: 20 | Y3: 21 | Z3: 22 | AA3: 23 | AB3: 24 | AC3: 25 | AD3: 26 | AE3: 27 | AF3: 28 | AG3: 29 | AH3: 30
A4: 總計 | B4: 標準產量 | C4: 170024 | D4: 28630.667 | G4: 28992 | H4: 28736 | I4: 28760 | K4: 28536 | L4: 28344 | N4: 26656
B5: 目標產量 | C5: 158952 | D5: 26772 | G5: 26992 | H5: 26992 | I5: 26992 | K5: 26992 | L5: 26332 | N5: 24652 | O5: 24932 | P5: 25232 | Q5: 24952 | R5: 24572 | S5: 24632 | U5: 25232 | V5: 25232 | W5: 25232 | X5: 25112 | Y5: 25112 | AB5: 25132 | AC5: 24952 | AD5: 25632 | AE5: 25972 | AF5: 26352
B6: 實際產量 | C6: 157379 | D6: 26482.433 | G6: 26604 | H6: 27007 | I6: 26470 | K6: 26979 | L6: 25798 | N6: 24521
B7: 差異 | C7: -1573 | D7: -289.56667 | G7: -388 | H7: 15 | I7: -522 | K7: -13 | L7: -534 | N7: -131
B8: 工時 | C8: 47.6 | D8: 8 | G8: 8 | H8: 8 | I8: 8 | K8: 8 | L8: 8 | N8: 8
B9: 直工人數 | C9: 1966 | D9: 1966 | G9: 1999 | H9: 2001 | I9: 1970 | K9: 1964 | L9: 1970 | N9: 1887
B10: 時產能 | C10: 3310.3042 | D10: 3310.3042 | G10: 3325.5 | H10: 3375.875 | I10: 3308.75 | K10: 3372.375 | L10: 3224.75 | N10: 3065.125
B11: 人均時產 | C11: 1.6837763 | D11: 1.6837763 | G11: 1.6635818 | H11: 1.687094 | I11: 1.6795685 | K11: 1.7170952 | L11: 1.6369289 | N11: 1.6243376
A12: A1_LEAN1-01_M | B12: 標準產量 | C12: 8160 | D12: 1360 | G12: 1360 | H12: 1360 | I12: 1360 | K12: 1360 | L12: 1360 | N12: 1360
B13: 目標產量 | C13: 8160 | D13: 1360 | G13: 1360 | H13: 1360 | I13: 1360 | K13: 1360 | L13: 1360 | N13: 1360 | O13: 1360 | P13: 1360 | Q13: 1360 | R13: 1360 | S13: 1360 | U13: 1360 | V13: 1360 | W13: 1360 | X13: 1360 | Y13: 1360 | AB13: 1360 | AC13: 1360 | AD13: 1360 | AE13: 1360 | AF13: 1360
B14: 實際產量 | C14: 8748 | D14: 1458 | G14: 1386 | H14: 1602 | I14: 1542 | K14: 1494 | L14: 1362 | N14: 1362
B15: 差異 | C15: 588 | D15: 98 | G15: 26 | H15: 242 | I15: 182 | K15: 134 | L15: 2 | N15: 2
B16: 工時 | C16: 48 | D16: 8 | G16: 8 | H16: 8 | I16: 8 | K16: 8 | L16: 8 | N16: 8
B17: 直工人數 | C17: 136 | D17: 136 | G17: 137 | H17: 137 | I17: 134 | K17: 138 | L17: 137 | N17: 136
B18: 時產能 | C18: 182.25 | D18: 182.25 | G18: 173.25 | H18: 200.25 | I18: 192.75 | K18: 186.75 | L18: 170.25 | N18: 170.25
B19: 人均時產 | C19: 1.3401 | D19: 1.3401 | G19: 1.2646 | H19: 1.4617 | I19: 1.4384 | K19: 1.3533 | L19: 1.2427 | N19: 1.2518
A20: A1_LEAN1-02_M | B20: 標準產量 | C20: 8640 | D20: 1440 | G20: 1440 | H20: 1440 | I20: 1440 | K20: 1440 | L20: 1440 | N20: 1440
B21: 目標產量 | C21: 8160 | D21: 1360 | G21: 1360 | H21: 1360 | I21: 1360 | K21: 1360 | L21: 1360 | N21: 1360 | O21: 1360 | P21: 1360 | Q21: 1080 | R21: 1080 | S21: 1440 | U21: 1440 | V21: 1440 | W21: 1440 | X21: 1440 | Y21: 1440 | AB21: 1440 | AC21: 1440 | AD21: 1440 | AE21: 1440 | AF21: 1440
B22: 實際產量 | C22: 8922 | D22: 1487 | G22: 1368 | H22: 1704 | I22: 1632 | K22: 1488 | L22: 1368 | N22: 1362
B23: 差異 | C23: 762 | D23: 127 | G23: 8 | H23: 344 | I23: 272 | K23: 128 | L23: 8 | N23: 2
B24: 工時 | C24: 48 | D24: 8 | G24: 8 | H24: 8 | I24: 8 | K24: 8 | L24: 8 | N24: 8
B25: 直工人數 | C25: 109 | D25: 109 | G25: 113 | H25: 113 | I25: 109 | K25: 108 | L25: 105 | N25: 107
B26: 時產能 | C26: 185.875 | D26: 185.875 | G26: 171 | H26: 213 | I26: 204 | K26: 186 | L26: 171 | N26: 170.25
B27: 人均時產 | C27: 1.7053 | D27: 1.7053 | G27: 1.5133 | H27: 1.885 | I27: 1.8716 | K27: 1.7222 | L27: 1.6286 | N27: 1.5911
A28: A1_LEAN1-03_M | B28: 標準產量 | C28: 8208 | D28: 1368 | G28: 1360 | H28: 1360 | I28: 1400 | K28: 1376 | L28: 1376 | N28: 1336
B29: 目標產量 | C29: 8160 | D29: 1360 | G29: 1360 | H29: 1360 | I29: 1360 | K29: 1360 | L29: 1360 | N29: 1360 | O29: 1360 | P29: 1360 | Q29: 1360 | R29: 1360 | S29: 1360 | U29: 1360 | V29: 1360 | W29: 1360 | X29: 1360 | Y29: 1360 | AB29: 1360 | AC29: 1360 | AD29: 1360 | AE29: 1360 | AF29: 1360
B30: 實際產量 | C30: 6864 | D30: 1144 | G30: 1368 | H30: 768 | I30: 906 | K30: 1098 | L30: 1362 | N30: 1362
B31: 差異 | C31: -1296 | D31: -216 | G31: 8 | H31: -592 | I31: -454 | K31: -262 | L31: 2 | N31: 2
B32: 工時 | C32: 48 | D32: 8 | G32: 8 | H32: 8 | I32: 8 | K32: 8 | L32: 8 | N32: 8
B33: 直工人數 | C33: 129 | D33: 129 | G33: 129 | H33: 129 | I33: 129 | K33: 130 | L33: 129 | N33: 129
B34: 時產能 | C34: 143 | D34: 143 | G34: 171 | H34: 96 | I34: 113.25 | K34: 137.25 | L34: 170.25 | N34: 170.25
B35: 人均時產 | C35: 1.1085 | D35: 1.1085 | G35: 1.3256 | H35: 0.7442 | I35: 0.8779 | K35: 1.0558 | L35: 1.3198 | N35: 1.3198
A36: A1_LEAN1-04_M | B36: 標準產量 | C36: 7680 | D36: 1280 | G36: 1280 | H36: 1280 | I36: 1280 | K36: 1280 | L36: 1280 | N36: 1280
B37: 目標產量 | C37: 7872 | D37: 1312 | G37: 1312 | H37: 1312 | I37: 1312 | K37: 1312 | L37: 1312 | N37: 1312 | O37: 1312 | P37: 1312 | Q37: 1312 | R37: 1312 | S37: 1312 | U37: 1312 | V37: 1312 | W37: 1312 | X37: 1312 | Y37: 1312 | AB37: 1312 | AC37: 1312 | AD37: 1312 | AE37: 1312 | AF37: 1312
B38: 實際產量 | C38: 7915 | D38: 1319.1667 | G38: 1326 | H38: 1326 | I38: 1314 | K38: 1320 | L38: 1314 | N38: 1315
B39: 差異 | C39: 43 | D39: 7.1666667 | G39: 14 | H39: 14 | I39: 2 | K39: 8 | L39: 2 | N39: 3
B40: 工時 | C40: 48 | D40: 8 | G40: 8 | H40: 8 | I40: 8 | K40: 8 | L40: 8 | N40: 8
...

Sheet 3.3.A2廠人均時產能-針車
A1: 回到首頁
A2: 2017/04月針車人均時產能報表
A3: Lean線 | B3: 項目 | C3: 總計 | D3: 日平均 | E3: 1 | F3: 2 | G3: 3 | H3: 4 | I3: 5 | J3: 6 | K3: 7 | L3: 8 | M3: 9 | N3: 10 | O3: 11 | P3: 12 | Q3: 13 | R3: 14 | S3: 15 | T3: 16 | U3: 17 | V3: 18 | W3: 19 | X3: 20 | Y3: 21 | Z3: 22 | AA3: 23 | AB3: 24 | AC3: 25 | AD3: 26 | AE3: 27 | AF3: 28 | AG3: 29 | AH3: 30
A4: 總計 | B4: 標準產量 | C4: 156928 | D4: 26448 | G4: 26336 | H4: 26736 | I4: 26744 | K4: 26512 | L4: 26240 | N4: 24360
B5: 目標產量 | C5: 145740 | D5: 24570 | G5: 24240 | H5: 25360 | I5: 24460 | K5: 24370 | L5: 24710 | N5: 22600 | O5: 22680 | P5: 23040 | Q5: 23160 | R5: 23160 | S5: 22800 | U5: 22600 | V5: 22100 | W5: 22160 | X5: 23000 | Y5: 23420 | AB5: 23300 | AC5: 23780 | AD5: 24260 | AE5: 24040 | AF5: 24040
B6: 實際產量 | C6: 140350 | D6: 23672.467 | G6: 23246 | H6: 23556 | I6: 23653 | K6: 22242 | L6: 25129 | N6: 22524
B7: 差異 | C7: -5390 | D7: -897.53333 | G7: -994 | H7: -1804 | I7: -807 | K7: -2128 | L7: 419 | N7: -76
B8: 工時 | C8: 47.529412 | D8: 8 | G8: 8 | H8: 8 | I8: 8 | K8: 8 | L8: 8 | N8: 8
B9: 直工人數 | C9: 1674 | D9: 1674 | G9: 1694 | H9: 1702 | I9: 1668 | K9: 1665 | L9: 1686 | N9: 1585
B10: 時產能 | C10: 2959.0583 | D10: 2959.0583 | G10: 2905.75 | H10: 2944.5 | I10: 2956.625 | K10: 2780.25 | L10: 3141.125 | N10: 2815.5
B11: 人均時產 | C11: 1.7676573 | D11: 1.7676573 | G11: 1.7153188 | H11: 1.7300235 | I11: 1.772557 | K11: 1.6698198 | L11: 1.8630635 | N11: 1.7763407
A12: A2_LEAN1-01_M | B12: 標準產量 | C12: 10104 | D12: 1684 | G12: 1760 | H12: 1744 | I12: 1680 | K12: 1680 | L12: 1640 | N12: 1600
B13: 目標產量 | C13: 8280 | D13: 1380 | G13: 1440 | H13: 1440 | I13: 1080 | K13: 1440 | L13: 1440 | N13: 1440 | O13: 1440 | P13: 1440 | Q13: 1440 | R13: 1440 | S13: 1080 | U13: 1440 | V13: 1440 | W13: 1440 | X13: 1440 | Y13: 1440 | AB13: 1440 | AC13: 1440 | AD13: 1140 | AE13: 1520 | AF13: 1520
B14: 實際產量 | C14: 7638 | D14: 1273 | G14: 1554 | H14: 1212 | I14: 1104 | K14: 984 | L14: 1440 | N14: 1344
B15: 差異 | C15: -642 | D15: -107 | G15: 114 | H15: -228 | I15: 24 | K15: -456 | L15: 0 | N15: -96
B16: 工時 | C16: 48 | D16: 8 | G16: 8 | H16: 8 | I16: 8 | K16: 8 | L16: 8 | N16: 8
B17: 直工人數 | C17: 73 | D17: 73 | G17: 74 | H17: 74 | I17: 73 | K17: 73 | L17: 74 | N17: 71
B18: 時產能 | C18: 159.125 | D18: 159.125 | G18: 194.25 | H18: 151.5 | I18: 138 | K18: 123 | L18: 180 | N18: 168
B19: 人均時產 | C19: 2.1798 | D19: 2.1798 | G19: 2.625 | H19: 2.0473 | I19: 1.8904 | K19: 1.6849 | L19: 2.4324 | N19: 2.3662
A20: A2_LEAN1-02_M | B20: 標準產量 | C20: 8800 | D20: 1760 | G20: 1760 | H20: 1760 | I20: 1760 | K20: 1760 | L20: 1760
B21: 目標產量 | C21: 8400 | D21: 1680 | G21: 1680 | H21: 1680 | I21: 1680 | K21: 1680 | L21: 1680
B22: 實際產量 | C22: 8424 | D22: 1684.8 | G22: 1728 | H22: 2100 | I22: 1596 | K22: 1452 | L22: 1548
B23: 差異 | C23: 24 | D23: 4.8 | G23: 48 | H23: 420 | I23: -84 | K23: -228 | L23: -132
B24: 工時 | C24: 40 | D24: 8 | G24: 8 | H24: 8 | I24: 8 | K24: 8 | L24: 8
B25: 直工人數 | C25: 87 | D25: 87 | G25: 89 | H25: 89 | I25: 88 | K25: 84 | L25: 87
B26: 時產能 | C26: 210.6 | D26: 210.6 | G26: 216 | H26: 262.5 | I26: 199.5 | K26: 181.5 | L26: 193.5
B27: 人均時產 | C27: 2.4207 | D27: 2.4207 | G27: 2.427 | H27: 2.9494 | I27: 2.267 | K27: 2.1607 | L27: 2.2241
A28: A2_LEAN1-03_M | B28: 標準產量 | C28: 10560 | D28: 1760 | G28: 1760 | H28: 1760 | I28: 1760 | K28: 1760 | L28: 1760 | N28: 1760
B29: 目標產量 | C29: 10080 | D29: 1680 | G29: 1680 | H29: 1680 | I29: 1680 | K29: 1680 | L29: 1680 | N29: 1680 | O29: 1680 | P29: 1680 | Q29: 1680 | R29: 1680 | S29: 1680 | U29: 1680 | V29: 1680 | W29: 1680 | X29: 1680 | Y29: 1680 | AB29: 1680 | AC29: 1680 | AD29: 1680 | AE29: 1680 | AF29: 1680
B30: 實際產量 | C30: 10032 | D30: 1672 | G30: 1680 | H30: 1716 | I30: 1578 | K30: 1482 | L30: 1734 | N30: 1842
B31: 差異 | C31: -48 | D31: -8 | G31: 0 | H31: 36 | I31: -102 | K31: -198 | L31: 54 | N31: 162
B32: 工時 | C32: 48 | D32: 8 | G32: 8 | H32: 8 | I32: 8 | K32: 8 | L32: 8 | N32: 8
B33: 直工人數 | C33: 84 | D33: 84 | G33: 81 | H33: 86 | I33: 87 | K33: 85 | L33: 86 | N33: 84
B34: 時產能 | C34: 209 | D34: 209 | G34: 210 | H34: 214.5 | I34: 197.25 | K34: 185.25 | L34: 216.75 | N34: 230.25
B35: 人均時產 | C35: 2.4881 | D35: 2.4881 | G35: 2.5926 | H35: 2.4942 | I35: 2.2672 | K35: 2.1794 | L35: 2.5203 | N35: 2.7411
A36: A2_LEAN1-04_M | B36: 標準產量 | C36: 7680 | D36: 1280 | G36: 1280 | H36: 1280 | I36: 1280 | K36: 1280 | L36: 1280 | N36: 1280
B37: 目標產量 | C37: 7680 | D37: 1280 | G37: 1280 | H37: 1280 | I37: 1280 | K37: 1280 | L37: 1280 | N37: 1280 | O37: 1280 | P37: 1280 | Q37: 1280 | R37: 1280 | S37: 1280 | U37: 1280 | V37: 1280 | W37: 1280 | X37: 1280 | Y37: 1280 | AB37: 1280 | AC37: 1280 | AD37: 1280 | AE37: 1280 | AF37: 1280
B38: 實際產量 | C38: 6786 | D38: 1131 | G38: 1290 | H38: 978 | I38: 1182 | K38: 1068 | L38: 1056 | N38: 1212
B39: 差異 | C39: -894 | D39: -149 | G39: 10 | H39: -302 | I39: -98 | K39: -212 | L39: -224 | N39: -68
B40: 工時 | C40: 48 | D40: 8 | G40: 8 | H40: 8 | I40: 8 | K40: 8 | L40: 8 | N40: 8
...

Sheet 3.4 A1廠人均時產能-成型
A1: 回到首頁
A2: 2017/04月成型人均時產能報表
A3: Lean線 | B3: 項目 | C3: 總計 | D3: 日平均 | E3: 1 | F3: 2 | G3: 3 | H3: 4 | I3: 5 | J3: 6 | K3: 7 | L3: 8 | M3: 9 | N3: 10 | O3: 11 | P3: 12 | Q3: 13 | R3: 14 | S3: 15 | T3: 16 | U3: 17 | V3: 18 | W3: 19 | X3: 20 | Y3: 21 | Z3: 22 | AA3: 23 | AB3: 24 | AC3: 25 | AD3: 26 | AE3: 27 | AF3: 28 | AG3: 29 | AH3: 30
A4: 總計 | B4: 標準產量 | C4: 170576 | D4: 28722.667 | G4: 28872 | H4: 28928 | I4: 28776 | K4: 28624 | L4: 28656 | N4: 26720
B5: 目標產量 | C5: 158952 | D5: 26772 | G5: 26992 | H5: 26992 | I5: 26992 | K5: 26992 | L5: 26332 | N5: 24652 | O5: 24932 | P5: 25232 | Q5: 24952 | R5: 24572 | S5: 24632 | U5: 25232 | V5: 25232 | W5: 25232 | X5: 25112 | Y5: 25112 | AB5: 25132 | AC5: 24952 | AD5: 25632 | AE5: 25972 | AF5: 26352
B6: 實際產量 | C6: 153270 | D6: 25797.533 | G6: 26908 | H6: 25457 | I6: 25758 | K6: 26588 | L6: 25624 | N6: 22935
B7: 差異 | C7: -5682 | D7: -974.46667 | G7: -84 | H7: -1535 | I7: -1234 | K7: -404 | L7: -708 | N7: -1717
B8: 工時 | C8: 47.6 | D8: 8 | G8: 8 | H8: 8 | I8: 8 | K8: 8 | L8: 8 | N8: 8
B9: 直工人數 | C9: 1352 | D9: 1352 | G9: 1373 | H9: 1372 | I9: 1357 | K9: 1351 | L9: 1356 | N9: 1281
B10: 時產能 | C10: 3224.6917 | D10: 3224.6917 | G10: 3363.5 | H10: 3182.125 | I10: 3219.75 | K10: 3323.5 | L10: 3203 | N10: 2866.875
B11: 人均時產 | C11: 2.385127 | D11: 2.385127 | G11: 2.4497451 | H11: 2.3193331 | I11: 2.3726971 | K11: 2.4600296 | L11: 2.3620944 | N11: 2.2379977
A12: A1_LEAN1-01_G | B12: 標準產量 | C12: 8160 | D12: 1360 | G12: 1360 | H12: 1360 | I12: 1360 | K12: 1360 | L12: 1360 | N12: 1360
B13: 目標產量 | C13: 8160 | D13: 1360 | G13: 1360 | H13: 1360 | I13: 1360 | K13: 1360 | L13: 1360 | N13: 1360 | O13: 1360 | P13: 1360 | Q13: 1360 | R13: 1360 | S13: 1360 | U13: 1360 | V13: 1360 | W13: 1360 | X13: 1360 | Y13: 1360 | AB13: 1360 | AC13: 1360 | AD13: 1360 | AE13: 1360 | AF13: 1360
B14: 實際產量 | C14: 8788 | D14: 1464.6667 | G14: 1608 | H14: 1360 | I14: 1500 | K14: 1450 | L14: 1410 | N14: 1460
B15: 差異 | C15: 628 | D15: 104.66667 | G15: 248 | H15: 0 | I15: 140 | K15: 90 | L15: 50 | N15: 100
B16: 工時 | C16: 48 | D16: 8 | G16: 8 | H16: 8 | I16: 8 | K16: 8 | L16: 8 | N16: 8
B17: 直工人數 | C17: 70 | D17: 70 | G17: 72 | H17: 71 | I17: 69 | K17: 70 | L17: 71 | N17: 71
B18: 時產能 | C18: 183.08333 | D18: 183.08333 | G18: 201 | H18: 170 | I18: 187.5 | K18: 181.25 | L18: 176.25 | N18: 182.5
B19: 人均時產 | C19: 2.6155 | D19: 2.6155 | G19: 2.7917 | H19: 2.3944 | I19: 2.7174 | K19: 2.5893 | L19: 2.4824 | N19: 2.5704
A20: A1_LEAN1-02_G | B20: 標準產量 | C20: 8640 | D20: 1440 | G20: 1440 | H20: 1440 | I20: 1440 | K20: 1440 | L20: 1440 | N20: 1440
B21: 目標產量 | C21: 8160 | D21: 1360 | G21: 1360 | H21: 1360 | I21: 1360 | K21: 1360 | L21: 1360 | N21: 1360 | O21: 1360 | P21: 1360 | Q21: 1080 | R21: 1080 | S21: 1440 | U21: 1440 | V21: 1440 | W21: 1440 | X21: 1440 | Y21: 1440 | AB21: 1440 | AC21: 1440 | AD21: 1440 | AE21: 1440 | AF21: 1440
B22: 實際產量 | C22: 7381 | D22: 1230.1667 | G22: 1100 | H22: 1001 | I22: 1360 | K22: 1360 | L22: 1360 | N22: 1200
B23: 差異 | C23: -779 | D23: -129.83333 | G23: -260 | H23: -359 | I23: 0 | K23: 0 | L23: 0 | N23: -160
B24: 工時 | C24: 48 | D24: 8 | G24: 8 | H24: 8 | I24: 8 | K24: 8 | L24: 8 | N24: 8
B25: 直工人數 | C25: 67 | D25: 67 | G25: 66 | H25: 71 | I25: 71 | K25: 66 | L25: 66 | N25: 67
B26: 時產能 | C26: 153.77083 | D26: 153.77083 | G26: 137.5 | H26: 125.125 | I26: 170 | K26: 170 | L26: 170 | N26: 150
B27: 人均時產 | C27: 2.2951 | D27: 2.2951 | G27: 2.0833 | H27: 1.7623 | I27: 2.3944 | K27: 2.5758 | L27: 2.5758 | N27: 2.2388
A28: A1_LEAN1-03_G | B28: 標準產量 | C28: 8176 | D28: 1362.6667 | G28: 1360 | H28: 1360 | I28: 1360 | K28: 1360 | L28: 1360 | N28: 1376
B29: 目標產量 | C29: 8160 | D29: 1360 | G29: 1360 | H29: 1360 | I29: 1360 | K29: 1360 | L29: 1360 | N29: 1360 | O29: 1360 | P29: 1360 | Q29: 1360 | R29: 1360 | S29: 1360 | U29: 1360 | V29: 1360 | W29: 1360 | X29: 1360 | Y29: 1360 | AB29: 1360 | AC29: 1360 | AD29: 1360 | AE29: 1360 | AF29: 1360
B30: 實際產量 | C30: 8163 | D30: 1360.5 | G30: 1468 | H30: 1367 | I30: 1220 | K30: 1360 | L30: 1385 | N30: 1363
B31: 差異 | C31: 3 | D31: 0.5 | G31: 108 | H31: 7 | I31: -140 | K31: 0 | L31: 25 | N31: 3
B32: 工時 | C32: 48 | D32: 8 | G32: 8 | H32: 8 | I32: 8 | K32: 8 | L32: 8 | N32: 8
B33: 直工人數 | C33: 62 | D33: 62 | G33: 64 | H33: 63 | I33: 61 | K33: 63 | L33: 64 | N33: 62
B34: 時產能 | C34: 170.0625 | D34: 170.0625 | G34: 183.5 | H34: 170.875 | I34: 152.5 | K34: 170 | L34: 173.125 | N34: 170.375
B35: 人均時產 | C35: 2.7429 | D35: 2.7429 | G35: 2.8672 | H35: 2.7123 | I35: 2.5 | K35: 2.6984 | L35: 2.7051 | N35: 2.748
A36: A1_LEAN1-04_G | B36: 標準產量 | C36: 7736 | D36: 1289.3333 | G36: 1336 | H36: 1280 | I36: 1280 | K36: 1280 | L36: 1280 | N36: 1280
B37: 目標產量 | C37: 7872 | D37: 1312 | G37: 1312 | H37: 1312 | I37: 1312 | K37: 1312 | L37: 1312 | N37: 1312 | O37: 1312 | P37: 1312 | Q37: 1312 | R37: 1312 | S37: 1312 | U37: 1312 | V37: 1312 | W37: 1312 | X37: 1312 | Y37: 1312 | AB37: 1312 | AC37: 1312 | AD37: 1312 | AE37: 1312 | AF37: 1312
B38: 實際產量 | C38: 7990 | D38: 1331.6667 | G38: 1216 | H38: 1312 | I38: 1312 | K38: 1312 | L38: 1412 | N38: 1426
B39: 差異 | C39: 118 | D39: 19.666667 | G39: -96 | H39: 0 | I39: 0 | K39: 0 | L39: 100 | N39: 114
B40: 工時 | C40: 48 | D40: 8 | G40: 8 | H40: 8 | I40: 8 | K40: 8 | L40: 8 | N40: 8
...

Sheet 3.5.A2廠人均時產能-成型
A1: 回到首頁
A2: 2017/04月成型人均時產能報表
A3: Lean線 | B3: 項目 | C3: 總計 | D3: 日平均 | E3: 1 | F3: 2 | G3: 3 | H3: 4 | I3: 5 | J3: 6 | K3: 7 | L3: 8 | M3: 9 | N3: 10 | O3: 11 | P3: 12 | Q3: 13 | R3: 14 | S3: 15 | T3: 16 | U3: 17 | V3: 18 | W3: 19 | X3: 20 | Y3: 21 | Z3: 22 | AA3: 23 | AB3: 24 | AC3: 25 | AD3: 26 | AE3: 27 | AF3: 28 | AG3: 29 | AH3: 30
A4: 總計 | B4: 標準產量 | C4: 157648 | D4: 26568 | G4: 26736 | H4: 26576 | I4: 26560 | K4: 26544 | L4: 26528 | N4: 24704
B5: 目標產量 | C5: 145740 | D5: 24570 | G5: 24240 | H5: 25360 | I5: 24460 | K5: 24370 | L5: 24710 | N5: 22600 | O5: 22680 | P5: 23040 | Q5: 23160 | R5: 23160 | S5: 22800 | U5: 22600 | V5: 22100 | W5: 22160 | X5: 23000 | Y5: 23420 | AB5: 23300 | AC5: 23780 | AD5: 24260 | AE5: 24040 | AF5: 24040
B6: 實際產量 | C6: 142075 | D6: 23941.567 | G6: 24248 | H6: 25090 | I6: 22585 | K6: 23810 | L6: 24162 | N6: 22180
B7: 差異 | C7: -3665 | D7: -628.43333 | G7: 8 | H7: -270 | I7: -1875 | K7: -560 | L7: -548 | N7: -420
B8: 工時 | C8: 47.529412 | D8: 8 | G8: 8 | H8: 8 | I8: 8 | K8: 8 | L8: 8 | N8: 8
B9: 直工人數 | C9: 1174 | D9: 1174 | G9: 1198 | H9: 1195 | I9: 1165 | K9: 1165 | L9: 1182 | N9: 1113
B10: 時產能 | C10: 2992.6958 | D10: 2992.6958 | G10: 3031 | H10: 3136.25 | I10: 2823.125 | K10: 2976.25 | L10: 3020.25 | N10: 2772.5
B11: 人均時產 | C11: 2.5491447 | D11: 2.5491447 | G11: 2.5300501 | H11: 2.624477 | I11: 2.4232833 | K11: 2.554721 | L11: 2.555203 | N11: 2.4910153
A12: A2_LEAN1-01_G | B12: 標準產量 | C12: 10208 | D12: 1701.3333 | G12: 1744 | H12: 1760 | I12: 1744 | K12: 1680 | L12: 1640 | N12: 1640
B13: 目標產量 | C13: 8280 | D13: 1380 | G13: 1440 | H13: 1440 | I13: 1080 | K13: 1440 | L13: 1440 | N13: 1440 | O13: 1440 | P13: 1440 | Q13: 1440 | R13: 1440 | S13: 1080 | U13: 1440 | V13: 1440 | W13: 1440 | X13: 1440 | Y13: 1440 | AB13: 1440 | AC13: 1440 | AD13: 1140 | AE13: 1520 | AF13: 1520
B14: 實際產量 | C14: 8802 | D14: 1467 | G14: 1440 | H14: 1440 | I14: 1280 | K14: 1546 | L14: 1656 | N14: 1440
B15: 差異 | C15: 522 | D15: 87 | G15: 0 | H15: 0 | I15: 200 | K15: 106 | L15: 216 | N15: 0
B16: 工時 | C16: 48 | D16: 8 | G16: 8 | H16: 8 | I16: 8 | K16: 8 | L16: 8 | N16: 8
B17: 直工人數 | C17: 66 | D17: 66 | G17: 67 | H17: 65 | I17: 65 | K17: 66 | L17: 66 | N17: 67
B18: 時產能 | C18: 183.375 | D18: 183.375 | G18: 180 | H18: 180 | I18: 160 | K18: 193.25 | L18: 207 | N18: 180
B19: 人均時產 | C19: 2.7784 | D19: 2.7784 | G19: 2.6866 | H19: 2.7692 | I19: 2.4615 | K19: 2.928 | L19: 3.1364 | N19: 2.6866
A20: A2_LEAN1-02_G | B20: 標準產量 | C20: 8800 | D20: 1760 | G20: 1760 | H20: 1760 | I20: 1760 | K20: 1760 | L20: 1760
B21: 目標產量 | C21: 8400 | D21: 1680 | G21: 1680 | H21: 1680 | I21: 1680 | K21: 1680 | L21: 1680
B22: 實際產量 | C22: 7872 | D22: 1574.4 | G22: 1688 | H22: 1680 | I22: 1348 | K22: 1680 | L22: 1476
B23: 差異 | C23: -528 | D23: -105.6 | G23: 8 | H23: 0 | I23: -332 | K23: 0 | L23: -204
B24: 工時 | C24: 40 | D24: 8 | G24: 8 | H24: 8 | I24: 8 | K24: 8 | L24: 8
B25: 直工人數 | C25: 68 | D25: 68 | G25: 69 | H25: 69 | I25: 67 | K25: 68 | L25: 69
B26: 時產能 | C26: 196.8 | D26: 196.8 | G26: 211 | H26: 210 | I26: 168.5 | K26: 210 | L26: 184.5
B27: 人均時產 | C27: 2.8941 | D27: 2.8941 | G27: 3.058 | H27: 3.0435 | I27: 2.5149 | K27: 3.0882 | L27: 2.6739
A28: A2_LEAN1-03_G | B28: 標準產量 | C28: 10560 | D28: 1760 | G28: 1760 | H28: 1760 | I28: 1760 | K28: 1760 | L28: 1760 | N28: 1760
B29: 目標產量 | C29: 10080 | D29: 1680 | G29: 1680 | H29: 1680 | I29: 1680 | K29: 1680 | L29: 1680 | N29: 1680 | O29: 1680 | P29: 1680 | Q29: 1680 | R29: 1680 | S29: 1680 | U29: 1680 | V29: 1680 | W29: 1680 | X29: 1680 | Y29: 1680 | AB29: 1680 | AC29: 1680 | AD29: 1680 | AE29: 1680 | AF29: 1680
B30: 實際產量 | C30: 9781 | D30: 1630.1667 | G30: 1680 | H30: 1584 | I30: 1477 | K30: 1680 | L30: 1680 | N30: 1680
B31: 差異 | C31: -299 | D31: -49.833333 | G31: 0 | H31: -96 | I31: -203 | K31: 0 | L31: 0 | N31: 0
B32: 工時 | C32: 48 | D32: 8 | G32: 8 | H32: 8 | I32: 8 | K32: 8 | L32: 8 | N32: 8
B33: 直工人數 | C33: 68 | D33: 68 | G33: 71 | H33: 70 | I33: 67 | K33: 65 | L33: 68 | N33: 69
B34: 時產能 | C34: 203.77083 | D34: 203.77083 | G34: 210 | H34: 198 | I34: 184.625 | K34: 210 | L34: 210 | N34: 210
B35: 人均時產 | C35: 2.9966 | D35: 2.9966 | G35: 2.9577 | H35: 2.8286 | I35: 2.7556 | K35: 3.2308 | L35: 3.0882 | N35: 3.0435
A36: A2_LEAN1-04_G | B36: 標準產量 | C36: 7840 | D36: 1306.6667 | G36: 1280 | H36: 1280 | I36: 1280 | K36: 1360 | L36: 1280 | N36: 1360
B37: 目標產量 | C37: 7680 | D37: 1280 | G37: 1280 | H37: 1280 | I37: 1280 | K37: 1280 | L37: 1280 | N37: 1280 | O37: 1280 | P37: 1280 | Q37: 1280 | R37: 1280 | S37: 1280 | U37: 1280 | V37: 1280 | W37: 1280 | X37: 1280 | Y37: 1280 | AB37: 1280 | AC37: 1280 | AD37: 1280 | AE37: 1280 | AF37: 1280
B38: 實際產量 | C38: 7410 | D38: 1235 | G38: 1280 | H38: 1280 | I38: 1280 | K38: 1010 | L38: 1280 | N38: 1280
B39: 差異 | C39: -270 | D39: -45 | G39: 0 | H39: 0 | I39: 0 | K39: -270 | L39: 0 | N39: 0
B40: 工時 | C40: 48 | D40: 8 | G40: 8 | H40: 8 | I40: 8 | K40: 8 | L40: 8 | N40: 8
...

Sheet 3.6.A廠總計產能
A1: 回到首頁
A2: 2017/04月成型人均時產能報表
A3: Lean線 | B3: 項目 | C3: 總計 | D3: 日平均 | E3: 1 | F3: 2 | G3: 3 | H3: 4 | I3: 5 | J3: 6 | K3: 7 | L3: 8 | M3: 9 | N3: 10 | O3: 11 | P3: 12 | Q3: 13 | R3: 14 | S3: 15 | T3: 16 | U3: 17 | V3: 18 | W3: 19 | X3: 20 | Y3: 21 | Z3: 22 | AA3: 23 | AB3: 24 | AC3: 25 | AD3: 26 | AE3: 27 | AF3: 28 | AG3: 29 | AH3: 30
A4: 總計 | B4: 標準產量 | C4: 328224 | D4: 54704 | G4: 55608 | H4: 55504 | I4: 55336 | K4: 55168 | L4: 55184 | N4: 51424
B5: 目標產量 | C5: 304692 | D5: 50782 | G5: 51232 | H5: 52352 | I5: 51452 | K5: 51362 | L5: 51042 | N5: 47252 | O5: 47612 | P5: 48272 | Q5: 48112 | R5: 47732 | S5: 47432 | U5: 47832 | V5: 47332 | W5: 47392 | X5: 48112 | Y5: 48532 | AB5: 48432 | AC5: 48732 | AD5: 49892 | AE5: 50012 | AF5: 50392
B6: 實際產量 | C6: 295345 | D6: 49224.167 | G6: 51156 | H6: 50547 | I6: 48343 | K6: 50398 | L6: 49786 | N6: 45115
B7: 差異 | C7: -9347 | D7: -1557.8333 | G7: -76 | H7: -1805 | I7: -3109 | K7: -964 | L7: -1256 | N7: -2137
B8: 工時 | C8: 47.55 | D8: 7.925 | G8: 8 | H8: 8 | I8: 8 | K8: 8 | L8: 8 | N8: 8
B9: 直工人數 | C9: 6441 | D9: 6441 | G9: 6515 | H9: 6521 | I9: 6420 | K9: 6405 | L9: 6461 | N9: 6128
B10: 時產能 | C10: 6211.0106 | D10: 6211.0106 | G10: 6394.5 | H10: 6318.375 | I10: 6042.875 | K10: 6299.75 | L10: 6223.25 | N10: 5639.375
B11: 人均時產 | C11: 0.96775 | D11: 0.96775 | G11: 0.98385 | H11: 0.97475 | I11: 0.94275 | K11: 0.9859 | L11: 0.9669 | N11: 0.92575
A12: A1 | B12: 標準產量 | C12: 170576 | D12: 28429.333 | G12: 28872 | H12: 28928 | I12: 28776 | K12: 28624 | L12: 28656 | N12: 26720
B13: 目標產量 | C13: 158952 | D13: 26492 | G13: 26992 | H13: 26992 | I13: 26992 | K13: 26992 | L13: 26332 | N13: 24652 | O13: 24932 | P13: 25232 | Q13: 24952 | R13: 24572 | S13: 24632 | U13: 25232 | V13: 25232 | W13: 25232 | X13: 25112 | Y13: 25112 | AB13: 25132 | AC13: 24952 | AD13: 25632 | AE13: 25972 | AF13: 26352
B14: 實際產量 | C14: 153270 | D14: 25545 | G14: 26908 | H14: 25457 | I14: 25758 | K14: 26588 | L14: 25624 | N14: 22935
B15: 差異 | C15: -5682 | D15: -947 | G15: -84 | H15: -1535 | I15: -1234 | K15: -404 | L15: -708 | N15: -1717
B16: 工時 | C16: 47.6 | D16: 7.9333333 | G16: 8 | H16: 8 | I16: 8 | K16: 8 | L16: 8 | N16: 8
B17: 直工人數 | C17: 3482 | D17: 3482 | G17: 3523 | H17: 3524 | I17: 3481 | K17: 3469 | L17: 3484 | N17: 3327
B18: 時產能 | C18: 3219.958 | D18: 3219.958 | G18: 3363.5 | H18: 3182.125 | I18: 3219.75 | K18: 3323.5 | L18: 3203 | N18: 2866.875
B19: 人均時產 | C19: 0.9247 | D19: 0.9247 | G19: 0.9547 | H19: 0.903 | I19: 0.9249 | K19: 0.9581 | L19: 0.9193 | N19: 0.8617
A20: A2 | B20: 標準產量 | C20: 157648 | D20: 26274.667 | G20: 26736 | H20: 26576 | I20: 26560 | K20: 26544 | L20: 26528 | N20: 24704
B21: 目標產量 | C21: 145740 | D21: 24290 | G21: 24240 | H21: 25360 | I21: 24460 | K21: 24370 | L21: 24710 | N21: 22600 | O21: 22680 | P21: 23040 | Q21: 23160 | R21: 23160 | S21: 22800 | U21: 22600 | V21: 22100 | W21: 22160 | X21: 23000 | Y21: 23420 | AB21: 23300 | AC21: 23780 | AD21: 24260 | AE21: 24040 | AF21: 24040
B22: 實際產量 | C22: 142075 | D22: 23679.167 | G22: 24248 | H22: 25090 | I22: 22585 | K22: 23810 | L22: 24162 | N22: 22180
B23: 差異 | C23: -3665 | D23: -610.83333 | G23: 8 | H23: -270 | I23: -1875 | K23: -560 | L23: -548 | N23: -420
B24: 工時 | C24: 47.5 | D24: 7.9166667 | G24: 8 | H24: 8 | I24: 8 | K24: 8 | L24: 8 | N24: 8
B25: 直工人數 | C25: 2959 | D25: 2959 | G25: 2992 | H25: 2997 | I25: 2939 | K25: 2936 | L25: 2977 | N25: 2801
B26: 時產能 | C26: 2991.0526 | D26: 2991.0526 | G26: 3031 | H26: 3136.25 | I26: 2823.125 | K26: 2976.25 | L26: 3020.25 | N26: 2772.5
B27: 人均時產 | C27: 1.0108 | D27: 1.0108 | G27: 1.013 | H27: 1.0465 | I27: 0.9606 | K27: 1.0137 | L27: 1.0145 | N27: 0.9898
A28: BB | B28: 標準產量
B29: 目標產量
B30: 實際產量
B31: 差異
B32: 工時
B33: 直工人數
B34: 時產能
B35: 人均時產

Sheet 3.7.A廠人員分攤POH產能
A1: 回到首頁
A2: 2017/03月A廠人員分攤POH產能
A3: Lean線 | B3: 項目 | C3: 總計 | D3: 日平均 | E3: 1 | F3: 2 | G3: 3 | H3: 4 | I3: 5 | J3: 6 | K3: 7 | L3: 8 | M3: 9 | N3: 10 | O3: 11 | P3: 12 | Q3: 13 | R3: 14 | S3: 15 | T3: 16 | U3: 17 | V3: 18 | W3: 19 | X3: 20 | Y3: 21 | Z3: 22 | AA3: 23 | AB3: 24 | AC3: 25 | AD3: 26 | AE3: 27 | AF3: 28 | AG3: 29 | AH3: 30
A4: 總計 | B4: 標準產量 | C4: ='3.6.A廠總計產能'!C4 -> 328224 | D4: ='3.6.A廠總計產能'!D4 -> 54704 | E4: ='3.6.A廠總計產能'!E4 -> 0 | F4: ='3.6.A廠總計產能'!F4 -> 0 | G4: ='3.6.A廠總計產能'!G4 -> 55608 | H4: ='3.6.A廠總計產能'!H4 -> 55504 | I4: ='3.6.A廠總計產能'!I4 -> 55336 | J4: ='3.6.A廠總計產能'!J4 -> 0 | ... AH4: ='3.6.A廠總計產能'!AH4 -> 0
B5: 目標產量 | C5: ='3.6.A廠總計產能'!C5 -> 304692 | D5: ='3.6.A廠總計產能'!D5 -> 50782 | E5: ='3.6.A廠總計產能'!E5 -> 0 | F5: ='3.6.A廠總計產能'!F5 -> 0 | G5: ='3.6.A廠總計產能'!G5 -> 51232 | H5: ='3.6.A廠總計產能'!H5 -> 52352 | I5: ='3.6.A廠總計產能'!I5 -> 51452 | J5: ='3.6.A廠總計產能'!J5 -> 0 | ... AH5: ='3.6.A廠總計產能'!AH5 -> 0
B6: 實際產量 | C6: ='3.6.A廠總計產能'!C6 -> 295345 | D6: ='3.6.A廠總計產能'!D6 -> 49224.167 | E6: ='3.6.A廠總計產能'!E6 -> 0 | F6: ='3.6.A廠總計產能'!F6 -> 0 | G6: ='3.6.A廠總計產能'!G6 -> 51156 | H6: ='3.6.A廠總計產能'!H6 -> 50547 | I6: ='3.6.A廠總計產能'!I6 -> 48343 | J6: ='3.6.A廠總計產能'!J6 -> 0 | ... AH6: ='3.6.A廠總計產能'!AH6 -> 0
B7: 差異 | C7: ='3.6.A廠總計產能'!C7 -> -9347 | D7: ='3.6.A廠總計產能'!D7 -> -1557.8333 | E7: ='3.6.A廠總計產能'!E7 -> 0 | F7: ='3.6.A廠總計產能'!F7 -> 0 | G7: ='3.6.A廠總計產能'!G7 -> -76 | H7: ='3.6.A廠總計產能'!H7 -> -1805 | I7: ='3.6.A廠總計產能'!I7 -> -3109 | J7: ='3.6.A廠總計產能'!J7 -> 0 | ... AH7: ='3.6.A廠總計產能'!AH7 -> 0
B8: 工時 | C8: ='3.6.A廠總計產能'!C8 -> 47.55 | D8: ='3.6.A廠總計產能'!D8 -> 7.925 | E8: ='3.6.A廠總計產能'!E8 -> 0 | F8: ='3.6.A廠總計產能'!F8 -> 0 | G8: ='3.6.A廠總計產能'!G8 -> 8 | H8: ='3.6.A廠總計產能'!H8 -> 8 | I8: ='3.6.A廠總計產能'!I8 -> 8 | J8: ='3.6.A廠總計產能'!J8 -> 0 | ... AH8: ='3.6.A廠總計產能'!AH8 -> 0
B9: 直工人數 | C9: ='3.6.A廠總計產能'!C9 -> 6441 | D9: ='3.6.A廠總計產能'!D9 -> 6441 | E9: ='3.6.A廠總計產能'!E9 -> 0 | F9: ='3.6.A廠總計產能'!F9 -> 0 | G9: ='3.6.A廠總計產能'!G9 -> 6515 | H9: ='3.6.A廠總計產能'!H9 -> 6521 | I9: ='3.6.A廠總計產能'!I9 -> 6420 | J9: ='3.6.A廠總計產能'!J9 -> 0 | ... AH9: ='3.6.A廠總計產能'!AH9 -> 0
B10: 時產能 | C10: ='3.6.A廠總計產能'!C10 -> 6211.0106 | D10: ='3.6.A廠總計產能'!D10 -> 6211.0106 | E10: ='3.6.A廠總計產能'!E10 -> 0 | F10: ='3.6.A廠總計產能'!F10 -> 0 | G10: ='3.6.A廠總計產能'!G10 -> 6394.5 | H10: ='3.6.A廠總計產能'!H10 -> 6318.375 | I10: ='3.6.A廠總計產能'!I10 -> 6042.875 | J10: ='3.6.A廠總計產能'!J10 -> 0 | ... AH10: ='3.6.A廠總計產能'!AH10 -> 0
B11: 廠內分攤 | C11: =SUM(E11:AH11)/COUNTIF(E6:AH6,">0") -> 1739.6667 | D11: =SUM(E11:AH11)/COUNTIF(E6:AH6,">0") -> 1739.6667 | E11: ='3-1.人員刷卡出勤'!C48+'3-1.人員刷卡出勤'!C45+'3-1.人員刷卡出勤'!C51 -> 1018 | F11: ='3-1.人員刷卡出勤'!D48+'3-1.人員刷卡出勤'!D45+'3-1.人員刷卡出勤'!D51 -> 0 | G11: ='3-1.人員刷卡出勤'!E48+'3-1.人員刷卡出勤'!E45+'3-1.人員刷卡出勤'!E51 -> 1590 | H11: ='3-1.人員刷卡出勤'!F48+'3-1.人員刷卡出勤'!F45+'3-1.人員刷卡出勤'!F51 -> 1601 | I11: ='3-1.人員刷卡出勤'!G48+'3-1.人員刷卡出勤'!G45+'3-1.人員刷卡出勤'!G51 -> 1544 | J11: ='3-1.人員刷卡出勤'!H48+'3-1.人員刷卡出勤'!H45+'3-1.人員刷卡出勤'!H51 -> 0 | K11: ='3-1.人員刷卡出勤'!I48+'3-1.人員刷卡出勤'!I45+'3-1.人員刷卡出勤'!I51 -> 1570 | L11: ='3-1.人員刷卡出勤'!J48+'3-1.人員刷卡出勤'!J45+'3-1.人員刷卡出勤'!J51 -> 1558 | ... AH11: ='3-1.人員刷卡出勤'!AF48+'3-1.人員刷卡出勤'!AF45+'3-1.人員刷卡出勤'!AF51 -> 0
B12: 廠外分攤 | C12: =SUM(E12:AH12)/COUNTIF(E6:AH6,">0") -> 438.83333 | D12: =SUM(E12:AH12)/COUNTIF(E6:AH6,">0") -> 438.83333 | E12: ='3-1.人員刷卡出勤'!C9/2+'3-1.人員刷卡出勤'!C12+'3-1.人員刷卡出勤'!C15++'3-1.人員刷卡出勤'!C24 -> 198.5 | F12: ='3-1.人員刷卡出勤'!D9/2+'3-1.人員刷卡出勤'!D12+'3-1.人員刷卡出勤'!D15++'3-1.人員刷卡出勤'!D24 -> 33 | G12: ='3-1.人員刷卡出勤'!E9/2+'3-1.人員刷卡出勤'!E12+'3-1.人員刷卡出勤'!E15++'3-1.人員刷卡出勤'!E24 -> 399.5 | H12: ='3-1.人員刷卡出勤'!F9/2+'3-1.人員刷卡出勤'!F12+'3-1.人員刷卡出勤'!F15++'3-1.人員刷卡出勤'!F24 -> 400.5 | I12: ='3-1.人員刷卡出勤'!G9/2+'3-1.人員刷卡出勤'!G12+'3-1.人員刷卡出勤'!G15++'3-1.人員刷卡出勤'!G24 -> 357 | J12: ='3-1.人員刷卡出勤'!H9/2+'3-1.人員刷卡出勤'!H12+'3-1.人員刷卡出勤'!H15++'3-1.人員刷卡出勤'!H24 -> 31 | K12: ='3-1.人員刷卡出勤'!I9/2+'3-1.人員刷卡出勤'!I12+'3-1.人員刷卡出勤'!I15++'3-1.人員刷卡出勤'!I24 -> 392 | L12: ='3-1.人員刷卡出勤'!J9/2+'3-1.人員刷卡出勤'!J12+'3-1.人員刷卡出勤'!J15++'3-1.人員刷卡出勤'!J24 -> 391.5 | ... AH12: ='3-1.人員刷卡出勤'!AF9/2+'3-1.人員刷卡出勤'!AF12+'3-1.人員刷卡出勤'!AF15++'3-1.人員刷卡出勤'!AF24 -> 0
B13: 人均時產 | C13: =C10/(C9+C11+C12) -> 0.72057667 | D13: =D10/(D9+D11+D12) -> 0.72057667 | E13: =IF(E10>0,E10/(E9+E11+E12),0) -> 0 | F13: =IF(F10>0,F10/(F9+F11+F12),0) -> 0 | G13: =IF(G10>0,G10/(G9+G11+G12),0) -> 0.75189606 | H13: =IF(H10>0,H10/(H9+H11+H12),0) -> 0.74137577 | I13: =IF(I10>0,I10/(I9+I11+I12),0) -> 0.72621981 | J13: =IF(J10>0,J10/(J9+J11+J12),0) -> 0 | K13: =IF(K10>0,K10/(K9+K11+K12),0) -> 0.75292817 | L13: =IF(L10>0,L10/(L9+L11+L12),0) -> 0.73993817 | ... AH13: =IF(AH10>0,AH10/(AH9+AH11+AH12),0) -> 0
A14: A1 | B14: 標準產量 | C14: ='3.6.A廠總計產能'!C12 -> 170576 | D14: ='3.6.A廠總計產能'!D12 -> 28429.333 | E14: ='3.6.A廠總計產能'!E12 -> 0 | F14: ='3.6.A廠總計產能'!F12 -> 0 | G14: ='3.6.A廠總計產能'!G12 -> 28872 | H14: ='3.6.A廠總計產能'!H12 -> 28928 | I14: ='3.6.A廠總計產能'!I12 -> 28776 | J14: ='3.6.A廠總計產能'!J12 -> 0 | ... AH14: ='3.6.A廠總計產能'!AH12 -> 0
B15: 目標產量 | C15: ='3.6.A廠總計產能'!C13 -> 158952 | D15: ='3.6.A廠總計產能'!D13 -> 26492 | E15: ='3.6.A廠總計產能'!E13 -> 0 | F15: ='3.6.A廠總計產能'!F13 -> 0 | G15: ='3.6.A廠總計產能'!G13 -> 26992 | H15: ='3.6.A廠總計產能'!H13 -> 26992 | I15: ='3.6.A廠總計產能'!I13 -> 26992 | J15: ='3.6.A廠總計產能'!J13 -> 0 | ... AH15: ='3.6.A廠總計產能'!AH13 -> 0
B16: 實際產量 | C16: ='3.6.A廠總計產能'!C14 -> 153270 | D16: ='3.6.A廠總計產能'!D14 -> 25545 | E16: ='3.6.A廠總計產能'!E14 -> 0 | F16: ='3.6.A廠總計產能'!F14 -> 0 | G16: ='3.6.A廠總計產能'!G14 -> 26908 | H16: ='3.6.A廠總計產能'!H14 -> 25457 | I16: ='3.6.A廠總計產能'!I14 -> 25758 | J16: ='3.6.A廠總計產能'!J14 -> 0 | ... AH16: ='3.6.A廠總計產能'!AH14 -> 0
B17: 差異 | C17: ='3.6.A廠總計產能'!C15 -> -5682 | D17: ='3.6.A廠總計產能'!D15 -> -947 | E17: ='3.6.A廠總計產能'!E15 -> 0 | F17: ='3.6.A廠總計產能'!F15 -> 0 | G17: ='3.6.A廠總計產能'!G15 -> -84 | H17: ='3.6.A廠總計產能'!H15 -> -1535 | I17: ='3.6.A廠總計產能'!I15 -> -1234 | J17: ='3.6.A廠總計產能'!J15 -> 0 | ... AH17: ='3.6.A廠總計產能'!AH15 -> 0
B18: 工時 | C18: ='3.6.A廠總計產能'!C16 -> 47.6 | D18: ='3.6.A廠總計產能'!D16 -> 7.9333333 | E18: ='3.6.A廠總計產能'!E16 -> 0 | F18: ='3.6.A廠總計產能'!F16 -> 0 | G18: ='3.6.A廠總計產能'!G16 -> 8 | H18: ='3.6.A廠總計產能'!H16 -> 8 | I18: ='3.6.A廠總計產能'!I16 -> 8 | J18: ='3.6.A廠總計產能'!J16 -> 0 | ... AH18: ='3.6.A廠總計產能'!AH16 -> 0
B19: 直工人數 | C19: ='3.6.A廠總計產能'!C17 -> 3482 | D19: ='3.6.A廠總計產能'!D17 -> 3482 | E19: ='3.6.A廠總計產能'!E17 -> 0 | F19: ='3.6.A廠總計產能'!F17 -> 0 | G19: ='3.6.A廠總計產能'!G17 -> 3523 | H19: ='3.6.A廠總計產能'!H17 -> 3524 | I19: ='3.6.A廠總計產能'!I17 -> 3481 | J19: ='3.6.A廠總計產能'!J17 -> 0 | ... AH19: ='3.6.A廠總計產能'!AH17 -> 0
B20: 時產能 | C20: ='3.6.A廠總計產能'!C18 -> 3219.958 | D20: ='3.6.A廠總計產能'!D18 -> 3219.958 | E20: ='3.6.A廠總計產能'!E18 -> 0 | F20: ='3.6.A廠總計產能'!F18 -> 0 | G20: ='3.6.A廠總計產能'!G18 -> 3363.5 | H20: ='3.6.A廠總計產能'!H18 -> 3182.125 | I20: ='3.6.A廠總計產能'!I18 -> 3219.75 | J20: ='3.6.A廠總計產能'!J18 -> 0 | ... AH20: ='3.6.A廠總計產能'!AH18 -> 0
B21: 廠內分攤 | C21: =SUM(E21:AH21)/COUNTIF(E16:AH16,">0") -> 667.5 | D21: =SUM(E21:AH21)/COUNTIF(E16:AH16,">0") -> 667.5 | E21: ='3-1.人員刷卡出勤'!C51/2+'3-1.人員刷卡出勤'!C54 -> 118.5 | F21: ='3-1.人員刷卡出勤'!D51/2+'3-1.人員刷卡出勤'!D54 -> 0 | G21: ='3-1.人員刷卡出勤'!E51/2+'3-1.人員刷卡出勤'!E54 -> 658.5 | H21: ='3-1.人員刷卡出勤'!F51/2+'3-1.人員刷卡出勤'!F54 -> 659.5 | I21: ='3-1.人員刷卡出勤'!G51/2+'3-1.人員刷卡出勤'!G54 -> 643 | J21: ='3-1.人員刷卡出勤'!H51/2+'3-1.人員刷卡出勤'!H54 -> 0 | K21: ='3-1.人員刷卡出勤'!I51/2+'3-1.人員刷卡出勤'!I54 -> 644.5 | L21: ='3-1.人員刷卡出勤'!J51/2+'3-1.人員刷卡出勤'!J54 -> 644 | ... AH21: ='3-1.人員刷卡出勤'!AF51/2+'3-1.人員刷卡出勤'!AF54 -> 0
B22: 廠外分攤 | C22: =SUM(E22:AH22)/COUNTIF(E16:AH16,">0") -> 219.41667 | D22: =SUM(E22:AH22)/COUNTIF(E16:AH16,">0") -> 219.41667 | E22: ='3-1.人員刷卡出勤'!C9/4+'3-1.人員刷卡出勤'!C12/2+'3-1.人員刷卡出勤'!C15/2++'3-1.人員刷卡出勤'!C24/2 -> 99.25 | F22: ='3-1.人員刷卡出勤'!D9/4+'3-1.人員刷卡出勤'!D12/2+'3-1.人員刷卡出勤'!D15/2++'3-1.人員刷卡出勤'!D24/2 -> 16.5 | G22: ='3-1.人員刷卡出勤'!E9/4+'3-1.人員刷卡出勤'!E12/2+'3-1.人員刷卡出勤'!E15/2++'3-1.人員刷卡出勤'!E24/2 -> 199.75 | H22: ='3-1.人員刷卡出勤'!F9/4+'3-1.人員刷卡出勤'!F12/2+'3-1.人員刷卡出勤'!F15/2++'3-1.人員刷卡出勤'!F24/2 -> 200.25 | I22: ='3-1.人員刷卡出勤'!G9/4+'3-1.人員刷卡出勤'!G12/2+'3-1.人員刷卡出勤'!G15/2++'3-1.人員刷卡出勤'!G24/2 -> 178.5 | J22: ='3-1.人員刷卡出勤'!H9/4+'3-1.人員刷卡出勤'!H12/2+'3-1.人員刷卡出勤'!H15/2++'3-1.人員刷卡出勤'!H24/2 -> 15.5 | K22: ='3-1.人員刷卡出勤'!I9/4+'3-1.人員刷卡出勤'!I12/2+'3-1.人員刷卡出勤'!I15/2++'3-1.人員刷卡出勤'!I24/2 -> 196 | L22: ='3-1.人員刷卡出勤'!J9/4+'3-1.人員刷卡出勤'!J12/2+'3-1.人員刷卡出勤'!J15/2++'3-1.人員刷卡出勤'!J24/2 -> 195.75 | ... AH22: ='3-1.人員刷卡出勤'!AF9/4+'3-1.人員刷卡出勤'!AF12/2+'3-1.人員刷卡出勤'!AF15/2++'3-1.人員刷卡出勤'!AF24/2 -> 0
B23: 人均時產 | C23: =C20/(C19+C21+C22) -> 0.7370152 | D23: =D20/(D19+D21+D22) -> 0.7370152 | E23: =IF(E20>0,E20/(E19+E21+E22),0) -> 0 | F23: =IF(F20>0,F20/(F19+F21+F22),0) -> 0 | G23: =IF(G20>0,G20/(G19+G21+G22),0) -> 0.76770328 | H23: =IF(H20>0,H20/(H19+H21+H22),0) -> 0.72589107 | I23: =IF(I20>0,I20/(I19+I21+I22),0) -> 0.74834399 | J23: =IF(J20>0,J20/(J19+J21+J22),0) -> 0 | K23: =IF(K20>0,K20/(K19+K21+K22),0) -> 0.77120316 | L23: =IF(L20>0,L20/(L19+L21+L22),0) -> 0.74079214 | ... AH23: =IF(AH20>0,AH20/(AH19+AH21+AH22),0) -> 0
A24: A2 | B24: 標準產量 | C24: ='3.6.A廠總計產能'!C20 -> 157648 | D24: ='3.6.A廠總計產能'!D20 -> 26274.667 | E24: ='3.6.A廠總計產能'!E20 -> 0 | F24: ='3.6.A廠總計產能'!F20 -> 0 | G24: ='3.6.A廠總計產能'!G20 -> 26736 | H24: ='3.6.A廠總計產能'!H20 -> 26576 | I24: ='3.6.A廠總計產能'!I20 -> 26560 | J24: ='3.6.A廠總計產能'!J20 -> 0 | ... AH24: ='3.6.A廠總計產能'!AH20 -> 0
B25: 目標產量 | C25: ='3.6.A廠總計產能'!C21 -> 145740 | D25: ='3.6.A廠總計產能'!D21 -> 24290 | E25: ='3.6.A廠總計產能'!E21 -> 0 | F25: ='3.6.A廠總計產能'!F21 -> 0 | G25: ='3.6.A廠總計產能'!G21 -> 24240 | H25: ='3.6.A廠總計產能'!H21 -> 25360 | I25: ='3.6.A廠總計產能'!I21 -> 24460 | J25: ='3.6.A廠總計產能'!J21 -> 0 | ... AH25: ='3.6.A廠總計產能'!AH21 -> 0
B26: 實際產量 | C26: ='3.6.A廠總計產能'!C22 -> 142075 | D26: ='3.6.A廠總計產能'!D22 -> 23679.167 | E26: ='3.6.A廠總計產能'!E22 -> 0 | F26: ='3.6.A廠總計產能'!F22 -> 0 | G26: ='3.6.A廠總計產能'!G22 -> 24248 | H26: ='3.6.A廠總計產能'!H22 -> 25090 | I26: ='3.6.A廠總計產能'!I22 -> 22585 | J26: ='3.6.A廠總計產能'!J22 -> 0 | ... AH26: ='3.6.A廠總計產能'!AH22 -> 0
B27: 差異 | C27: ='3.6.A廠總計產能'!C23 -> -3665 | D27: ='3.6.A廠總計產能'!D23 -> -610.83333 | E27: ='3.6.A廠總計產能'!E23 -> 0 | F27: ='3.6.A廠總計產能'!F23 -> 0 | G27: ='3.6.A廠總計產能'!G23 -> 8 | H27: ='3.6.A廠總計產能'!H23 -> -270 | I27: ='3.6.A廠總計產能'!I23 -> -1875 | J27: ='3.6.A廠總計產能'!J23 -> 0 | ... AH27: ='3.6.A廠總計產能'!AH23 -> 0
B28: 工時 | C28: ='3.6.A廠總計產能'!C24 -> 47.5 | D28: ='3.6.A廠總計產能'!D24 -> 7.9166667 | E28: ='3.6.A廠總計產能'!E24 -> 0 | F28: ='3.6.A廠總計產能'!F24 -> 0 | G28: ='3.6.A廠總計產能'!G24 -> 8 | H28: ='3.6.A廠總計產能'!H24 -> 8 | I28: ='3.6.A廠總計產能'!I24 -> 8 | J28: ='3.6.A廠總計產能'!J24 -> 0 | ... AH28: ='3.6.A廠總計產能'!AH24 -> 0
B29: 直工人數 | C29: ='3.6.A廠總計產能'!C25 -> 2959 | D29: ='3.6.A廠總計產能'!D25 -> 2959 | E29: ='3.6.A廠總計產能'!E25 -> 0 | F29: ='3.6.A廠總計產能'!F25 -> 0 | G29: ='3.6.A廠總計產能'!G25 -> 2992 | H29: ='3.6.A廠總計產能'!H25 -> 2997 | I29: ='3.6.A廠總計產能'!I25 -> 2939 | J29: ='3.6.A廠總計產能'!J25 -> 0 | ... AH29: ='3.6.A廠總計產能'!AH25 -> 0
B30: 時產能 | C30: ='3.6.A廠總計產能'!C26 -> 2991.0526 | D30: ='3.6.A廠總計產能'!D26 -> 2991.0526 | E30: ='3.6.A廠總計產能'!E26 -> 0 | F30: ='3.6.A廠總計產能'!F26 -> 0 | G30: ='3.6.A廠總計產能'!G26 -> 3031 | H30: ='3.6.A廠總計產能'!H26 -> 3136.25 | I30: ='3.6.A廠總計產能'!I26 -> 2823.125 | J30: ='3.6.A廠總計產能'!J26 -> 0 | ... AH30: ='3.6.A廠總計產能'!AH26 -> 0
B31: 廠內分攤 | C31: =SUM(E31:AH31)/COUNTIF(E26:AH26,">0") -> 582.5 | D31: =SUM(E31:AH31)/COUNTIF(E26:AH26,">0") -> 582.5 | E31: ='3-1.人員刷卡出勤'!C51/2+'3-1.人員刷卡出勤'!C48 -> 118.5 | F31: ='3-1.人員刷卡出勤'!D51/2+'3-1.人員刷卡出勤'!D48 -> 0 | G31: ='3-1.人員刷卡出勤'!E51/2+'3-1.人員刷卡出勤'!E48 -> 573.5 | H31: ='3-1.人員刷卡出勤'!F51/2+'3-1.人員刷卡出勤'!F48 -> 571.5 | I31: ='3-1.人員刷卡出勤'!G51/2+'3-1.人員刷卡出勤'!G48 -> 562 | J31: ='3-1.人員刷卡出勤'!H51/2+'3-1.人員刷卡出勤'!H48 -> 0 | K31: ='3-1.人員刷卡出勤'!I51/2+'3-1.人員刷卡出勤'!I48 -> 561.5 | L31: ='3-1.人員刷卡出勤'!J51/2+'3-1.人員刷卡出勤'!J48 -> 553 | ... AH31: ='3-1.人員刷卡出勤'!AF51/2+'3-1.人員刷卡出勤'!AF48 -> 0
B32: 廠外分攤 | C32: =SUM(E32:AH32)/COUNTIF(E26:AH26,">0") -> 219.41667 | D32: =SUM(E32:AH32)/COUNTIF(E26:AH26,">0") -> 219.41667 | E32: ='3-1.人員刷卡出勤'!C9/4+'3-1.人員刷卡出勤'!C12/2+'3-1.人員刷卡出勤'!C15/2++'3-1.人員刷卡出勤'!C24/2 -> 99.25 | F32: ='3-1.人員刷卡出勤'!D9/4+'3-1.人員刷卡出勤'!D12/2+'3-1.人員刷卡出勤'!D15/2++'3-1.人員刷卡出勤'!D24/2 -> 16.5 | G32: ='3-1.人員刷卡出勤'!E9/4+'3-1.人員刷卡出勤'!E12/2+'3-1.人員刷卡出勤'!E15/2++'3-1.人員刷卡出勤'!E24/2 -> 199.75 | H32: ='3-1.人員刷卡出勤'!F9/4+'3-1.人員刷卡出勤'!F12/2+'3-1.人員刷卡出勤'!F15/2++'3-1.人員刷卡出勤'!F24/2 -> 200.25 | I32: ='3-1.人員刷卡出勤'!G9/4+'3-1.人員刷卡出勤'!G12/2+'3-1.人員刷卡出勤'!G15/2++'3-1.人員刷卡出勤'!G24/2 -> 178.5 | J32: ='3-1.人員刷卡出勤'!H9/4+'3-1.人員刷卡出勤'!H12/2+'3-1.人員刷卡出勤'!H15/2++'3-1.人員刷卡出勤'!H24/2 -> 15.5 | K32: ='3-1.人員刷卡出勤'!I9/4+'3-1.人員刷卡出勤'!I12/2+'3-1.人員刷卡出勤'!I15/2++'3-1.人員刷卡出勤'!I24/2 -> 196 | L32: ='3-1.人員刷卡出勤'!J9/4+'3-1.人員刷卡出勤'!J12/2+'3-1.人員刷卡出勤'!J15/2++'3-1.人員刷卡出勤'!J24/2 -> 195.75 | ... AH32: ='3-1.人員刷卡出勤'!AF9/4+'3-1.人員刷卡出勤'!AF12/2+'3-1.人員刷卡出勤'!AF15/2++'3-1.人員刷卡出勤'!AF24/2 -> 0
B33: 人均時產 | C33: =C30/(C29+C31+C32) -> 0.79529883 | D33: =D30/(D29+D31+D32) -> 0.79529883 | E33: =IF(E30>0,E30/(E29+E31+E32),0) -> 0 | F33: =IF(F30>0,F30/(F29+F31+F32),0) -> 0 | G33: =IF(G30>0,G30/(G29+G31+G32),0) -> 0.80499303 | H33: =IF(H30>0,H30/(H29+H31+H32),0) -> 0.83217247 | I33: =IF(I30>0,I30/(I29+I31+I32),0) -> 0.76725778 | J33: =IF(J30>0,J30/(J29+J31+J32),0) -> 0 | K33: =IF(K30>0,K30/(K29+K31+K32),0) -> 0.8058075 | L33: =IF(L30>0,L30/(L29+L31+L32),0) -> 0.81064215 | ... AH33: =IF(AH30>0,AH30/(AH29+AH31+AH32),0) -> 0
A34: BB | B34: 標準產量 | C34: ='3.6.A廠總計產能'!C28 -> 0 | D34: ='3.6.A廠總計產能'!D28 -> 0 | E34: ='3.6.A廠總計產能'!E28 -> 0 | F34: ='3.6.A廠總計產能'!F28 -> 0 | G34: ='3.6.A廠總計產能'!G28 -> 0 | H34: ='3.6.A廠總計產能'!H28 -> 0 | I34: ='3.6.A廠總計產能'!I28 -> 0 | J34: ='3.6.A廠總計產能'!J28 -> 0 | ... AH34: ='3.6.A廠總計產能'!AH28 -> 0
B35: 目標產量 | C35: ='3.6.A廠總計產能'!C29 -> 0 | D35: ='3.6.A廠總計產能'!D29 -> 0 | E35: ='3.6.A廠總計產能'!E29 -> 0 | F35: ='3.6.A廠總計產能'!F29 -> 0 | G35: ='3.6.A廠總計產能'!G29 -> 0 | H35: ='3.6.A廠總計產能'!H29 -> 0 | I35: ='3.6.A廠總計產能'!I29 -> 0 | J35: ='3.6.A廠總計產能'!J29 -> 0 | ... AH35: ='3.6.A廠總計產能'!AH29 -> 0
B36: 實際產量 | C36: ='3.6.A廠總計產能'!C30 -> 0 | D36: ='3.6.A廠總計產能'!D30 -> 0 | E36: ='3.6.A廠總計產能'!E30 -> 0 | F36: ='3.6.A廠總計產能'!F30 -> 0 | G36: ='3.6.A廠總計產能'!G30 -> 0 | H36: ='3.6.A廠總計產能'!H30 -> 0 | I36: ='3.6.A廠總計產能'!I30 -> 0 | J36: ='3.6.A廠總計產能'!J30 -> 0 | ... AH36: ='3.6.A廠總計產能'!AH30 -> 0
B37: 差異 | C37: ='3.6.A廠總計產能'!C31 -> 0 | D37: ='3.6.A廠總計產能'!D31 -> 0 | E37: ='3.6.A廠總計產能'!E31 -> 0 | F37: ='3.6.A廠總計產能'!F31 -> 0 | G37: ='3.6.A廠總計產能'!G31 -> 0 | H37: ='3.6.A廠總計產能'!H31 -> 0 | I37: ='3.6.A廠總計產能'!I31 -> 0 | J37: ='3.6.A廠總計產能'!J31 -> 0 | ... AH37: ='3.6.A廠總計產能'!AH31 -> 0
B38: 工時 | C38: ='3.6.A廠總計產能'!C32 -> 0 | D38: ='3.6.A廠總計產能'!D32 -> 0 | E38: ='3.6.A廠總計產能'!E32 -> 0 | F38: ='3.6.A廠總計產能'!F32 -> 0 | G38: ='3.6.A廠總計產能'!G32 -> 0 | H38: ='3.6.A廠總計產能'!H32 -> 0 | I38: ='3.6.A廠總計產能'!I32 -> 0 | J38: ='3.6.A廠總計產能'!J32 -> 0 | ... AH38: ='3.6.A廠總計產能'!AH32 -> 0
B39: 直工人數 | C39: ='3.6.A廠總計產能'!C33 -> 0 | D39: ='3.6.A廠總計產能'!D33 -> 0 | E39: ='3.6.A廠總計產能'!E33 -> 0 | F39: ='3.6.A廠總計產能'!F33 -> 0 | G39: ='3.6.A廠總計產能'!G33 -> 0 | H39: ='3.6.A廠總計產能'!H33 -> 0 | I39: ='3.6.A廠總計產能'!I33 -> 0 | J39: ='3.6.A廠總計產能'!J33 -> 0 | ... AH39: ='3.6.A廠總計產能'!AH33 -> 0
B40: 時產能 | C40: ='3.6.A廠總計產能'!C34 -> 0 | D40: ='3.6.A廠總計產能'!D34 -> 0 | E40: ='3.6.A廠總計產能'!E34 -> 0 | F40: ='3.6.A廠總計產能'!F34 -> 0 | G40: ='3.6.A廠總計產能'!G34 -> 0 | H40: ='3.6.A廠總計產能'!H34 -> 0 | I40: ='3.6.A廠總計產能'!I34 -> 0 | J40: ='3.6.A廠總計產能'!J34 -> 0 | ... AH40: ='3.6.A廠總計產能'!AH34 -> 0
...

Sheet 5.1 全廠線均產能
A1: 回到首頁
A2: 2017年04月各廠線均，人均產量狀況表
D3: 單位:雙
A4: 廠別 | B4: 線數 | C4: 項目 | D4: 平均 | E4: 1 | F4: 2 | G4: 3 | H4: 4 | I4: 5 | J4: 6 | K4: 7 | L4: 8 | M4: 9 | N4: 10 | O4: 11 | P4: 12 | Q4: 13 | R4: 14 | S4: 15 | T4: 16 | U4: 17 | V4: 18 | W4: 19 | X4: 20 | Y4: 21 | Z4: 22 | AA4: 23 | AB4: 24 | AC4: 25 | AD4: 26 | AE4: 27 | AF4: 28 | AG4: 29 | AH4: 30
A5: A1成型 | B5: 20 | C5: 實際產量 | D5: =SUM(E5:AH5)/COUNTIF(E5:AH5,">0") -> 25545 | E5: ='3.7.A廠人員分攤POH產能'!E16 -> 0 | F5: ='3.7.A廠人員分攤POH產能'!F16 -> 0 | G5: ='3.7.A廠人員分攤POH產能'!G16 -> 26908 | H5: ='3.7.A廠人員分攤POH產能'!H16 -> 25457 | I5: ='3.7.A廠人員分攤POH產能'!I16 -> 25758 | J5: ='3.7.A廠人員分攤POH產能'!J16 -> 0 | K5: ='3.7.A廠人員分攤POH產能'!K16 -> 26588 | L5: ='3.7.A廠人員分攤POH產能'!L16 -> 25624 | ... AH5: ='3.7.A廠人員分攤POH產能'!AH16 -> 0
C6: 線均產量 | D6: =SUM(E6:AH6)/COUNTIF(E6:AH6,">0") -> 1277.25 | E6: =E5/$B5 -> 0 | F6: =F5/$B5 -> 0 | G6: =G5/$B5 -> 1345.4 | H6: =H5/$B5 -> 1272.85 | I6: =I5/$B5 -> 1287.9 | J6: =J5/$B5 -> 0 | K6: =K5/$B5 -> 1329.4 | L6: =L5/$B5 -> 1281.2 | ... AH6: =AH5/$B5 -> 0
C7: 線均時產 | D7: =SUM(E7:AH7)/COUNTIF(E7:AH7,">0") -> 3193.125 | E7: ='3.7.A廠人員分攤POH產能'!E20 -> 0 | F7: ='3.7.A廠人員分攤POH產能'!F20 -> 0 | G7: ='3.7.A廠人員分攤POH產能'!G20 -> 3363.5 | H7: ='3.7.A廠人員分攤POH產能'!H20 -> 3182.125 | I7: ='3.7.A廠人員分攤POH產能'!I20 -> 3219.75 | J7: ='3.7.A廠人員分攤POH產能'!J20 -> 0 | K7: ='3.7.A廠人員分攤POH產能'!K20 -> 3323.5 | L7: ='3.7.A廠人員分攤POH產能'!L20 -> 3203 | ... AH7: ='3.7.A廠人員分攤POH產能'!AH20 -> 0
C8: 人均時產 | D8: =SUM(E8:AH8)/COUNTIF(E8:AH8,">0") -> 0.74051438 | E8: ='3.7.A廠人員分攤POH產能'!E23 -> 0 | F8: ='3.7.A廠人員分攤POH產能'!F23 -> 0 | G8: ='3.7.A廠人員分攤POH產能'!G23 -> 0.76770328 | H8: ='3.7.A廠人員分攤POH產能'!H23 -> 0.72589107 | I8: ='3.7.A廠人員分攤POH產能'!I23 -> 0.74834399 | J8: ='3.7.A廠人員分攤POH產能'!J23 -> 0 | K8: ='3.7.A廠人員分攤POH產能'!K23 -> 0.77120316 | L8: ='3.7.A廠人員分攤POH產能'!L23 -> 0.74079214 | ... AH8: ='3.7.A廠人員分攤POH產能'!AH23 -> 0
A9: A2成型 | B9: 17 | C9: 實際產量 | D9: =SUM(E9:AH9)/COUNTIF(E9:AH9,">0") -> 23679.167 | E9: ='3.7.A廠人員分攤POH產能'!E26 -> 0 | F9: ='3.7.A廠人員分攤POH產能'!F26 -> 0 | G9: ='3.7.A廠人員分攤POH產能'!G26 -> 24248 | H9: ='3.7.A廠人員分攤POH產能'!H26 -> 25090 | I9: ='3.7.A廠人員分攤POH產能'!I26 -> 22585 | J9: ='3.7.A廠人員分攤POH產能'!J26 -> 0 | K9: ='3.7.A廠人員分攤POH產能'!K26 -> 23810 | L9: ='3.7.A廠人員分攤POH產能'!L26 -> 24162 | ... AH9: ='3.7.A廠人員分攤POH產能'!AH26 -> 0
C10: 線均產量 | D10: =SUM(E10:AH10)/COUNTIF(E10:AH10,">0") -> 1392.8922 | E10: =E9/$B9 -> 0 | F10: =F9/$B9 -> 0 | G10: =G9/$B9 -> 1426.3529 | H10: =H9/$B9 -> 1475.8824 | I10: =I9/$B9 -> 1328.5294 | J10: =J9/$B9 -> 0 | K10: =K9/$B9 -> 1400.5882 | L10: =L9/$B9 -> 1421.2941 | ... AH10: =AH9/$B9 -> 0
C11: 線均時產 | D11: =SUM(E11:AH11)/COUNTIF(E11:AH11,">0") -> 2959.8958 | E11: ='3.7.A廠人員分攤POH產能'!E30 -> 0 | F11: ='3.7.A廠人員分攤POH產能'!F30 -> 0 | G11: ='3.7.A廠人員分攤POH產能'!G30 -> 3031 | H11: ='3.7.A廠人員分攤POH產能'!H30 -> 3136.25 | I11: ='3.7.A廠人員分攤POH產能'!I30 -> 2823.125 | J11: ='3.7.A廠人員分攤POH產能'!J30 -> 0 | K11: ='3.7.A廠人員分攤POH產能'!K30 -> 2976.25 | L11: ='3.7.A廠人員分攤POH產能'!L30 -> 3020.25 | ... AH11: ='3.7.A廠人員分攤POH產能'!AH30 -> 0
C12: 人均時產 | D12: =SUM(E12:EH12)/COUNTIF(E12:EH12,">0") -> 0.80023652 | E12: ='3.7.A廠人員分攤POH產能'!E33 -> 0 | F12: ='3.7.A廠人員分攤POH產能'!F33 -> 0 | G12: ='3.7.A廠人員分攤POH產能'!G33 -> 0.80499303 | H12: ='3.7.A廠人員分攤POH產能'!H33 -> 0.83217247 | I12: ='3.7.A廠人員分攤POH產能'!I33 -> 0.76725778 | J12: ='3.7.A廠人員分攤POH產能'!J33 -> 0 | K12: ='3.7.A廠人員分攤POH產能'!K33 -> 0.8058075 | L12: ='3.7.A廠人員分攤POH產能'!L33 -> 0.81064215 | ... AH12: ='3.7.A廠人員分攤POH產能'!AH33 -> 0
A13: BB | B13: 1 | C13: 實際產量 | D13: =AVERAGE(E13:AH13) -> 0 | E13: ='3.7.A廠人員分攤POH產能'!E36 -> 0 | F13: ='3.7.A廠人員分攤POH產能'!F36 -> 0 | G13: ='3.7.A廠人員分攤POH產能'!G36 -> 0 | H13: ='3.7.A廠人員分攤POH產能'!H36 -> 0 | I13: ='3.7.A廠人員分攤POH產能'!I36 -> 0 | J13: ='3.7.A廠人員分攤POH產能'!J36 -> 0 | K13: ='3.7.A廠人員分攤POH產能'!K36 -> 0 | L13: ='3.7.A廠人員分攤POH產能'!L36 -> 0 | ... AH13: ='3.7.A廠人員分攤POH產能'!AH36 -> 0
C14: 線均產量 | D14: =SUM(E14:AH14)/COUNTIF(E14:AH14,">0") -> #DIV/0! | E14: =E13/$B13 -> 0 | F14: =F13/$B13 -> 0 | G14: =G13/$B13 -> 0 | H14: =H13/$B13 -> 0 | I14: =I13/$B13 -> 0 | J14: =J13/$B13 -> 0 | K14: =K13/$B13 -> 0 | L14: =L13/$B13 -> 0 | ... AH14: =AH13/$B13 -> 0
C15: 線均時產 | D15: =SUM(E15:AH15)/COUNTIF(E15:AH15,">0") -> #DIV/0! | E15: ='3.7.A廠人員分攤POH產能'!E40 -> 0 | F15: ='3.7.A廠人員分攤POH產能'!F40 -> 0 | G15: ='3.7.A廠人員分攤POH產能'!G40 -> 0 | H15: ='3.7.A廠人員分攤POH產能'!H40 -> 0 | I15: ='3.7.A廠人員分攤POH產能'!I40 -> 0 | J15: ='3.7.A廠人員分攤POH產能'!J40 -> 0 | K15: ='3.7.A廠人員分攤POH產能'!K40 -> 0 | L15: ='3.7.A廠人員分攤POH產能'!L40 -> 0 | ... AH15: ='3.7.A廠人員分攤POH產能'!AH40 -> 0
C16: 人均時產 | D16: =SUM(E16:EH16)/COUNTIF(E16:EH16,">0") -> #DIV/0! | E16: ='3.7.A廠人員分攤POH產能'!E41 -> 0 | F16: ='3.7.A廠人員分攤POH產能'!F41 -> 0 | G16: ='3.7.A廠人員分攤POH產能'!G41 -> 0 | H16: ='3.7.A廠人員分攤POH產能'!H41 -> 0 | I16: ='3.7.A廠人員分攤POH產能'!I41 -> 0 | J16: ='3.7.A廠人員分攤POH產能'!J41 -> 0 | K16: ='3.7.A廠人員分攤POH產能'!K41 -> 0 | L16: ='3.7.A廠人員分攤POH產能'!L41 -> 0 | ... AH16: ='3.7.A廠人員分攤POH產能'!AH41 -> 0
A17: A廠成型 | B17: =B5+B9+B13 -> 38 | C17: 實際產量 | D17: =AVERAGE(E17:AH17) -> 9844.8333 | E17: ='3.7.A廠人員分攤POH產能'!E6 -> 0 | F17: ='3.7.A廠人員分攤POH產能'!F6 -> 0 | G17: ='3.7.A廠人員分攤POH產能'!G6 -> 51156 | H17: ='3.7.A廠人員分攤POH產能'!H6 -> 50547 | I17: ='3.7.A廠人員分攤POH產能'!I6 -> 48343 | J17: ='3.7.A廠人員分攤POH產能'!J6 -> 0 | K17: ='3.7.A廠人員分攤POH產能'!K6 -> 50398 | L17: ='3.7.A廠人員分攤POH產能'!L6 -> 49786 | ... AH17: ='3.7.A廠人員分攤POH產能'!AH6 -> 0
C18: 線均產量 | D18: =SUM(E18:AH18)/COUNTIF(E18:AH18,">0") -> 1295.3728 | E18: =E17/$B17 -> 0 | F18: =F17/$B17 -> 0 | G18: =G17/$B17 -> 1346.2105 | H18: =H17/$B17 -> 1330.1842 | I18: =I17/$B17 -> 1272.1842 | J18: =J17/$B17 -> 0 | K18: =K17/$B17 -> 1326.2632 | L18: =L17/$B17 -> 1310.1579 | ... AH18: =AH17/$B17 -> 0
C19: 線均時產 | D19: =SUM(E19:AH19)/COUNTIF(E19:AH19,">0") -> 6153.0208 | E19: ='3.7.A廠人員分攤POH產能'!E10 -> 0 | F19: ='3.7.A廠人員分攤POH產能'!F10 -> 0 | G19: ='3.7.A廠人員分攤POH產能'!G10 -> 6394.5 | H19: ='3.7.A廠人員分攤POH產能'!H10 -> 6318.375 | I19: ='3.7.A廠人員分攤POH產能'!I10 -> 6042.875 | J19: ='3.7.A廠人員分攤POH產能'!J10 -> 0 | K19: ='3.7.A廠人員分攤POH產能'!K10 -> 6299.75 | L19: ='3.7.A廠人員分攤POH產能'!L10 -> 6223.25 | ... AH19: ='3.7.A廠人員分攤POH產能'!AH10 -> 0
C20: 人均時產 | D20: =SUM(E20:EH20)/COUNTIF(E20:EH20,">0") -> 0.73509328 | E20: ='3.7.A廠人員分攤POH產能'!E13 -> 0 | F20: ='3.7.A廠人員分攤POH產能'!F13 -> 0 | G20: ='3.7.A廠人員分攤POH產能'!G13 -> 0.75189606 | H20: ='3.7.A廠人員分攤POH產能'!H13 -> 0.74137577 | I20: ='3.7.A廠人員分攤POH產能'!I13 -> 0.72621981 | J20: ='3.7.A廠人員分攤POH產能'!J13 -> 0 | K20: ='3.7.A廠人員分攤POH產能'!K13 -> 0.75292817 | L20: ='3.7.A廠人員分攤POH產能'!L13 -> 0.73993817 | ... AH20: ='3.7.A廠人員分攤POH產能'!AH13 -> 0
A22: B1成型 | B22: 17 | C22: 實際產量 | D22: =AVERAGE(E22:AH22) -> #DIV/0!
C23: 線均產量 | D23: =AVERAGE(E23:AH23) -> #DIV/0!
C24: 線均時產 | D24: =AVERAGE(E24:AH24) -> #DIV/0!
C25: 人均時產 | D25: ='[1]3-4.B1廠人均時產'!AI323 -> 0.41638229
A26: B7成型 | B26: 18 | C26: 實際產量 | D26: =AVERAGE(E26:AH26) -> #DIV/0!
C27: 線均產量 | D27: =AVERAGE(E27:AH27) -> #DIV/0!
C28: 線均時產 | D28: =AVERAGE(E28:AH28) -> #DIV/0!
C29: 人均時產 | D29: ='[1]3-5.B7廠人均時產'!AI334 -> 1.1685486
A30: B廠成型 | B30: =B22+B26 -> 35 | C30: 實際產量 | D30: =AVERAGE(E30:AH30) -> #DIV/0!
C31: 線均產量 | D31: =AVERAGE(E31:AH31) -> #DIV/0!
C32: 線均時產 | D32: =AVERAGE(E32:AH32) -> #DIV/0!
C33: 人均時產 | D33: ='[1]3-6.總計產能 '!AI74 -> 0.46327545
A34: 全廠成型 | B34: =B17+B30 -> 73 | C34: 實際產量 | D34: =AVERAGE(E34:AH34) -> #DIV/0!
C35: 線均產量 | D35: =AVERAGE(E35:AH35) -> #DIV/0!
C36: 線均時產 | D36: =AVERAGE(E36:AH36) -> #DIV/0!
C37: 人均時產 | D37: ='[1]3-6.總計產能 '!AI77 -> 0.58666142
