Workbook

Sheet T12
A1: A1-01 廠 2018 年 12月 份 生 產 進 度 表--成型 / A1 LEAN01(CONVERSE)A7棟
D2: 裁斷 | H2: 針車 | J2: 成型 | U2: 本月目標: | W2: =+AG247 -> 185327 | AA2: 雙 | AD2: (PRS) | AF2: 43427
A3: D/T | B3: 43435 | C3: 43436 | D3: 43437 | E3: 43438 | F3: 43439 | G3: 43440 | H3: 43441 | I3: 43442 | J3: 43443 | K3: 43444 | L3: 43445 | M3: 43446 | N3: 43447 | O3: 43448 | P3: 43449 | Q3: 43450 | R3: 43451 | S3: 43452 | T3: 43453 | U3: 43454 | V3: 43455 | W3: 43456 | X3: 43457 | Y3: 43458 | Z3: 43459 | AA3: 43460 | AB3: 43461 | AC3: 43462 | AD3: 43463 | AE3: 43464 | AF3: 43465 | AG3: TTL
A4: LINE | B4: 六 | C4: =IF(B4="日","一",IF(B4="一","二",IF(B4="二","三",IF(B4="三","四",IF(B4="四","五",IF(B4="五","六",IF(B4="六","日",""))))))) -> 日 | D4: =IF(C4="日","一",IF(C4="一","二",IF(C4="二","三",IF(C4="三","四",IF(C4="四","五",IF(C4="五","六",IF(C4="六","日",""))))))) -> 一 | E4: =IF(D4="日","一",IF(D4="一","二",IF(D4="二","三",IF(D4="三","四",IF(D4="四","五",IF(D4="五","六",IF(D4="六","日",""))))))) -> 二 | F4: =IF(E4="日","一",IF(E4="一","二",IF(E4="二","三",IF(E4="三","四",IF(E4="四","五",IF(E4="五","六",IF(E4="六","日",""))))))) -> 三 | G4: =IF(F4="日","一",IF(F4="一","二",IF(F4="二","三",IF(F4="三","四",IF(F4="四","五",IF(F4="五","六",IF(F4="六","日",""))))))) -> 四 | H4: =IF(G4="日","一",IF(G4="一","二",IF(G4="二","三",IF(G4="三","四",IF(G4="四","五",IF(G4="五","六",IF(G4="六","日",""))))))) -> 五 | I4: =IF(H4="日","一",IF(H4="一","二",IF(H4="二","三",IF(H4="三","四",IF(H4="四","五",IF(H4="五","六",IF(H4="六","日",""))))))) -> 六 | J4: =IF(I4="日","一",IF(I4="一","二",IF(I4="二","三",IF(I4="三","四",IF(I4="四","五",IF(I4="五","六",IF(I4="六","日",""))))))) -> 日 | ... AF4: =IF(AE4="日","一",IF(AE4="一","二",IF(AE4="二","三",IF(AE4="三","四",IF(AE4="四","五",IF(AE4="五","六",IF(AE4="六","日",""))))))) -> 一 | AH4: =+AH5*9.5 -> 180.5 | AI4: =+AI5*8 -> 56 | AJ4: so ngay
B5: 8 | D5: 9.5 | E5: 9.5 | F5: 9.5 | G5: 9.5 | H5: 9.5 | I5: 8 | K5: 9.5 | L5: 9.5 | M5: 9.5 | N5: 9.5 | O5: 9.5 | P5: 8 | R5: 9.5 | S5: 9.5 | T5: 9.5 | U5: 9.5 | V5: 9.5 | W5: 8 | Y5: 8 | Z5: 9.5 | AA5: 9.5 | AB5: 9.5 | AC5: 9.5 | AD5: 8 | AF5: 8 | AG5: =SUM(B5:AF5) -> 236.5 | AH5: =COUNTIF(B5:AF5,9.5) -> 19 | AI5: =COUNTIF(B5:AG5,8) -> 7 | AJ5: =COUNTA(B5:AF5) -> 26
A6: LY | B6: 6G CTAS OX | D6: 6G CTAS OX | E6: SA216N-5B | F6: SA216N-5B | G6: SA216J-3B | H6: SA216J-3B | I6: SA216J-3B | K6: SA216J-3B | L6: SA216J-3B | M6: SA216J-3B | N6: SA216J-3B | O6: SA216J-3B | S6: KD686A | V6: KD686A | Y6: KD686A-8 | Z6: KD686A-8 | AA6: KD686A-8 | AB6: KD686A-8 | AC6: KD686B-7A | AD6: KD686B-7A
A7: RY | B7: Y1812-0863 | D7: Y1812-0898 | E7: Y1812-0606 | F7: Y1812-0580 | G7: Y1812-0604 | H7: Y1812-0608 | I7: Y1812-0611 | K7: Y1812-0837 | L7: Y1901-0045 | M7: Y1901-0252 | N7: Y1901-0253 | O7: Y1901-0528 | S7: Y1902-0111 | V7: Y1902-0112 | Y7: Y1901-0179 | Z7: Y1902-0026 | AA7: Y1902-0395 | AB7: Y1901-0278 | AC7: Y1902-0439 | AD7: Y1902-0452
A8: 材料/VT | B8: 43432 | D8: 43432 | E8: OK | F8: OK | G8: OK | H8: OK | I8: OK | K8: OK | L8: OK | M8: 12/01 | N8: 12/01 | O8: 12/01 | S8: 12/05 | V8: 12/05 | Y8: 12/07 | Z8: 12/20 | AA8: 12/10 | AB8: 12/07 | AC8: 12/05 | AD8: 12/05
A9: CHAT LIEU | B9: 基本型體 | D9: 基本型體 | E9: 皮+星星月亮 | F9: 皮+星星月亮 | G9: 皮+星星月亮 | H9: 皮+星星月亮 | I9: 皮+星星月亮 | K9: 皮+星星月亮 | L9: 皮+星星月亮 | M9: 皮+星星月亮 | N9: 皮+星星月亮 | O9: 皮+星星月亮 | S9: 布+星星月亮 | V9: 布+星星月亮 | Y9: 布+星星月亮 | Z9: 布+星星月亮 | AA9: 布+星星月亮 | AB9: 布+星星月亮 | AC9: PU+星星月亮 | AD9: PU+星星月亮
A10: Last# | B10: 01L-1 | D10: 01L-1 | E10: W-2689H | F10: W-2689H | G10: 01H-1 | H10: 01H-1 | I10: 01H-1 | K10: 01H-1 | L10: 01H-1 | M10: 01H-1 | N10: 01H-1 | O10: 01H-1 | S10: 01L-1 | V10: 01L-1 | Y10: 01L-1 | Z10: 01L-1 | AA10: 01L-1 | AB10: 01L-1 | AC10: 01L-1 | AD10: 01L-1
A11: BUY | B11: 10BUY | D11: 10BUY | E11: 9BUY | F11: 9BUY | G11: 9BUY | H11: 9BUY | I11: 9BUY | K11: 9BUY | L11: 9BUY | M11: 10BUY | N11: 10BUY | O11: 10BUY | S11: 10BUY | V11: 10BUY | Y11: 10BUY | Z11: 10BUY | AA11: 10BUY | AB11: 10BUY | AC11: 10BUY | AD11: 10BUY
A12: BTS | E12: OK12/5
A13: 裁斷/C | E13: 6 | F13: 6 | G13: 6 | H13: 6 | I13: 6 | K13: 6 | L13: 6
A14: SKU | B14: 3J256C | D14: 3J256C | E14: 763532C | F14: 763532C | G14: 663608C | H14: 663608C | I14: 663608C | K14: 663608C | L14: 663608C | M14: 663608C | N14: 663608C | O14: 663605C | S14: 660740C | V14: 660742C | Y14: 663599C | Z14: 663599C | AA14: 664184C | AB14: 664184F | AC14: 651830C | AD14: 651830C
A15: 針車/M | D15: 3size | E15: in | F15: in | G15: in | H15: in | I15: in | K15: in | L15: in | M15: OK12/12 | N15: OK12/13 | O15: OK12/14
A16: 數量/SL | B16: 1488 | D16: 480 | E16: 1272 | F16: 1200 | G16: 1176 | H16: 1152 | I16: 432 | K16: 1896 | L16: 876 | M16: 1512 | N16: 732 | O16: 252 | S16: 5340 | V16: 4140 | Y16: 168 | Z16: 336 | AA16: 384 | AB16: 276 | AC16: 1164 | AD16: 336
A17: 成型/G | B17: OK12/4 | D17: OK12/4 | E17: 5size | F17: OK12/7 | G17: OK12/6 | H17: OK12/8 | I17: OK12/10 | K17: OK12/11 | L17: OK12/12 | M17: in | N17: in | O17: in | S17: in | V17: in | Y17: in | Z17: in | AA17: in | AB17: in | AC17: in | AD17: in
A18: CSD | B18: 43105 | D18: 43464 | E18: 43444 | F18: 43451 | G18: 43448 | H18: 43448 | I18: 43448 | K18: 43448 | L18: 43461 | M18: 43475 | N18: 43490 | O18: 43484 | S18: 43486 | V18: 43486 | Y18: 43481 | Z18: 43510 | AA18: 43509 | AB18: 43490 | AC18: 43493 | AD18: 43493
A19: 國家/N | B19: AUSTRALIA | D19: PHILIPPINES | E19: USA | F19: USA | G19: USA | H19: USA | I19: USA | K19: USA | L19: BV | M19: USA | N19: USA | O19: CHILE | S19: BV | V19: BV | Y19: CANADA | Z19: CANADA | AA19: BV | AB19: USA | AC19: MEXICO | AD19: MEXICO
A20: LY | B20: 6G CTAS OX | D20: 6G CTAS OX | E20: SA216N-5B | F20: SA216N-5B | G20: SA216J-3B | I20: SA216J-3B | N20: SA216J-3B | O20: SA216J-3B | Y20: KD686A-8 | Z20: KD686A-8 | AA20: KD686A-8 | AB20: KD686A-8 | AC20: KD686B-7A | AD20: 01H-D
A21: RY | B21: Y1812-0879 | D21: Y1901-0203 | E21: Y1812-0836 | F21: Y1812-0482 | G21: Y1812-0607 | I21: Y1812-0834 | N21: Y1901-0250 | O21: Y1901-0251 | Y21: Y1901-0214 | Z21: Y1901-0174 | AA21: Y1902-0023 | AB21: Y1901-0175 | AC21: Y1902-0451 | AD21: Y1901-0295
A22: 材料/VT | B22: 43432 | D22: 12/01 | E22: OK | F22: OK | G22: OK | I22: OK | N22: 12/01 | O22: 12/01 | Y22: 12/05 | Z22: 12/07 | AA22: 12/10 | AB22: 12/07 | AC22: 12/05 | AD22: 12/15
A23: CHAT LIEU | B23: 基本型體 | D23: 基本型體 | E23: 皮+星星月亮 | F23: 皮+星星月亮 | G23: 皮+星星月亮 | I23: 皮+星星月亮 | N23: 皮+星星月亮 | O23: 皮+星星月亮 | Y23: 布+星星月亮 | Z23: 布+星星月亮 | AA23: 布+星星月亮 | AB23: 布+星星月亮 | AC23: PU+星星月亮 | AD23: 布
A24: Last# | B24: 01L-1 | D24: 01L-1 | E24: W-2689H | F24: W-2689H | G24: 01H-1 | I24: 01H-1 | N24: 01H-1 | O24: 01H-1 | Y24: 01L-1 | Z24: 01L-1 | AA24: 01L-1 | AB24: 01L-1 | AC24: 01L-1 | AD24: 01H-1
A25: BUY | B25: 10BUY | D25: 10BUY | E25: 9BUY | F25: 9BUY | G25: 9BUY | I25: 9BUY | N25: 10BUY | O25: 10BUY | Y25: 10BUY | Z25: 10BUY | AA25: 10BUY | AB25: 10BUY | AC25: 10BUY | AD25: 10BUY
A26: BTS
A27: 裁斷/C | E27: 6 | F27: 6 | G27: 6 | I27: 6
A28: SKU | B28: 3J256C | D28: 3J256C | E28: 763532C | F28: 763532C | G28: 663608C | I28: 663608C | N28: 663605C | O28: 663605C | Y28: 663599C | Z28: 664184C | AA28: 664184C | AB28: 664434C | AC28: 651830C | AD28: 617660F
A29: 針車/M | D29: 4size | E29: in | F29: in | G29: in | I29: in | N29: OK12/13 | O29: -5
A30: 數量/SL | B30: 240 | D30: 480 | E30: 504 | F30: 336 | G30: 1788 | I30: 678 | N30: 828 | O30: 624 | Y30: 1800 | Z30: 576 | AA30: 156 | AB30: 324 | AC30: 1284 | AD30: 1116
A31: 成型/G | B31: OK12/5 | D31: OK12/4 | E31: OK12/5 | F31: OK12/7 | G31: OK12/8 | I31: OK12/10 | N31: in | O31: in | Y31: in | Z31: in | AA31: in | AB31: in | AC31: in
A32: CSD | B32: 43464 | D32: 43468 | E32: 43444 | F32: 43460 | G32: 43448 | I32: 43448 | N32: 43475 | O32: 43490 | Y32: 43488 | Z32: 43481 | AA32: 43510 | AB32: 43482 | AC32: 43493 | AD32: 43482
A33: 國家/N | B33: NEW ZEALAND | D33: BV | E33: USA | F33: BV | G33: USA | I33: USA | N33: USA | O33: USA | Y33: BV | Z33: CANADA | AA33: CANADA | AB33: CANADA | AC33: MEXICO | AD33: USA
A34: LY | B34: 6G CTAS OX | D34: 6G CTAS OX | O34: SA216J-3B | AA34: KD686A-8 | AB34: KD686A-8 | AC34: KD686B-7A
A35: RY | B35: Y1812-0883 | D35: Y1902-0334 | O35: Y1903-0055 | AA35: Y1902-0491 | AB35: Y1901-0283 | AC35: Y1902-0454
A36: 材料/VT | B36: 43432 | D36: 12/01 | O36: 43439 | AA36: 12/10 | AB36: 12/05 | AC36: 12/05
A37: CHAT LIEU | B37: 基本型體 | D37: 基本型體 | O37: 皮+星星月亮 | AA37: 布+星星月亮 | AB37: 布+星星月亮 | AC37: PU+星星月亮
A38: Last# | B38: 01L-1 | D38: 01L-1 | O38: 01H-1 | AA38: 01L-1 | AB38: 01L-1 | AC38: 01L-1
A39: BUY | B39: 10BUY | D39: 10BUY | O39: 10BUY | AA39: 10BUY | AB39: 10BUY | AC39: 10BUY
A40: BTS
...

Sheet T01
A1: A1-01 廠 2019 年 01月 份 生 產 進 度 表--成型 / A1 LEAN01(CONVERSE)A7棟
D2: 裁斷 | H2: 針車 | J2: 成型 | U2: 本月目標: | W2: =+AG243+AG183+AG123+AG63 -> 188719 | AA2: 雙 | AD2: (PRS) | AF2: 43476
A3: D/T | B3: 43466 | C3: 43467 | D3: 43468 | E3: 43469 | F3: 43470 | G3: 43471 | H3: 43472 | I3: 43473 | J3: 43474 | K3: 43475 | L3: 43476 | M3: 43477 | N3: 43478 | O3: 43479 | P3: 43480 | Q3: 43481 | R3: 43482 | S3: 43483 | T3: 43484 | U3: 43485 | V3: 43486 | W3: 43487 | X3: 43488 | Y3: 43489 | Z3: 43490 | AA3: 43491 | AB3: 43492 | AC3: 43493 | AD3: 43494 | AE3: 43495 | AF3: 43496 | AG3: TTL
A4: LINE | B4: 二 | C4: =IF(B4="日","一",IF(B4="一","二",IF(B4="二","三",IF(B4="三","四",IF(B4="四","五",IF(B4="五","六",IF(B4="六","日",""))))))) -> 三 | D4: =IF(C4="日","一",IF(C4="一","二",IF(C4="二","三",IF(C4="三","四",IF(C4="四","五",IF(C4="五","六",IF(C4="六","日",""))))))) -> 四 | E4: =IF(D4="日","一",IF(D4="一","二",IF(D4="二","三",IF(D4="三","四",IF(D4="四","五",IF(D4="五","六",IF(D4="六","日",""))))))) -> 五 | F4: =IF(E4="日","一",IF(E4="一","二",IF(E4="二","三",IF(E4="三","四",IF(E4="四","五",IF(E4="五","六",IF(E4="六","日",""))))))) -> 六 | G4: =IF(F4="日","一",IF(F4="一","二",IF(F4="二","三",IF(F4="三","四",IF(F4="四","五",IF(F4="五","六",IF(F4="六","日",""))))))) -> 日 | H4: =IF(G4="日","一",IF(G4="一","二",IF(G4="二","三",IF(G4="三","四",IF(G4="四","五",IF(G4="五","六",IF(G4="六","日",""))))))) -> 一 | I4: =IF(H4="日","一",IF(H4="一","二",IF(H4="二","三",IF(H4="三","四",IF(H4="四","五",IF(H4="五","六",IF(H4="六","日",""))))))) -> 二 | J4: =IF(I4="日","一",IF(I4="一","二",IF(I4="二","三",IF(I4="三","四",IF(I4="四","五",IF(I4="五","六",IF(I4="六","日",""))))))) -> 三 | ... AF4: =IF(AE4="日","一",IF(AE4="一","二",IF(AE4="二","三",IF(AE4="三","四",IF(AE4="四","五",IF(AE4="五","六",IF(AE4="六","日",""))))))) -> 四 | AH4: =+AH5*9.5 -> 171 | AI4: =+AI5*8 -> 64 | AJ4: so ngay
C5: 9.5 | D5: 9.5 | E5: 9.5 | F5: 8 | H5: 9.5 | I5: 9.5 | J5: 9.5 | K5: 9.5 | L5: 9.5 | M5: 8 | O5: 9.5 | P5: 9.5 | Q5: 9.5 | R5: 9.5 | S5: 9.5 | T5: 8 | V5: 9.5 | W5: 9.5 | X5: 9.5 | Y5: 9.5 | Z5: 9.5 | AA5: 8 | AC5: 8 | AD5: 8 | AE5: 8 | AF5: 8 | AG5: =SUM(B5:AF5) -> 235 | AH5: =COUNTIF(B5:AF5,9.5) -> 18 | AI5: =COUNTIF(B5:AG5,8) -> 8 | AJ5: =COUNTA(B5:AF5) -> 26
A6: LY | C6: 01H-D | D6: 01H-D | E6: KD251B-10 | F6: KD251B-10 | H6: KD251B-10 | I6: KD251B-10 | J6: KD251B-10 | L6: KD251B-10 | M6: KD251B-12 | O6: KD251B-12 | P6: KD251A | Q6: SA216J | R6: SA086J | W6: KD686A-8 | X6: KD686A-8 | Y6: KD686A-8 | Z6: KD686A-8 | AA6: 6G CTAS OX | AC6: 6G CTAS OX | AD6: 6G CTAS OX | AE6: 6G CTAS OX
A7: RY | C7: Y1901-0296 | D7: Y1901-0299 | E7: Y1902-0098 | F7: Y1901-0261 | H7: Y1902-0183 | I7: Y1902-0184 | J7: Y1901-0260 | L7: Y1903-0147 | M7: Y1902-0116 | O7: Y1902-0195 | P7: Y1902-0448 | Q7: 39 | R7: 45 | W7: Y1903-0149 | X7: Y1902-0127 | Y7: Y1903-0150 | Z7: Y1902-0571 | AA7: Y1902-0679 | AC7: Y1902-0683 | AD7: Y1902-0666 | AE7: Y1903-0300
A8: 材料/VT | C8: =VLOOKUP(C7,'[2]2019-02'!$A$3:$G$1657,7,0) -> OK | D8: =VLOOKUP(D7,'[2]2019-02'!$A$3:$G$1657,7,0) -> OK | E8: =VLOOKUP(E7,'[2]2019-02'!$A$3:$G$1657,7,0) -> OK | F8: =VLOOKUP(F7,'[2]2019-02'!$A$3:$G$1657,7,0) -> OK | H8: =VLOOKUP(H7,'[2]2019-02'!$A$3:$G$1657,7,0) -> OK | I8: =VLOOKUP(I7,'[2]2019-02'!$A$3:$G$1657,7,0) -> OK | J8: =VLOOKUP(J7,'[2]2019-02'!$A$3:$G$1657,7,0) -> OK | L8: =VLOOKUP(L7,'[2]2019-02'!$A$3:$G$1657,7,0) -> 12/21 | M8: =VLOOKUP(M7,'[2]2019-02'!$A$3:$G$1657,7,0) -> OK | O8: =VLOOKUP(O7,'[2]2019-02'!$A$3:$G$1657,7,0) -> OK | P8: =VLOOKUP(P7,'[2]2019-02'!$A$3:$G$1657,7,0) -> OK | Q8: 666047C | R8: 666042C | W8: =VLOOKUP(W7,'[2]2019-02'!$A$3:$G$1657,7,0) -> 12/28 | X8: =VLOOKUP(X7,'[2]2019-02'!$A$3:$G$1657,7,0) -> OK | Y8: =VLOOKUP(Y7,'[2]2019-02'!$A$3:$G$1657,7,0) -> 01/03 | Z8: =VLOOKUP(Z7,'[2]2019-02'!$A$3:$G$1657,7,0) -> 01/03 | AA8: =VLOOKUP(AA14,'[3]2018-11-16'!$A:$D,4,0) -> 基本型體 | AC8: =VLOOKUP(AC14,'[3]2018-11-16'!$A:$D,4,0) -> 基本型體 | AD8: =VLOOKUP(AD14,'[3]2018-11-16'!$A:$D,4,0) -> 基本型體 | AE8: =VLOOKUP(AE14,'[3]2018-11-16'!$A:$D,4,0) -> 基本型體
A9: CHAT LIEU | C9: 布 | D9: 布 | E9: 布 | F9: 布 | H9: 布 | I9: 布 | J9: 布 | L9: 布 | M9: 布 | O9: 布 | P9: PU | Q9: 35 | R9: 90 | W9: 布 | X9: 布 | Y9: 布 | Z9: 布
A10: Last# | C10: 01H-1 | D10: 01H-1 | E10: W-2689L | F10: W-2689L | H10: W-2689L | I10: W-2689L | J10: W-2689L | L10: W-2689L | M10: W-2689L | O10: W-2689L | P10: W-2689 | W10: 01L-1 | X10: 01L-1 | Y10: 01L-1 | Z10: 01L-1 | AA10: 01L-1 | AC10: 01L-1 | AD10: 01L-1 | AE10: 01L-1
A11: BUY | C11: 10BUY | D11: 10BUY | E11: 10BUY | F11: 10BUY | H11: 10BUY | I11: 10BUY | J11: 10BUY | L11: 11BUY | M11: 10BUY | O11: 10BUY | P11: 10BUY | Q11: SA216J | R11: SA086J | W11: 11BUY | X11: 10BUY | Y11: 11BUY | Z11: 11BUY | AA11: 12BUY | AC11: 12BUY | AD11: 12BUY | AE11: 12BUY
A12: BTS | Q12: 40 | R12: 46
A13: 裁斷/C | C13: 5 | D13: 5 | E13: 3 | F13: 3 | H13: 3 | I13: 3 | J13: 3 | L13: 3 | M13: 3 | O13: 3 | P13: 3 | Q13: 666048C | R13: 666043C | W13: 5 | X13: 5 | Y13: 5 | Z13: 5 | AA13: 1 | AC13: 1 | AD13: 1 | AE13: 1
A14: SKU | C14: 617660F | D14: 617663F | E14: 763527C | F14: 764438C | H14: 764438C | I14: 764439C | J14: 764437C | L14: 764437C | M14: 764861C | O14: 764862C | P14: 751878C | Q14: 74 | R14: 88 | W14: 664434C | X14: 664436C | Y14: 664436C | Z14: 664435C | AA14: 3J235C | AC14: 3J235C | AD14: 3J237C | AE14: 3J238
A15: 針車/M
A16: 數量/SL | C16: 468 | D16: 588 | E16: 1800 | F16: 168 | H16: 408 | I16: 408 | J16: 168 | L16: 1824 | M16: 1800 | O16: 600 | P16: 1800 | Q16: SA216J | R16: SA086N | W16: 1800 | X16: 1764 | Y16: 1800 | Z16: 1800 | AA16: 864 | AC16: 360 | AD16: 672 | AE16: 5700
A17: 成型/G | C17: OK1/4 | D17: OK1/5 | E17: -4 | F17: OK1/7 | H17: OK1/10 | I17: -5 | J17: -5 | M17: in | O17: in | P17: in | Q17: 41 | R17: 47 | X17: in
A18: CSD | C18: 43490 | D18: 43490 | E18: 43507 | F18: 43490 | H18: 43510 | I18: 43510 | J18: 43490 | L18: 43542 | M18: 43507 | O18: 43510 | P18: 43493 | Q18: 666049C | R18: 766045C | W18: 43543 | X18: 43508 | Y18: 43539 | Z18: 43522 | AA18: 43520 | AC18: 43520 | AD18: 43519 | AE18: 43535
A19: 國家/N | C19: USA | D19: USA | E19: BV | F19: USA | H19: BV | I19: BV | J19: USA | L19: BV | M19: BV | O19: BV | P19: MEXICO | Q19: 41 | R19: 51.5 | W19: BV | X19: BV | Y19: BV | Z19: BV | AA19: AUSTRALIA | AC19: NEW ZEALAND | AD19: BV | AE19: USA
A20: LY | C20: 01H-D | D20: 01H-D | F20: KD251B-10 | H20: KD251B-10 | I20: KD251B-10 | J20: KD251B-10 | O20: KD251B-12 | AA20: 6G CTAS OX | AD20: 6G CTAS OX
A21: RY | C21: Y1902-0296 | D21: Y1902-0297 | F21: Y1902-0114 | H21: Y1901-0262 | I21: Y1903-0148 | J21: Y1902-0113 | O21: Y1902-0119 | Q21: SA216J | R21: SA086N | AA21: Y1903-0329 | AD21: Y1902-0695
A22: 材料/VT | C22: =VLOOKUP(C21,'[2]2019-02'!$A$3:$G$1657,7,0) -> OK | D22: =VLOOKUP(D21,'[2]2019-02'!$A$3:$G$1657,7,0) -> OK | F22: =VLOOKUP(F21,'[2]2019-02'!$A$3:$G$1657,7,0) -> OK | H22: =VLOOKUP(H21,'[2]2019-02'!$A$3:$G$1657,7,0) -> OK | I22: =VLOOKUP(I21,'[2]2019-02'!$A$3:$G$1657,7,0) -> 01/03 | J22: =VLOOKUP(J21,'[2]2019-02'!$A$3:$G$1657,7,0) -> OK | O22: =VLOOKUP(O21,'[2]2019-02'!$A$3:$G$1657,7,0) -> OK | Q22: 42 | R22: 48 | AA22: =VLOOKUP(AA28,'[3]2018-11-16'!$A:$D,4,0) -> 基本型體 | AD22: =VLOOKUP(AD28,'[3]2018-11-16'!$A:$D,4,0) -> 基本型體
A23: CHAT LIEU | C23: 布 | D23: 布 | F23: 布 | H23: 布 | I23: 布 | J23: 布 | O23: 布 | Q23: 666050C | R23: 766046C
A24: Last# | C24: 01H-1 | D24: 01H-1 | F24: W-2689L | H24: W-2689L | I24: W-2689L | J24: W-2689L | O24: W-2689L | Q24: 42 | R24: 51 | AA24: 01L-1 | AD24: 01L-1
A25: BUY | C25: 10BUY | D25: 10BUY | F25: 10BUY | H25: 10BUY | I25: 11BUY | J25: 10BUY | O25: 10BUY | AA25: 12BUY | AD25: 12BUY
A26: BTS | Q26: SA216J | R26: SA170J
A27: 裁斷/C | C27: 5 | D27: 5 | F27: 3 | H27: 3 | I27: 3 | J27: 3 | O27: 3 | Q27: 43 | R27: 35 | AA27: 1 | AD27: 1
A28: SKU | C28: 617660F | D28: 617663F | F28: 764438C | H28: 764439C | I28: 764439C | J28: 764437C | O28: 764862C | Q28: 766051C | R28: 666039C | AA28: 3J235C | AD28: 3J237C
A29: 針車/M | Q29: 80 | R29: 63
A30: 數量/SL | C30: 528 | D30: 612 | F30: 1224 | H30: 168 | I30: 1812 | J30: 3420 | O30: 1728 | AA30: 1752 | AD30: 360
A31: 成型/G | C31: OK1/5 | D31: OK1/7 | F31: OK1/9 | H31: OK1/14 | I31: -5 | J31: -1404 | O31: in | Q31: SA216J | R31: SA170J
A32: CSD | C32: 43519 | D32: 43519 | F32: 43507 | H32: 43490 | I32: 43542 | J32: 43508 | O32: 43507 | Q32: 44 | R32: 36 | AA32: 43551 | AD32: 43520
A33: 國家/N | C33: USA | D33: USA | F33: BV | H33: USA | I33: BV | J33: BV | O33: BV | Q33: 766052C | R33: 666040C | AA33: BV | AD33: PERU
A34: LY | C34: 01H-D | D34: KD251B-10 | H34: KD251B-10 | Q34: 45 | R34: 56 | AD34: 6G CTAS OX
A35: RY | C35: Y1901-0236 | D35: Y1901-0178 | H35: Y1902-0115 | AD35: Y1903-0332
A36: 材料/VT | C36: =VLOOKUP(C35,'[2]2019-02'!$A$3:$G$1657,7,0) -> OK | D36: =VLOOKUP(D35,'[2]2019-02'!$A$3:$G$1657,7,0) -> OK | H36: =VLOOKUP(H35,'[2]2019-02'!$A$3:$G$1657,7,0) -> OK | R36: SA170J | AD36: =VLOOKUP(AD42,'[3]2018-11-16'!$A:$D,4,0) -> 基本型體
A37: CHAT LIEU | C37: 布 | D37: 布 | H37: 布 | R37: 37
A38: Last# | C38: 01H-1 | D38: W-2689L | H38: W-2689L | R38: 666041C | AD38: 01L-1
A39: BUY | C39: 10BUY | D39: 10BUY | H39: 10BUY | R39: 57 | AD39: 12BUY
A40: BTS
...

Sheet T02
A1: A1-01 廠 2019 年 02月 份 生 產 進 度 表--成型 / A1 LEAN01(CONVERSE)A7棟
D2: 裁斷 | H2: 針車 | J2: 成型 | U2: 本月目標: | W2: =+AD248 -> 103512 | AA2: 雙 | AC2: 43508
A3: D/T | B3: 43497 | C3: 43498 | D3: 43499 | E3: 43500 | F3: 43501 | G3: 43502 | H3: 43503 | I3: 43504 | J3: 43505 | K3: 43506 | L3: 43507 | M3: 43508 | N3: 43509 | O3: 43510 | P3: 43511 | Q3: 43512 | R3: 43513 | S3: 43514 | T3: 43515 | U3: 43516 | V3: 43517 | W3: 43518 | X3: 43519 | Y3: 43520 | Z3: 43521 | AA3: 43522 | AB3: 43523 | AC3: 43524 | AD3: TTL
A4: LINE | B4: 五 | C4: =IF(B4="日","一",IF(B4="一","二",IF(B4="二","三",IF(B4="三","四",IF(B4="四","五",IF(B4="五","六",IF(B4="六","日",""))))))) -> 六 | D4: =IF(C4="日","一",IF(C4="一","二",IF(C4="二","三",IF(C4="三","四",IF(C4="四","五",IF(C4="五","六",IF(C4="六","日",""))))))) -> 日 | E4: =IF(D4="日","一",IF(D4="一","二",IF(D4="二","三",IF(D4="三","四",IF(D4="四","五",IF(D4="五","六",IF(D4="六","日",""))))))) -> 一 | F4: =IF(E4="日","一",IF(E4="一","二",IF(E4="二","三",IF(E4="三","四",IF(E4="四","五",IF(E4="五","六",IF(E4="六","日",""))))))) -> 二 | G4: =IF(F4="日","一",IF(F4="一","二",IF(F4="二","三",IF(F4="三","四",IF(F4="四","五",IF(F4="五","六",IF(F4="六","日",""))))))) -> 三 | H4: =IF(G4="日","一",IF(G4="一","二",IF(G4="二","三",IF(G4="三","四",IF(G4="四","五",IF(G4="五","六",IF(G4="六","日",""))))))) -> 四 | I4: =IF(H4="日","一",IF(H4="一","二",IF(H4="二","三",IF(H4="三","四",IF(H4="四","五",IF(H4="五","六",IF(H4="六","日",""))))))) -> 五 | J4: =IF(I4="日","一",IF(I4="一","二",IF(I4="二","三",IF(I4="三","四",IF(I4="四","五",IF(I4="五","六",IF(I4="六","日",""))))))) -> 六 | ... AC4: =IF(AB4="日","一",IF(AB4="一","二",IF(AB4="二","三",IF(AB4="三","四",IF(AB4="四","五",IF(AB4="五","六",IF(AB4="六","日",""))))))) -> 四 | AE4: =+AE6*9.5 -> 0 | AF4: =+AF6*8 -> 112 | AG4: so ngay
B5: 8 | L5: 8 | M5: 8 | N5: 8 | O5: 8 | P5: 8 | Q5: 8 | S5: 8 | T5: 8 | U5: 8 | V5: 8 | W5: 8 | X5: 8 | Z5: 8 | AA5: 8 | AB5: 8 | AC5: 8 | AD5: =SUM(B5:AC5) -> 136
B6: 4 | L6: 4 | M6: 6 | N6: 8 | O6: 8 | P6: 8 | Q6: 8 | S6: 8 | T6: 8 | U6: 8 | V6: 8 | W6: 8 | X6: 8 | Z6: 8 | AA6: 8 | AB6: 8 | AC6: 8 | AD6: =SUM(B6:AC6) -> 126 | AE6: =COUNTIF(B6:AC6,9.5) -> 0 | AF6: =COUNTIF(B6:AD6,8) -> 14 | AG6: =COUNTA(B6:AC6) -> 17
A7: LY | N7: 6G CTAS OX | Q7: 6G CTAS OX | T7: 6G CTAS OX | U7: 6G CTAS OX | V7: 6G CTAS OX | X7: 6G CTAS OX | Z7: CC-OX-A | AB7: CC-OX-A | AC7: CC-OX-A
A8: RY | N8: Y1903-0304 | Q8: Y1904-0043 | T8: Y1904-0069 | U8: Y1903-0274 | V8: Y1905-0023 | X8: ZS1903-009 | Z8: Y1903-0422 | AB8: Y1903-0424 | AC8: Y1903-0427
A9: 材料/VT | N9: =VLOOKUP(N15,'[3]2018-11-16'!$A:$D,4,0) -> 基本型體 | Q9: =VLOOKUP(Q15,'[3]2018-11-16'!$A:$D,4,0) -> 基本型體 | T9: =VLOOKUP(T15,'[3]2018-11-16'!$A:$D,4,0) -> 基本型體 | U9: =VLOOKUP(U15,'[3]2018-11-16'!$A:$D,4,0) -> 基本型體 | V9: =VLOOKUP(V15,'[3]2018-11-16'!$A:$D,4,0) -> 基本型體
A10: CHAT LIEU | N10: =VLOOKUP(N8,'[4]2019-01'!$A$3:$G$2159,7,0) -> 01/09 | Q10: =VLOOKUP(Q8,'[4]2019-01'!$A$3:$G$2159,7,0) -> 01/09 | T10: =VLOOKUP(T8,'[4]2019-01'!$A$3:$G$2159,7,0) -> 01/09 | U10: =VLOOKUP(U8,'[4]2019-01'!$A$3:$G$2159,7,0) -> 01/09 | V10: =VLOOKUP(V8,'[4]2019-01'!$A$3:$G$2159,7,0) -> 01/22 | Z10: 布+IN TL | AB10: 布+IN TL | AC10: 布+IN TL
A11: Last# | N11: 01L-1 | Q11: 01L-1 | T11: 01L-1 | U11: 01L-1 | V11: 01L-1 | X11: 01H-1 | Z11: 067L-1 | AB11: 067L-1 | AC11: 067L-1
A12: BUY | N12: 12BUY | Q12: 12BUY | T12: 12BUY | U12: 12BUY | V12: 12BUY | X12: 11 BUY | Z12: 1 BUY | AB12: 1 BUY | AC12: 1 BUY
A13: BTS
A14: 裁斷/C | N14: 1 | Q14: 1 | T14: 1 | U14: 1 | V14: 1 | AB14: 5SIZE
A15: SKU | N15: 3J238 | Q15: 3J238 | T15: 3J238C | U15: 3J236C | V15: 3J237C | X15: 326706C | Z15: 165710C | AB15: 165710C | AC15: 165710C
A16: 針車/M
A17: 數量/SL | N17: 600 | Q17: 3708 | T17: 156 | U17: 228 | V17: 4656 | X17: 192 | Z17: 610 | AB17: 1200 | AC17: 550
A18: 成型/G | U18: 5SIZE
A19: CSD | N19: 43541 | Q19: 43576 | T19: 43563 | U19: 43544 | V19: 43596 | X19: 43169 | Z19: 43532 | AB19: 43532 | AC19: 43532
A20: 國家/N | N20: USA | Q20: USA | T20: MEXICO | U20: BV | V20: BV | X20: Viet Nam | Z20: BV | AB20: BV | AC20: BV
A21: LY | N21: 6G CTAS OX | T21: 6G CTAS OX | U21: 6G CTAS OX | Z21: CC-OX-A | AC21: CC-OX-A
A22: RY | N22: Y1903-0372 | T22: Y1905-0012 | U22: Y1904-0068 | Z22: Y1903-0400 | AC22: Y1904-0147
A23: 材料/VT | N23: =VLOOKUP(N29,'[3]2018-11-16'!$A:$D,4,0) -> 基本型體 | T23: =VLOOKUP(T29,'[3]2018-11-16'!$A:$D,4,0) -> 基本型體 | U23: =VLOOKUP(U29,'[3]2018-11-16'!$A:$D,4,0) -> 基本型體
A24: CHAT LIEU | N24: =VLOOKUP(N22,'[4]2019-01'!$A$3:$G$2159,7,0) -> 01/09 | T24: =VLOOKUP(T22,'[4]2019-01'!$A$3:$G$2159,7,0) -> 01/22 | U24: =VLOOKUP(U22,'[4]2019-01'!$A$3:$G$2159,7,0) -> 01/09 | Z24: 布+IN TL | AC24: 布+IN TL
A25: Last# | N25: 01L-1 | T25: 01L-1 | U25: 01L-1 | Z25: 067L-1 | AC25: 067L-1
A26: BUY | N26: 12BUY | T26: 12BUY | U26: 12BUY | Z26: 1 BUY | AC26: 1 BUY
A27: BTS
A28: 裁斷/C | N28: 1 | T28: 1 | U28: 1
A29: SKU | N29: 3J238 | T29: 3J238C | U29: 3J237C | Z29: 165710C | AC29: 165710C
A30: 針車/M
A31: 數量/SL | N31: 5412 | T31: 1044 | U31: 1224 | Z31: 2640 | AC31: 396
A32: 成型/G
A33: CSD | N33: 43538 | T33: 43596 | U33: 43563 | Z33: 43532 | AC33: 43532
A34: 國家/N | N34: USA | T34: BV | U34: MEXICO | Z34: BV | AC34: BV
A35: LY | AC35: CC-OX-A
A36: RY | AC36: Y1903-0401
A37: 材料/VT
A38: CHAT LIEU | AC38: 布+IN TL
A39: Last# | AC39: 067L-1
A40: BUY | AC40: 1 BUY
...

Sheet T03
A1: A1-01 廠 2019 年 03月 份 生 產 進 度 表--成型 / A1 LEAN01(CONVERSE)A7棟
D2: 裁斷 | H2: 針車 | J2: 成型 | U2: 本月目標: | W2: =+AG247 -> 176888 | AA2: 雙 | AD2: (PRS) | AE2: 43508
A3: D/T | B3: 43525 | C3: 43526 | D3: 43527 | E3: 43528 | F3: 43529 | G3: 43530 | H3: 43531 | I3: 43532 | J3: 43533 | K3: 43534 | L3: 43535 | M3: 43536 | N3: 43537 | O3: 43538 | P3: 43539 | Q3: 43540 | R3: 43541 | S3: 43542 | T3: 43543 | U3: 43544 | V3: 43545 | W3: 43546 | X3: 43547 | Y3: 43548 | Z3: 43549 | AA3: 43550 | AB3: 43551 | AC3: 43552 | AD3: 43553 | AE3: 43554 | AF3: 43555 | AG3: TTL
A4: LINE | B4: 五 | C4: =IF(B4="日","一",IF(B4="一","二",IF(B4="二","三",IF(B4="三","四",IF(B4="四","五",IF(B4="五","六",IF(B4="六","日",""))))))) -> 六 | D4: =IF(C4="日","一",IF(C4="一","二",IF(C4="二","三",IF(C4="三","四",IF(C4="四","五",IF(C4="五","六",IF(C4="六","日",""))))))) -> 日 | E4: =IF(D4="日","一",IF(D4="一","二",IF(D4="二","三",IF(D4="三","四",IF(D4="四","五",IF(D4="五","六",IF(D4="六","日",""))))))) -> 一 | F4: =IF(E4="日","一",IF(E4="一","二",IF(E4="二","三",IF(E4="三","四",IF(E4="四","五",IF(E4="五","六",IF(E4="六","日",""))))))) -> 二 | G4: =IF(F4="日","一",IF(F4="一","二",IF(F4="二","三",IF(F4="三","四",IF(F4="四","五",IF(F4="五","六",IF(F4="六","日",""))))))) -> 三 | H4: =IF(G4="日","一",IF(G4="一","二",IF(G4="二","三",IF(G4="三","四",IF(G4="四","五",IF(G4="五","六",IF(G4="六","日",""))))))) -> 四 | I4: =IF(H4="日","一",IF(H4="一","二",IF(H4="二","三",IF(H4="三","四",IF(H4="四","五",IF(H4="五","六",IF(H4="六","日",""))))))) -> 五 | J4: =IF(I4="日","一",IF(I4="一","二",IF(I4="二","三",IF(I4="三","四",IF(I4="四","五",IF(I4="五","六",IF(I4="六","日",""))))))) -> 六 | ... AF4: =IF(AE4="日","一",IF(AE4="一","二",IF(AE4="二","三",IF(AE4="三","四",IF(AE4="四","五",IF(AE4="五","六",IF(AE4="六","日",""))))))) -> 日 | AH4: =+AH5*9.5 -> 190 | AI4: =+AI5*8 -> 48 | AJ4: so ngay
B5: 8 | C5: 8 | E5: 9.5 | F5: 9.5 | G5: 9.5 | H5: 9.5 | I5: 9.5 | J5: 8 | L5: 9.5 | M5: 9.5 | N5: 9.5 | O5: 9.5 | P5: 9.5 | Q5: 8 | S5: 9.5 | T5: 9.5 | U5: 9.5 | V5: 9.5 | W5: 9.5 | X5: 8 | Z5: 9.5 | AA5: 9.5 | AB5: 9.5 | AC5: 9.5 | AD5: 9.5 | AE5: 8 | AG5: =SUM(B5:AF5) -> 238 | AH5: =COUNTIF(B5:AF5,9.5) -> 20 | AI5: =COUNTIF(B5:AG5,8) -> 6 | AJ5: =COUNTA(B5:AF5) -> 26
A6: LY | C6: CC-OX-A | E6: CC-OX-A | F6: CC-OX-A | G6: SA216J-B-3 | M6: SA216J-B-3 | O6: SA216J-B-3 | S6: SA216J-B-3 | T6: SA216J-B-3 | U6: SA216J-B-3 | V6: SA216J-B-3 | W6: SA216J-B-3 | X6: SA216J-B-3 | AA6: SA216N-5B | AB6: SA216N-5B | AC6: SA216N-8B | AD6: SA216N-8A | AE6: SA216N-7B
A7: RY | C7: Y1903-0402 | E7: Y1904-0392 | F7: Y1904-0342 | G7: Y1904-0112 | M7: Y1904-0113 | O7: Y1904-0253 | S7: Y1903-0429 | T7: Y1904-0280 | U7: Y1904-0202 | V7: Y1904-0507 | W7: Y1904-0215 | X7: Y1905-0062 | AA7: Y1904-0279 | AB7: Y1904-0733 | AC7: Y1904-0651 | AD7: Y1904-0294 | AE7: Y1904-0296
A8: 材料/VT
A9: CHAT LIEU | E9: VẢI 布 | F9: VẢI 布 | G9: 皮+星星月亮 | M9: 皮+星星月亮 | O9: 皮+星星月亮 | S9: 皮+星星月亮 | T9: 皮+星星月亮 | U9: 皮+星星月亮 | V9: 皮+星星月亮 | W9: 皮+星星月亮 | X9: 皮+星星月亮 | AA9: 皮+星星月亮 | AB9: 皮+星星月亮 | AC9: 反毛皮+in | AD9: vải布+星星月亮 | AE9: 皮+in
A10: Last# | C10: 067L-1 | E10: 067L-1 | F10: 067L-1 | G10: 01H-1 | M10: 01H-1 | O10: 01H-1 | S10: 01H-1 | T10: 01H-1 | U10: 01H-1 | V10: 01H-1 | W10: 01H-1 | X10: 01H-1 | AA10: W-2689H | AB10: W-2689H | AC10: W-2689H | AD10: W-2689H | AE10: W-2689H
A11: BUY | C11: 1Buy | E11: 1 BUY | F11: 1 BUY | G11: 1 BUY | M11: 1 BUY | O11: 1 BUY | S11: 1 BUY | T11: 1 BUY | U11: 1 BUY | V11: 1 BUY | W11: 1 BUY | X11: 1 BUY | AA11: 1 BUY | AB11: 1 BUY | AC11: 1 BUY | AD11: 1 BUY | AE11: 1 BUY
A12: BTS
A13: 裁斷/C | V13: 5SIZE
A14: SKU | C14: 165710C | E14: 165895F | F14: 165895F | G14: 661927C | M14: 661929C | O14: 662817C | S14: 662817C | T14: 662817C | U14: 662817C | V14: 662817C | W14: 662817C | X14: 662817C | AA14: 763532C | AB14: 763532C | AC14: 765281C | AD14: 765286F | AE14: 765296C
A15: 針車/M
A16: 數量/SL | C16: 3110 | E16: 600 | F16: 1152 | G16: 7668 | M16: 3744 | O16: 4872 | S16: 2292 | T16: 276 | U16: 1512 | V16: 624 | W16: 312 | X16: 300 | AA16: 1092 | AB16: 3024 | AC16: 216 | AD16: 312 | AE16: 708
A17: 成型/G
A18: CSD | C18: 43576 | E18: 43576 | F18: 43576 | G18: 43561 | M18: 43578 | O18: 43574 | S18: 43576 | T18: 43576 | U18: 43579 | V18: 43581 | W18: 43581 | X18: 43586 | AA18: 43576 | AB18: 43575 | AC18: 43590 | AD18: 43590 | AE18: 43590
A19: 國家/N | C19: USA | E19: USA | F19: USA | G19: USA | M19: USA | O19: BV | S19: CANADA | T19: USA | U19: CANADA | V19: BV | W19: BV | X19: Canada | AA19: USA | AB19: CHILE | AC19: BV | AD19: USA | AE19: USA
A20: LY | E20: CC-OX-A | U20: SA216J-B-3 | V20: SA216J-B-3 | W20: SA216J-B-3 | X20: SA216N-13B | AA20: SA216N-5B | AC20: SA216N-8B | AD20: SA216N-7B
A21: RY | E21: Y1904-0398 | U21: Y1904-0892 | V21: Y1904-0897 | W21: Y1904-0657 | X21: Y1904-0314 | AA21: Y1904-0574 | AC21: Y1904-0515 | AD21: Y1904-0182
A22: 材料/VT
A23: CHAT LIEU | E23: VẢI 布 | U23: 皮+星星月亮 | V23: 皮+星星月亮 | W23: 皮+星星月亮 | X23: 皮+星星月亮 | AA23: 皮+星星月亮 | AC23: 反毛皮+in | AD23: 皮+in
A24: Last# | E24: 067L-1 | U24: 01H-1 | V24: 01H-1 | W24: 01H-1 | X24: W-2689 | AA24: W-2689H | AC24: W-2689H | AD24: W-2689H
A25: BUY | E25: 1 BUY | U25: 1 BUY | V25: 1 BUY | W25: 1 BUY | X25: 1 BUY | AA25: 1 BUY | AC25: 1 BUY | AD25: 1 BUY
A26: BTS
A27: 裁斷/C | E27: 4SIZE | V27: 5SIZE
A28: SKU | E28: 165895F | U28: 662817C | V28: 662817C | W28: 662817C | X28: 762011C | AA28: 763532C | AC28: 765281C | AD28: 765296C
A29: 針車/M
A30: 數量/SL | E30: 900 | U30: 240 | V30: 288 | W30: 132 | X30: 2736 | AA30: 288 | AC30: 144 | AD30: 360
A31: 成型/G
A32: CSD | E32: 43576 | U32: 43579 | V32: 43581 | W32: 43581 | X32: 43578 | AA32: 43581 | AC32: 43590 | AD32: 43590
A33: 國家/N | E33: USA | U33: CANADA | V33: BV | W33: BV | X33: USA | AA33: BV | AC33: BV | AD33: CANADA
A34: LY | V34: SA216J-B-3 | W34: SA216J-B-3 | AC34: SA216N-8A | AD34: SA216N-7B
A35: RY | V35: Y1904-0211 | W35: Y1904-0232 | AC35: Y1904-0293 | AD35: Y1904-0295
A36: 材料/VT
A37: CHAT LIEU | V37: 皮+星星月亮 | W37: 皮+星星月亮 | AC37: vải布+星星月亮 | AD37: 皮+in
A38: Last# | V38: 01H-1 | W38: 01H-1 | AC38: W-2689H | AD38: W-2689H
A39: BUY | V39: 1 BUY | W39: 1 BUY | AC39: 1 BUY | AD39: 1 BUY
A40: BTS
...

Sheet T04
A1: A1-01 廠 2019 年 04月 份 生 產 進 度 表--成型 / A1 LEAN01(CONVERSE)A7棟
D2: 裁斷 | H2: 針車 | J2: 成型 | U2: 本月目標: | W2: =+AF243+AF183+AF123+AF63 -> 161519 | AA2: 雙 | AD2: (PRS)
A3: D/T | B3: 43556 | C3: 43557 | D3: 43558 | E3: 43559 | F3: 43560 | G3: 43561 | H3: 43562 | I3: 43563 | J3: 43564 | K3: 43565 | L3: 43566 | M3: 43567 | N3: 43568 | O3: 43569 | P3: 43570 | Q3: 43571 | R3: 43572 | S3: 43573 | T3: 43574 | U3: 43575 | V3: 43576 | W3: 43577 | X3: 43578 | Y3: 43579 | Z3: 43580 | AA3: 43581 | AB3: 43582 | AC3: 43583 | AD3: 43584 | AE3: 43585 | AF3: TTL
A4: LINE | B4: 一 | C4: =IF(B4="日","一",IF(B4="一","二",IF(B4="二","三",IF(B4="三","四",IF(B4="四","五",IF(B4="五","六",IF(B4="六","日",""))))))) -> 二 | D4: =IF(C4="日","一",IF(C4="一","二",IF(C4="二","三",IF(C4="三","四",IF(C4="四","五",IF(C4="五","六",IF(C4="六","日",""))))))) -> 三 | E4: =IF(D4="日","一",IF(D4="一","二",IF(D4="二","三",IF(D4="三","四",IF(D4="四","五",IF(D4="五","六",IF(D4="六","日",""))))))) -> 四 | F4: =IF(E4="日","一",IF(E4="一","二",IF(E4="二","三",IF(E4="三","四",IF(E4="四","五",IF(E4="五","六",IF(E4="六","日",""))))))) -> 五 | G4: =IF(F4="日","一",IF(F4="一","二",IF(F4="二","三",IF(F4="三","四",IF(F4="四","五",IF(F4="五","六",IF(F4="六","日",""))))))) -> 六 | H4: =IF(G4="日","一",IF(G4="一","二",IF(G4="二","三",IF(G4="三","四",IF(G4="四","五",IF(G4="五","六",IF(G4="六","日",""))))))) -> 日 | I4: =IF(H4="日","一",IF(H4="一","二",IF(H4="二","三",IF(H4="三","四",IF(H4="四","五",IF(H4="五","六",IF(H4="六","日",""))))))) -> 一 | J4: =IF(I4="日","一",IF(I4="一","二",IF(I4="二","三",IF(I4="三","四",IF(I4="四","五",IF(I4="五","六",IF(I4="六","日",""))))))) -> 二 | ... AE4: =IF(AD4="日","一",IF(AD4="一","二",IF(AD4="二","三",IF(AD4="三","四",IF(AD4="四","五",IF(AD4="五","六",IF(AD4="六","日",""))))))) -> 二 | AG4: =+AG5*9.5 -> 180.5 | AH4: =+AH5*8 -> 40 | AI4: so ngay
B5: 9.5 | C5: 9.5 | D5: 9.5 | E5: 9.5 | F5: 9.5 | G5: 8 | I5: 9.5 | J5: 9.5 | K5: 9.5 | L5: 9.5 | M5: 9.5 | N5: 8 | Q5: 9.5 | R5: 9.5 | S5: 9.5 | T5: 9.5 | U5: 8 | W5: 9.5 | X5: 9.5 | Y5: 9.5 | Z5: 9.5 | AA5: 9.5 | AB5: 8 | AD5: 8 | AF5: =SUM(B5:AE5) -> 220.5 | AG5: =COUNTIF(B5:AE5,9.5) -> 19 | AH5: =COUNTIF(B5:AF5,8) -> 5 | AI5: =COUNTA(B5:AE5) -> 24
A6: LY | B6: SA216N-7B | C6: SA216J-8A | E6: SA216J-8A | F6: SA216J-8A | G6: SA216J-7B | R6: SA216J-8B | S6: SA216J-8B | T6: SA216J-8B | U6: SA216J-8B | W6: SA216J-8B | X6: SA216J-8B | Y6: SA216J-8B | Z6: SA216J-8B
A7: RY | B7: Y1904-0183 | C7: Y1904-0300 | E7: Y1904-0404 | F7: Y1904-0349 | G7: Y1904-0267 | R7: Y1904-0519 | S7: Y1904-0431 | T7: Y1904-0453 | U7: Y1904-0432 | W7: Y1905-0165 | X7: Y1905-0574 | Y7: Y1905-0166 | Z7: Y1905-0567
A8: 材料/VT
A9: CHAT LIEU | B9: 皮+in | C9: VẢI 布 | E9: VẢI 布 | F9: VẢI 布 | G9: 皮+in | R9: 反毛皮+in | S9: 反毛皮+in | T9: 反毛皮+in | U9: 反毛皮+in | W9: 反毛皮+in | X9: 反毛皮+in | Y9: 反毛皮+in | Z9: 反毛皮+in
A10: Last# | B10: W-2689H | C10: 01H-1 | E10: 01H-1 | F10: 01H-1 | G10: 01H-1 | R10: 01H-1 | S10: 01H-1 | T10: 01H-1 | U10: 01H-1 | W10: 01H-1 | X10: 01H-1 | Y10: 01H-1 | Z10: 01H-1
A11: BUY | B11: 1 BUY | C11: 1 BUY | E11: 1 BUY | F11: 1 BUY | G11: 1 BUY | R11: 1 BUY | S11: 1 BUY | T11: 1Buy | U11: 1 BUY | W11: 1 BUY | X11: 1 BUY | Y11: 1 BUY | Z11: 1 BUY
A12: BTS
A13: 裁斷/C | R13: 5SIZE
A14: SKU | B14: 765297C | C14: 665284F | E14: 665285F | F14: 665285F | G14: 665292C | R14: 665277C | S14: 665277C | T14: 665278C | U14: 665279C | W14: 665277C | X14: 665277C | Y14: 665278C | Z14: 665278C
A15: 針車/M
A16: 數量/SL | B16: 252 | C16: 946 | E16: 648 | F16: 2568 | G16: 12624 | R16: 576 | S16: 300 | T16: 252 | U16: 396 | W16: 1356 | X16: 120 | Y16: 2256 | Z16: 120
A17: 成型/G
A18: CSD | B18: 43590 | C18: 43590 | E18: 43590 | F18: 43590 | G18: 43593 | R18: 43590 | S18: 43590 | T18: 43590 | U18: 43590 | W18: 43594 | X18: 43600 | Y18: 43594 | Z18: 43600
A19: 國家/N | B19: CANADA | C19: USA | E19: USA | F19: USA | G19: BV | R19: BV | S19: BV | T19: BV | U19: BV | W19: BV | X19: MEXICO | Y19: BV | Z19: MEXICO
A20: LY | B20: SA216N-7B | C20: SA216J-8A | R20: SA216J-8B | S20: SA216J-8B | T20: SA216J-8B | U20: SA216J-8B | W20: SA216J-8B | X20: SA216J-8B | Z20: SA216J-8B
A21: RY | B21: Y1904-0297 | C21: Y1904-0185 | R21: Y1904-0470 | S21: Y1904-0647 | T21: Y1904-0483 | U21: Y1904-0648 | W21: Y1905-0462 | X21: Y1905-0575 | Z21: Y1905-0600
A22: 材料/VT
A23: CHAT LIEU | B23: 皮+in | C23: 布+TC+IN | R23: 反毛皮+in | S23: 反毛皮+in | U23: 反毛皮+in | W23: 反毛皮+in | X23: 反毛皮+in | Z23: 反毛皮+in
A24: Last# | B24: W-2689H | C24: 01H-1 | R24: 01H-1 | S24: 01H-1 | T24: 01H-1 | U24: 01H-1 | W24: 01H-1 | X24: 01H-1 | Z24: 01H-1
A25: BUY | B25: 1 BUY | C25: 1 BUY | R25: 1 BUY | S25: 1 BUY | T25: 1Buy | U25: 1 BUY | W25: 1 BUY | X25: 1 BUY | Z25: 1 BUY
A26: BTS
A27: 裁斷/C | R27: 5SIZE
A28: SKU | B28: 765297C | C28: 665285C | R28: 665277C | S28: 665277C | T28: 665278C | U28: 665279C | W28: 665277C | X28: 665277C | Z28: 665278C
A29: 針車/M
A30: 數量/SL | B30: 972 | C30: 3072 | R30: 324 | S30: 312 | T30: 228 | U30: 336 | W30: 264 | X30: 168 | Z30: 168
A31: 成型/G
A32: CSD | B32: 43590 | C32: 43590 | R32: 43590 | S32: 43590 | T32: 43590 | U32: 43590 | W32: 43595 | X32: 43600 | Z32: 43600
A33: 國家/N | B33: USA | C33: CANADA | R33: BV | S33: BV | T33: BV | U33: BV | W33: BV | X33: MEXICO | Z33: MEXICO
A34: LY | S34: SA216J-8B | T34: SA216J-8B | U34: SA216J-8B | X34: SA216J-8B | Z34: SA216J-8B
A35: RY | S35: Y1904-0661 | T35: Y1904-0529 | U35: Y1904-0663 | X35: Y1906-0044 | Z35: Y1906-0045
A36: 材料/VT
A37: CHAT LIEU | S37: 反毛皮+in | T37: 反毛皮+in | U37: 反毛皮+in | X37: 反毛皮+in | Z37: 反毛皮+in
A38: Last# | S38: 01H-1 | T38: 01H-1 | U38: 01H-1 | X38: 01H-1 | Z38: 01H-1
A39: BUY | S39: 1 BUY | T39: 1 BUY | U39: 1 BUY | X39: 1 BUY | Z39: 1 BUY
A40: BTS
...

Sheet  T05
A1: A1-01 廠 2019 年 05月 份 生 產 進 度 表--成型 / A1 LEAN01(CONVERSE)A7棟
D2: 裁斷 | H2: 針車 | J2: 成型 | U2: 本月目標: | W2: =+AG243+AG183+AG123+AG63 -> 48300 | AA2: 雙 | AD2: (PRS)
A3: D/T | B3: 43586 | C3: 43587 | D3: 43588 | E3: 43589 | F3: 43590 | G3: 43591 | H3: 43592 | I3: 43593 | J3: 43594 | K3: 43595 | L3: 43596 | M3: 43597 | N3: 43598 | O3: 43599 | P3: 43600 | Q3: 43601 | R3: 43602 | S3: 43603 | T3: 43604 | U3: 43605 | V3: 43606 | W3: 43607 | X3: 43608 | Y3: 43609 | Z3: 43610 | AA3: 43611 | AB3: 43612 | AC3: 43613 | AD3: 43614 | AE3: 43615 | AF3: 43616 | AG3: TTL
A4: LINE | B4: 三 | C4: =IF(B4="日","一",IF(B4="一","二",IF(B4="二","三",IF(B4="三","四",IF(B4="四","五",IF(B4="五","六",IF(B4="六","日",""))))))) -> 四 | D4: =IF(C4="日","一",IF(C4="一","二",IF(C4="二","三",IF(C4="三","四",IF(C4="四","五",IF(C4="五","六",IF(C4="六","日",""))))))) -> 五 | E4: =IF(D4="日","一",IF(D4="一","二",IF(D4="二","三",IF(D4="三","四",IF(D4="四","五",IF(D4="五","六",IF(D4="六","日",""))))))) -> 六 | F4: =IF(E4="日","一",IF(E4="一","二",IF(E4="二","三",IF(E4="三","四",IF(E4="四","五",IF(E4="五","六",IF(E4="六","日",""))))))) -> 日 | G4: =IF(F4="日","一",IF(F4="一","二",IF(F4="二","三",IF(F4="三","四",IF(F4="四","五",IF(F4="五","六",IF(F4="六","日",""))))))) -> 一 | H4: =IF(G4="日","一",IF(G4="一","二",IF(G4="二","三",IF(G4="三","四",IF(G4="四","五",IF(G4="五","六",IF(G4="六","日",""))))))) -> 二 | I4: =IF(H4="日","一",IF(H4="一","二",IF(H4="二","三",IF(H4="三","四",IF(H4="四","五",IF(H4="五","六",IF(H4="六","日",""))))))) -> 三 | J4: =IF(I4="日","一",IF(I4="一","二",IF(I4="二","三",IF(I4="三","四",IF(I4="四","五",IF(I4="五","六",IF(I4="六","日",""))))))) -> 四 | ... AF4: =IF(AE4="日","一",IF(AE4="一","二",IF(AE4="二","三",IF(AE4="三","四",IF(AE4="四","五",IF(AE4="五","六",IF(AE4="六","日",""))))))) -> 五 | AH4: =+AH5*9.5 -> 161.5 | AI4: =+AI5*8 -> 32 | AJ4: so ngay
C5: 9.5 | D5: 9.5 | E5: 8 | G5: 9.5 | H5: 9.5 | I5: 9.5 | J5: 9.5 | K5: 9.5 | L5: 8 | N5: 9.5 | O5: 9.5 | P5: 9.5 | Q5: 9.5 | R5: 9.5 | S5: 8 | U5: 9.5 | V5: 9.5 | W5: 9.5 | X5: 9.5 | Y5: 9.5 | Z5: 8 | AG5: =SUM(B5:AF5) -> 193.5 | AH5: =COUNTIF(B5:AF5,9.5) -> 17 | AI5: =COUNTIF(B5:AG5,8) -> 4 | AJ5: =COUNTA(B5:AF5) -> 21
A6: LY | C6: SA216J-8B | D6: SA216J-8B | E6: SA216J-8A | G6: SA216J-8A
A7: RY | C7: Y1905-0463 | D7: Y1905-0596 | E7: Y1905-0405 | G7: Y1905-0410
A8: 材料/VT
A9: CHAT LIEU | C9: 反毛皮+in | D9: 反毛皮+in | E9: 布+TC+IN | G9: 布+TC+IN
A10: Last# | C10: 01H-1 | D10: 01H-1 | E10: 01H-1 | G10: 01H-1
A11: BUY | C11: 1 BUY | D11: 1 BUY | E11: 1 BUY | G11: 1 BUY
A12: BTS
A13: 裁斷/C
A14: SKU | C14: 665279C | D14: 665279C | E14: 665284C | G14: 665285C
A15: 針車/M
A16: 數量/SL | C16: 132 | D16: 168 | E16: 372 | G16: 372
A17: 成型/G
A18: CSD | C18: 43595 | D18: 43600 | E18: 43597 | G18: 43597
A19: 國家/N | C19: BV | D19: MEXICO | E19: BV | G19: BV
A20: LY | C20: SA216J-8B | D20: SA216J-8B | E20: SA216J-8A
A21: RY | C21: Y1905-0397 | D21: Y1906-0046 | E21: Y1905-0169
A22: 材料/VT
A23: CHAT LIEU | C23: 反毛皮+in | D23: 反毛皮+in | E23: 布+TC+IN
A24: Last# | C24: 01H-1 | D24: 01H-1 | E24: 01H-1
A25: BUY | C25: 1 BUY | D25: 1 BUY | E25: 1 BUY
A26: BTS
A27: 裁斷/C
A28: SKU | C28: 665279C | D28: 665279C | E28: 665285C
A29: 針車/M
A30: 數量/SL | C30: 444 | D30: 732 | E30: 1920
A31: 成型/G
A32: CSD | C32: 43597 | D32: 43620 | E32: 43595
A33: 國家/N | C33: BV | D33: CHILE | E33: BV
A34: LY | C34: SA216J-8B | D34: SA216J-8A
A35: RY | C35: Y1905-0568 | D35: Y1905-0168
A36: 材料/VT
A37: CHAT LIEU | C37: 反毛皮+in | D37: 布+TC+IN
A38: Last# | C38: 01H-1 | D38: 01H-1
A39: BUY | C39: 1 BUY | D39: 1 BUY
A40: BTS
...

Sheet dk 1 buy
A2: Order No | B2: ARTICLE | C2: Cust PO | D2: Pairs Qty | E2: BOM TAKER | F2: Nation | G2: BUY§O | H2: NOTE | K2: HI CR-XXX | L2: OX CR-XXX
A3: Y1903-0397 | B3: 165709C | C3: 2018121201 | D3: 250 | E3: KITTY | F3: NETHERLANDS B.V | G3: 201901 19F | H3: Pre-built | K3: YL1902-0002 | L3: YL1902-0004-2
A4: Y1903-0398 | B4: 165709C | C4: 2018121202 | D4: 4495 | E4: KITTY | F4: CHINA | G4: 201901 19F | H4: Pre-built
A5: Y1903-0399 | B5: 165709C | C5: 2018121203 | D5: 3310 | E5: KITTY | F5: USA | G5: 201901 19F | H5: Pre-built
K6: 067H-1 | L6: 067L-1
A7: Y1903-0400 | B7: 165710C | C7: 2018121204 | D7: 250 | E7: JOHN | F7: NETHERLANDS B.V | G7: 201901 19F | H7: Pre-built | K7: 1 BUY ĐHN | L7: 1 BUY ĐHN
A8: Y1903-0401 | B8: 165710C | C8: 2018121205 | D8: 2495 | E8: JOHN | F8: CHINA | G8: 201901 19F | H8: Pre-built
A9: Y1903-0402 | B9: 165710C | C9: 2018121206 | D9: 3110 | E9: JOHN | F9: USA | G9: 201901 19F | H9: Pre-built
K10: M7650C | L10: M7652C
A11: Y1903-0403 | B11: 365711C | C11: 2018121207 | D11: 6100 | E11: JEANIE | F11: NETHERLANDS B.V | G11: 201901 19F | H11: Pre-built
A12: Y1903-0404 | B12: 365711C | C12: 2018121208 | D12: 891 | E12: JEANIE | F12: USA | G12: 201901 19F | H12: Pre-built | K12: 53000 | L12: 36612
A14: Y1903-0405 | B14: 365712C | C14: 2018121209 | D14: 6100 | E14: ASHLEY | F14: NETHERLANDS B.V | G14: 201901 19F | H14: Pre-built | K14: 43521 | L14: 43521
A15: Y1903-0406 | B15: 365712C | C15: 2018121210 | D15: 840 | E15: ASHLEY | F15: USA | G15: 201901 19F | H15: Pre-built | K15: USA | L15: USA
A18: ORG | B18: Sold To Customer Name | C18: Material | D18: Purchase Requisition Quantity | E18: PHOI DOI | F18: PO# | G18: RGAC
A19: Converse US | B19: L & M FOOTWEAR INC/ROBERT WAYNE | C19: M9621 | D19: 480 | E19: 43490 | F19: 100183224 | G19: 43546
A20: Converse US | B20: FAMOUS FOOTWEAR | C20: M9621 | D20: 588 | E20: 43490 | F20: 100183225 | G20: 43546
A21: Converse US | B21: FAMOUS FOOTWEAR | C21: M9621 | D21: 432 | E21: 43490 | F21: 100183226 | G21: 43546
A22: Converse US | B22: FAMOUS FOOTWEAR | C22: M9696 | D22: 1104 | E22: 43490 | F22: 100183227 | G22: 43546
A23: Converse US | B23: FAMOUS FOOTWEAR | C23: M9696 | D23: 924 | E23: 43490 | F23: 100183228 | G23: 43546
A24: Converse US | B24: JOURNEYS | C24: M9622 | D24: 3000 | E24: 43490 | F24: 100183229 | G24: 43550
A25: Converse US | B25: JOURNEYS | C25: M9621 | D25: 6000 | E25: 43490 | F25: 100183230 | G25: 43550
A26: Converse US | B26: OFF BROADWAY SHOES INC | C26: M9621 | D26: 360 | E26: 43490 | F26: 100183231 | G26: 43546
A27: Converse Canada | B27: JOURNEYS DIV GCO CANADA | C27: M9166C | D27: 792 | E27: 43490 | F27: 100183210 | G27: 43541
A28: FILCON MANUFACTURING CORP. | C28: 159484C | D28: 480 | E28: 43507 | F28: 4600067062 | G28: 43520
A29: FILCON MANUFACTURING CORP. | C29: M9166C | D29: 3000 | E29: 43490 | F29: 4600067063 | G29: 43520
D30: =SUM(D19:D29) -> 17160
A33: Order No | B33: ARTICLE | C33: Cust PO | D33: Pairs Qty | E33: BOM TAKER | F33: Nation | G33: BUY§O | H33: Status
A34: Y1903-0416 | B34: 161599C | C34: 2018122005 | D34: 7000 | E34: JEANIE | F34: NETHERLANDS B.V | G34: 201901 19F | H34: Pre-built 2nd~1220
A35: Y1903-0417 | B35: 161602C | C35: 2018122006 | D35: 1500 | E35: PETER | F35: NETHERLANDS B.V | G35: 201901 19F | H35: Pre-built 2nd~1220
A36: Y1903-0418 | B36: 161603C | C36: 2018122007 | D36: 3000 | E36: PETER | F36: NETHERLANDS B.V | G36: 201901 19F | H36: Pre-built 2nd~1220
A37: Y1904-0115 | B37: 361817C | C37: 2018122009 | D37: 3000 | E37: ASHLEY | F37: NETHERLANDS B.V | G37: 201901 19F | H37: Pre-built 2nd~1220 | I37: huy
A38: Y1903-0419 | B38: 361818C | C38: 2018122008 | D38: 7500 | E38: ASHLEY | F38: NETHERLANDS B.V | G38: 201901 19F | H38: Pre-built 2nd~1220
A39: Y1904-0112 | B39: 661927C | C39: 2018122002 | D39: 9630 | E39: JEANIE | F39: USA | G39: 201901 19F | H39: Pre-built 2nd~1220
A40: Y1904-0113 | B40: 661929C | C40: 2018122003 | D40: 3555 | E40: JEANIE | F40: USA | G40: 201901 19F | H40: Pre-built 2nd~1220
A41: Y1904-0114 | B41: 665291C | C41: 2018122004 | D41: 7000 | E41: JEANIE | F41: USA | G41: 201901 19F | H41: Pre-built 2nd~1220
