Workbook

Sheet 總表 (2370)
A1: 1. 飛越料號 | B1: 2. 來億料號 | C1: 飛越材料名稱
A2: A1000025402-B177 | B2: A110008055 | C2: 54" 320G GS-VN0058 MESH 17-0000TPG-FROST GRAY | D2: t1-->t6
A3: A1000046104-BD20 | B3: A110008056 | C3: 61" 245G FRA5903 19-3906TPG-DARK SHADOW | D3: t1-->t6
A4: A1000055805-BA49 | B4: A070000296 | C4: 58" 300G HMTOP-220 LYCRA 19-2514TPG-ITALIAN PLUM | D4: t1-->t6
A5: A1000055805-BF74 | B5: A070000283 | C5: 58" 300G HMTOP-220 LYCRA 19-4818TPG-MALLARD GREEN | D5: t1-->t6
A6: A1000055805-BH18 | B6: A070000280 | C6: 58" 300G HMTOP-220 LYCRA 19-0419TPG-RIFLE GREEN | D6: t1-->t6
A7: A1000055805-BI86 | B7: A070000297 | C7: 58" 300G HMTOP-220 LYCRA 18-0435TPG-CALLA GREEN | D7: t1-->t6
A8: A1000055805-BJ67 | B8: A070000295 | C8: 58" 300G HMTOP-220 LYCRA 19-4122TPG-MOONLIT OCEAN | D8: t1-->t6
A9: A1000065607-B207 | B9: A010013450 | C9: 56" 210D NYLON 19-4007TPG-ANTHRACITE | D9: t1-->t6
A10: A1000065807-C009 | B10: A010003774 | C10: 58" 210D NYLON BLACK | D10: t1-->t6
A11: A1000075408-C057 | B11: A130000308 | C11: 54" 0.6MM #6700 NON WOVEN GRAY | D11: t1-->t6
A12: A1000085200-B175 | B12: A110007236 | C12: 52" BY130854AW MESH 19-3908TPG-NINE IRON | D12: t1-->t6
A13: A1000085200-B837 | B13: A110009313 | C13: 52" BY130854AW MESH 18-2326TPG-CACTUS FLOWER | D13: t1-->t6
... A2841: H200115A8-E245 | B2841: N010018697 | C2841: 20*38MM GORE-TEX,WOVEN,BOTTOM,LOOP(ELU7205L29) 419C/7403C/485C | D2841: t7-->t9
A2842: H30101507-0000 | B2842: V901019672 | C2842: 55.0*52.0*38.0CM HOKA CARTON SOLID 8(M'S) . | D2842: t7-->t9 | F2842: V901019672 | G2842: 55.0*52.0*38.0CM HOKA CARTON SOLID 8
A2843: H30126925-0000 | B2843: V901019677 | C2843: 55.0*41.0*36.0CM HOKA CARTON CARTON SOLID . | D2843: t7-->t9 | F2843: V901019677 | G2843: 55.0*41.0*36.0CM HOKA CARTON CARTON SOLID
A2844: H30127025-0000 | B2844: V901019673 | C2844: 57.0*41.0*37.0CM HOKA CARTON CARTON SOLID . | D2844: t7-->t9 | F2844: V901019673 | G2844: 57.0*41.0*37.0CM HOKA CARTON CARTON SOLID
A2845: H30127125-0000 | B2845: V901019674 | C2845: 55.0*28.0*36.0CM HOKA CARTON CARTON SOLID . | D2845: t7-->t9 | F2845: V901019674 | G2845: 55.0*28.0*36.0CM HOKA CARTON CARTON SOLID
A2846: H30127225-0000 | B2846: V901019675 | C2846: 57.0*28.0*37.0CM HOKA CARTON CARTON SOLID . | D2846: t7-->t9 | F2846: V901019675 | G2846: 57.0*28.0*37.0CM HOKA CARTON CARTON SOLID
A2847: J10012515-B172 | B2847: J030018357 | C2847: HARDNESS:63+/-2A HOKA-S19-010 M'S DURABRASION RUBBER OUTSOLE 18-0601TPG-CHARCOAL GRAY | D2847: t7-->t9
A2848: J10012515-B207 | B2848: J030018588 | C2848: HARDNESS:63+/-2A HOKA-S19-010 M'S DURABRASION RUBBER OUTSOLE 19-4007TPG-ANTHRACITE | D2848: t7-->t9
A2849: J10012515-B269 | B2849: J030019334 | C2849: HARDNESS:63+/-2A HOKA-S19-010 M'S DURABRASION RUBBER OUTSOLE 19-0712TPG-DEMITASSE | D2849: t7-->t9
A2850: J10012515-BD26 | B2850: J030018356 | C2850: HARDNESS:63+/-2A HOKA-S19-010 M'S DURABRASION RUBBER OUTSOLE 19-3921TPG-BLACK IRIS | D2850: t7-->t9
A2851: J10012515-BD27 | B2851: J030018355 | C2851: HARDNESS:63+/-2A HOKA-S19-010 M'S DURABRASION RUBBER OUTSOLE 19-3925TPG-PATRIOT BLUE | D2851: t7-->t9
A2852: J10012615-B172 | B2852: J030018364 | C2852: HARDNESS:63+/-2A HOKA-S19-020 M'S DURABRASION RUBBER OUTSOLE 18-0601TPG-CHARCOAL GRAY | D2852: t7-->t9
A2853: J10012715-B144 | B2853: J030018361 | C2853: HARDNESS:63+/-2A HOKA-S19-010 W'S DURABRASION RUBBER OUTSOLE 14-4201TPG-LUNAR ROCK | D2853: t7-->t9
A2854: J10012715-B188 | B2854: J030018804 | C2854: HARDNESS:63+/-2A HOKA-S19-010 W'S DURABRASION RUBBER OUTSOLE 19-0810TPG-MAJOR BROWN | D2854: t7-->t9
A2855: J10012715-B207 | B2855: J030018363 | C2855: HARDNESS:63+/-2A HOKA-S19-010 W'S DURABRASION RUBBER OUTSOLE 19-4007TPG-ANTHRACITE | D2855: t7-->t9
A2856: J10012715-BD26 | B2856: J030018362 | C2856: HARDNESS:63+/-2A HOKA-S19-010 W'S DURABRASION RUBBER OUTSOLE 19-3921TPG-BLACK IRIS | D2856: t7-->t9
A2857: J10014415-B144 | B2857: J030018365 | C2857: HARDNESS:63+/-2A HOKA-S19-020 W'S DURABRASION RUBBER OUTSOLE 14-4201TPG-LUNAR ROCK | D2857: t7-->t9
A2858: J10015108-B145 | B2858: J030015584 | C2858: HARDNESS:48+/-3C HOKA-S19-011 M'S INJECTINON DTL OUTSOLE 14-4203TPG-VAPOR BLUE | D2858: t7-->t9
... A3067: P20213011-CJ61 | B3067: O020000327 | C3067: 10-11# 0.5MM P373 THERMO PLASTIC(SPEEDGOAT MID 2 GTX) W'S ORIGINAL COLOR | D3067: t7-->t9
A3068: Q10003500-0000 | B3068: V901019671 | C3068: WPU-110 DAU KIM TINH NUOC . | D3068: t7-->t9 | F3068: V901019671 | G3068: WPU-110
A3069: Q10016900-0000 | B3069: V901019676 | C3069: CAO SU TỰ NHIÊN LATEX HA 60% . | D3069: t7-->t9 | F3069: V901019676 | G3069: CAO SU TU NHIEN LATEX 60%
A3070: A1000085200-BD51 | B3070: A110009890 | C3070: 52" BY130854AW MESH 19-4125TPG-MAJOLICA BLUE | D3070: t7-->t9
A3071: A1002544416-BE63 | B3071: A110009913 | C3071: 44" 220G FRS-223 MESH 17-4408TPG-LEAD | D3071: t7-->t9
A3072: A1002544416-BJ60 | B3072: A110008317 | C3072: 44" 220G FRS-223 MESH 16-3850TPG-SILVER SCONCE | D3072: t7-->t9
A3073: A1002594400-CJ61 | B3073: C010007140 | C3073: 44" 6OZ 1/2 CANVAS ORIGINAL COLOR | D3073: t7-->t9
A3074: A1002705494-B177 | B3074: A110008316 | C3074: 54" 550G GS18-107C OPEN SANDWICH MESH 17-0000TPG-FROST GRAY | D3074: t7-->t9
A3075: A10027348F6-D793 | B3075: A110009942 | C3075: 48" 480G+/-10G GS18-W675T MESH 17-1562TPG/17-1501TPG | D3075: t7-->t9
...

Sheet MSVT T1-T9 OK
A1: STT | B1: 飛越料號 | C1: 飛越材料名稱 | D1: 來億料號 | E1: 利庫
A2: 1 | B2: A1000025402-B177 | C2: 54" 320G GS-VN0058 MESH 17-0000TPG-FROST GRAY | D2: A110008055 | E2: =VLOOKUP(D2,'10Buy'!$A$2:$C$1000,1,FALSE) -> #N/A
A3: 2 | B3: A1000025402-BC16 | C3: 54" 320G GS-VN0058 MESH 19-3933TPG-MEDIEVAL BLUE | D3: A110008057 | E3: =VLOOKUP(D3,'10Buy'!$A$2:$C$1000,1,FALSE) -> #N/A
A4: 3 | B4: A1000025402-BC43 | C4: 54" 320G GS-VN0058 MESH 15-3920TPG-PLACID BLUE | D4: A110009231 | E4: =VLOOKUP(D4,'10Buy'!$A$2:$C$1000,1,FALSE) -> #N/A
A5: 4 | B5: A1000025402-BD27 | C5: 54" 320G GS-VN0058 MESH 19-3925TPG-PATRIOT BLUE | D5: A110008061 | E5: =VLOOKUP(D5,'10Buy'!$A$2:$C$1000,1,FALSE) -> #N/A
A6: 5 | B6: A1000025402-CJ53 | C6: 54" 320G GS-VN0058 MESH HOKA STANDARD WHITE | D6: A110009258 | E6: =VLOOKUP(D6,'10Buy'!$A$2:$C$1000,1,FALSE) -> #N/A
A7: 6 | B7: A1000034423-C0090001 | C7: 44" 20G TRICOT BLACK+44" 4MM KF329 FOAM+ADHESIVE BLACK | D7: P180000106 | E7: =VLOOKUP(D7,'10Buy'!$A$2:$C$1000,1,FALSE) -> #N/A
A8: 7 | B8: A1000034423-C0090002 | C8: 44" 20G TRICOT BLACK+44" 4MM KF329 FOAM BLACK+44" 20G TRICOT BLACK | D8: P180000166 | E8: =VLOOKUP(D8,'10Buy'!$A$2:$C$1000,1,FALSE) -> #N/A
A9: 8 | B9: A1000034423-C1480002 | C9: 44" 20G TRICOT WHITE+44" 4MM KF329 FOAM+ADHESIVE PIN-BLUE | D9: P180000165 | E9: =VLOOKUP(D9,'10Buy'!$A$2:$C$1000,1,FALSE) -> #N/A
A10: 9 | B10: A1000034423-CJ650001 | C10: 44" 20G TRICOT 2059-WHITE+44" 4MM KF329 FOAM PIN-BLUE+ADHESIVE | D10: P180000107 | E10: =VLOOKUP(D10,'10Buy'!$A$2:$C$1000,1,FALSE) -> #N/A
A11: 10 | B11: A1000035423-C009 | C11: 54" 20G TRICOT BLACK | D11: A080000112 | E11: =VLOOKUP(D11,'10Buy'!$A$2:$C$1000,1,FALSE) -> #N/A
A12: 11 | B12: A1000046104-B743 | C12: 61" 245G FRA5903 16-1451TPG-NASTURTIUM | D12: A110008062 | E12: =VLOOKUP(D12,'10Buy'!$A$2:$C$1000,1,FALSE) -> #N/A
A13: 12 | B13: A1000046104-BC16 | C13: 61" 245G FRA5903 19-3933TPG-MEDIEVAL BLUE | D13: A110008058 | E13: =VLOOKUP(D13,'10Buy'!$A$2:$C$1000,1,FALSE) -> #N/A
... A3718: 3717 | B3718: W10000331-0000 | C3718: 20*25 BOC NYLON MAU TRANG PE . | D3718: V901019693 | E3718: =VLOOKUP(D3718,'10Buy'!$A$2:$C$1000,1,FALSE) -> #N/A

Sheet 10Buy
A1: 料號 | B1: 材料描述
A2: A070000280 | B2: 58" 300G HMTOP-220 LYCRA 19-0419TPG-RIFLE GREEN
A3: A070000297 | B3: 58" 300G HMTOP-220 LYCRA 18-0435TPG-CALLA GREEN
