Workbook

Sheet 目   錄
A1: 2017年綜合報表目錄
A2: 序號 | B2: 項目 | C2: 備注
A3: 1 | B3: 1.月份產能總表
A4: 2 | B4: 2.1年度品牌報表
B5: 2.2月份預計出貨數量
A6: 3 | B6: 3-1.人員刷卡出勤
B7: 3.2.A1廠人均時產能-針車
B8: 3.3.A2廠人均時產能-針車
B9: 3.4.A1廠人均時產能-成型
B10: 3.5.A2廠人均時產能-成型
B11: 3.6.A廠總計產能
B12: 3.7.A廠人員分攤POH產能
A13: 5 | B13: 5.1.全廠線均產能

Sheet 1.月份產能總表
A1: 回到首頁
A2: 2017年度03月份產量達成狀況明細表
A3: 單位項目 | C3: 總計 | D3: 日平均 | E3: 1 | F3: 2 | G3: 3 | H3: 4 | I3: 5 | J3: 6 | K3: 7 | L3: 8 | M3: 9 | N3: 10 | O3: 11 | P3: 12 | Q3: 13 | R3: 14 | S3: 15 | T3: 16 | U3: 17 | V3: 18 | W3: 19 | X3: 20 | Y3: 21 | Z3: 22 | AA3: 23 | AB3: 24 | AC3: 25 | AD3: 26 | AE3: 27 | AF3: 28 | AG3: 29 | AH3: 30 | AI3: 31
A4: A1廠成型 | B4: 標準產量 | C4: 654880 | D4: 36382.2 | E4: 37232 | F4: 37024 | G4: 37520 | H4: 37216 | J4: 36968 | K4: 36856 | L4: 37312 | M4: 36976 | N4: 37048 | O4: 37040 | Q4: 36880 | R4: 37128 | S4: 36536 | T4: 35920 | U4: 35256 | V4: 34600 | X4: 34024 | Y4: 33344
B5: 目標產量 | C5: 592900 | D5: 32938.9 | E5: 33220 | F5: 34720 | G5: 35240 | H5: 35240 | J5: 34900 | K5: 34900 | L5: 35200 | M5: 35020 | N5: 35020 | O5: 34160 | Q5: 34480 | R5: 33600 | S5: 33440 | T5: 30700 | U5: 30260 | V5: 29720 | X5: 26460 | Y5: 26620 | Z5: 26840 | AA5: 27840 | AB5: 28180 | AC5: 27820 | AE5: 26964 | AF5: 27624 | AG5: 28272 | AH5: 28272 | AI5: 28272
B6: 實際產量 | C6: 582898 | D6: 32383.2 | E6: 32950 | F6: 35030 | G6: 35346 | H6: 35509 | J6: 36824 | K6: 35486 | L6: 34787 | M6: 33670 | N6: 34263 | O6: 33989 | Q6: 34078 | R6: 30035 | S6: 31537 | T6: 30298 | U6: 30450 | V6: 29240 | X6: 24522 | Y6: 24884
B7: 目標與實際差異 | C7: -10002 | D7: -555.7 | E7: -270 | F7: 310 | G7: 106 | H7: 269 | J7: 1924 | K7: 586 | L7: -413 | M7: -1350 | N7: -757 | O7: -171 | Q7: -402 | R7: -3565 | S7: -1903 | T7: -402 | U7: 190 | V7: -480 | X7: -1938 | Y7: -1736
B8: 標準與實際差異 | C8: -71982 | D8: -3999 | E8: -4282 | F8: -1994 | G8: -2174 | H8: -1707 | J8: -144 | K8: -1370 | L8: -2525 | M8: -3306 | N8: -2785 | O8: -3051 | Q8: -2802 | R8: -7093 | S8: -4999 | T8: -5622 | U8: -4806 | V8: -5360 | X8: -9502 | Y8: -8460
B9: 目標與實際達成率 | C9: 98 | D9: 98 | E9: 99 | F9: 100 | G9: 100 | H9: 100 | J9: 105 | K9: 101 | L9: 98 | M9: 96 | N9: 97 | O9: 99 | Q9: 98 | R9: 89 | S9: 94 | T9: 98 | U9: 100 | V9: 98 | X9: 92 | Y9: 93 | Z9: 0 | AA9: 0 | AB9: 0 | AC9: 0 | AE9: 0 | AF9: 0 | AG9: 0 | AH9: 0 | AI9: 0
B10: 標準與實際達成率 | C10: 89 | D10: 89 | E10: 88 | F10: 94 | G10: 94 | H10: 95 | J10: 99 | K10: 96 | L10: 93 | M10: 91 | N10: 92 | O10: 91 | Q10: 92 | R10: 80 | S10: 86 | T10: 84 | U10: 86 | V10: 84 | X10: 72 | Y10: 74
A11: A2廠成型 | B11: 標準產量 | C11: 528440 | D11: 29357.8 | E11: 29712 | F11: 29984 | G11: 29896 | H11: 29776 | J11: 30040 | K11: 30200 | L11: 30000 | M11: 29960 | N11: 29920 | O11: 29920 | Q11: 29576 | R11: 29128 | S11: 29016 | T11: 28536 | U11: 28512 | V11: 28320 | X11: 28120 | Y11: 27824
B12: 目標產量 | C12: 485660 | D12: 26981.1 | E12: 27860 | F12: 26750 | G12: 27790 | H12: 28520 | J12: 28520 | K12: 28520 | L12: 28520 | M12: 28000 | N12: 28440 | O12: 27200 | Q12: 26300 | R12: 27000 | S12: 24620 | T12: 25380 | U12: 26520 | V12: 26020 | X12: 25360 | Y12: 24340 | Z12: 24870 | AA12: 25210 | AB12: 26000 | AC12: 25440 | AE12: 25840 | AF12: 24990 | AG12: 24470 | AH12: 24480 | AI12: 24640
B13: 實際產量 | C13: 483687 | D13: 26871.5 | E13: 27860 | F13: 26864 | G13: 27570 | H13: 28474 | J13: 28520 | K13: 28520 | L13: 28522 | M13: 26520 | N13: 28104 | O13: 27031 | Q13: 26680 | R13: 26960 | S13: 24388 | T13: 25136 | U13: 26510 | V13: 26079 | X13: 25430 | Y13: 24519
B14: 目標與實際差異 | C14: -1973 | D14: -109.6 | E14: 0 | F14: 114 | G14: -220 | H14: -46 | J14: 0 | K14: 0 | L14: 2 | M14: -1480 | N14: -336 | O14: -169 | Q14: 380 | R14: -40 | S14: -232 | T14: -244 | U14: -10 | V14: 59 | X14: 70 | Y14: 179
B15: 標準與實際差異 | C15: -44753 | D15: -2486.3 | E15: -1852 | F15: -3120 | G15: -2326 | H15: -1302 | J15: -1520 | K15: -1680 | L15: -1478 | M15: -3440 | N15: -1816 | O15: -2889 | Q15: -2896 | R15: -2168 | S15: -4628 | T15: -3400 | U15: -2002 | V15: -2241 | X15: -2690 | Y15: -3305
B16: 目標與實際達成率 | C16: 99 | D16: 99 | E16: 100 | F16: 100 | G16: 99 | H16: 99 | J16: 100 | K16: 100 | L16: 100 | M16: 94 | N16: 98 | O16: 99 | Q16: 101 | R16: 99 | S16: 99 | T16: 99 | U16: 99 | V16: 100 | X16: 100 | Y16: 100 | Z16: 0 | AA16: 0 | AB16: 0 | AC16: 0 | AE16: 0 | AF16: 0 | AG16: 0 | AH16: 0 | AI16: 0
B17: 標準與實際達成率 | C17: 91 | D17: 91 | E17: 93 | F17: 89 | G17: 92 | H17: 95 | J17: 94 | K17: 94 | L17: 95 | M17: 88 | N17: 93 | O17: 90 | Q17: 90 | R17: 92 | S17: 84 | T17: 88 | U17: 92 | V17: 92 | X17: 90 | Y17: 88
A18: A1廠BB鞋 | B18: 標準產量 | C18: 43808 | D18: 2433.8 | E18: 2480 | F18: 2480 | G18: 2480 | H18: 2480 | J18: 2480 | K18: 2480 | L18: 2480 | M18: 2480 | N18: 2480 | O18: 2480 | Q18: 2480 | R18: 2480 | S18: 2480 | T18: 2480 | U18: 2480 | V18: 2480 | X18: 2272 | Y18: 1856
B19: 目標產量 | C19: 40440 | D19: 2246.7 | E19: 2400 | F19: 2400 | G19: 2400 | H19: 2400 | J19: 2400 | K19: 2400 | L19: 2400 | M19: 2400 | N19: 2400 | O19: 2400 | Q19: 2400 | R19: 2400 | S19: 2400 | T19: 2400 | U19: 2400 | V19: 2400 | X19: 1020 | Y19: 1020 | Z19: 1360 | AA19: 1360 | AB19: 1360 | AC19: 1360 | AE19: 1360 | AF19: 1360 | AG19: 1360 | AH19: 1360 | AI19: 1360
B20: 實際產量 | C20: 41040 | D20: 2280 | E20: 2000 | F20: 2500 | G20: 2500 | H20: 2600 | J20: 4000 | K20: 3100 | L20: 2400 | M20: 2400 | N20: 2400 | O20: 2400 | Q20: 2400 | R20: 1700 | S20: 2000 | T20: 1800 | U20: 2400 | V20: 2400 | X20: 1020 | Y20: 1020
B21: 目標與實際差異 | C21: 600 | D21: 33.3 | E21: -400 | F21: 100 | G21: 100 | H21: 200 | J21: 1600 | K21: 700 | L21: 0 | M21: 0 | N21: 0 | O21: 0 | Q21: 0 | R21: -700 | S21: -400 | T21: -600 | U21: 0 | V21: 0 | X21: 0 | Y21: 0
B22: 標準與實際差異 | C22: -2768 | D22: -153.8 | E22: -480 | F22: 20 | G22: 20 | H22: 120 | J22: 1520 | K22: 620 | L22: -80 | M22: -80 | N22: -80 | O22: -80 | Q22: -80 | R22: -780 | S22: -480 | T22: -680 | U22: -80 | V22: -80 | X22: -1252 | Y22: -836
B23: 目標與實際達成率 | C23: 101 | D23: 101 | E23: 83 | F23: 104 | G23: 104 | H23: 108 | J23: 166 | K23: 129 | L23: 100 | M23: 100 | N23: 100 | O23: 100 | Q23: 100 | R23: 70 | S23: 83 | T23: 75 | U23: 100 | V23: 100 | X23: 100 | Y23: 100 | Z23: 0 | AA23: 0 | AB23: 0 | AC23: 0 | AE23: 0 | AF23: 0 | AG23: 0 | AH23: 0 | AI23: 0
B24: 標準與實際達成率 | C24: 93 | D24: 93 | E24: 80 | F24: 100 | G24: 100 | H24: 104 | J24: 161 | K24: 125 | L24: 96 | M24: 96 | N24: 96 | O24: 96 | Q24: 96 | R24: 68 | S24: 80 | T24: 72 | U24: 96 | V24: 96 | X24: 44 | Y24: 54
A25: A廠區小計 | B25: 標準產量 | C25: 1227128 | D25: 68173.8 | E25: 69424 | F25: 69488 | G25: 69896 | H25: 69472 | J25: 69488 | K25: 69536 | L25: 69792 | M25: 69416 | N25: 69448 | O25: 69440 | Q25: 68936 | R25: 68736 | S25: 68032 | T25: 66936 | U25: 66248 | V25: 65400 | X25: 64416 | Y25: 63024
B26: 目標產量 | C26: 1119000 | D26: 62166.7 | E26: 63480 | F26: 63870 | G26: 65430 | H26: 66160 | J26: 65820 | K26: 65820 | L26: 66120 | M26: 65420 | N26: 65860 | O26: 63760 | Q26: 63180 | R26: 63000 | S26: 60460 | T26: 58480 | U26: 59180 | V26: 58140 | X26: 52840 | Y26: 51980 | Z26: 53070 | AA26: 54410 | AB26: 55540 | AC26: 54620 | AE26: 54164 | AF26: 53974 | AG26: 54102 | AH26: 54112 | AI26: 54272
B27: 實際產量 | C27: 1107625 | D27: 61534.7 | E27: 62810 | F27: 64394 | G27: 65416 | H27: 66583 | J27: 69344 | K27: 67106 | L27: 65709 | M27: 62590 | N27: 64767 | O27: 63420 | Q27: 63158 | R27: 58695 | S27: 57925 | T27: 57234 | U27: 59360 | V27: 57719 | X27: 50972 | Y27: 50423
B28: 目標與實際差異 | C28: -11375 | D28: -632 | E28: -670 | F28: 524 | G28: -14 | H28: 423 | J28: 3524 | K28: 1286 | L28: -411 | M28: -2830 | N28: -1093 | O28: -340 | Q28: -22 | R28: -4305 | S28: -2535 | T28: -1246 | U28: 180 | V28: -421 | X28: -1868 | Y28: -1557
B29: 標準與實際差異 | C29: -119503 | D29: -6639.1 | E29: -6614 | F29: -5094 | G29: -4480 | H29: -2889 | J29: -144 | K29: -2430 | L29: -4083 | M29: -6826 | N29: -4681 | O29: -6020 | Q29: -5778 | R29: -10041 | S29: -10107 | T29: -9702 | U29: -6888 | V29: -7681 | X29: -13444 | Y29: -12601
B30: 目標與實際達成率 | C30: 98 | D30: 98 | E30: 98 | F30: 100 | G30: 99 | H30: 100 | J30: 105 | K30: 101 | L30: 99 | M30: 95 | N30: 98 | O30: 99 | Q30: 99 | R30: 93 | S30: 95 | T30: 97 | U30: 100 | V30: 99 | X30: 96 | Y30: 97 | Z30: 0 | AA30: 0 | AB30: 0 | AC30: 0 | AE30: 0 | AF30: 0 | AG30: 0 | AH30: 0 | AI30: 0
B31: 標準與實際達成率 | C31: 90 | D31: 90 | E31: 90 | F31: 92 | G31: 93 | H31: 95 | J31: 99 | K31: 96 | L31: 94 | M31: 90 | N31: 93 | O31: 91 | Q31: 91 | R31: 85 | S31: 85 | T31: 85 | U31: 89 | V31: 88 | X31: 79 | Y31: 80

Sheet 2.1年度品牌報表
A1: 回到首頁
A2: 2017年度品牌接單生產報表-每天更新（以月份訂單統計）
A3: 品牌 | B3: 項目 | C3: 01月 | D3: 02月 | E3: 03月 | F3: 04月 | G3: 05月 | H3: 06月 | I3: 07月 | J3: 08月 | K3: 09月 | L3: 10月 | M3: 11月 | N3: 12月 | O3: 小計
A4: CONS外銷 | B4: 接單雙數 | C4: 923173 | D4: 930123 | E4: 1522093 | F4: 1788564 | G4: 1046594 | H4: 587937 | I4: 91056 | J4: 540 | K4: 0 | L4: 0 | M4: 0 | N4: 0 | O4: 6890080
B5: 完成雙數 | C5: 126310 | D5: 225104 | E5: 140154 | F5: 0 | G5: 0 | H5: 0 | I5: 0 | J5: 0 | K5: 0 | L5: 0 | M5: 0 | N5: 0 | O5: 491568
B6: 提前生產 | C6: 796863 | D6: 705019 | E6: 1380270 | F6: 1004636 | G6: 101846 | H6: 26148 | I6: 0 | J6: 0 | K6: 0 | L6: 0 | M6: 0 | N6: 0 | O6: 4014782
B7: 欠數 | C7: 0 | D7: 0 | E7: 1669 | F7: 783928 | G7: 944748 | H7: 561789 | I7: 91056 | J7: 540 | K7: 0 | L7: 0 | M7: 0 | N7: 0 | O7: 2383730
A8: CONS內銷 | B8: 接單雙數 | C8: 14280 | D8: 14520 | E8: 960 | F8: 7620 | G8: 16140 | H8: 11160 | I8: 0 | J8: 0 | K8: 0 | L8: 0 | M8: 0 | N8: 0 | O8: 64680
B9: 完成雙數 | C9: 1847 | D9: 1164 | E9: 960 | F9: 0 | G9: 0 | H9: 0 | I9: 0 | J9: 0 | K9: 0 | L9: 0 | M9: 0 | N9: 0 | O9: 3971
B10: 提前生產 | C10: 12433 | D10: 9985 | E10: 0 | F10: 7620 | G10: 10256 | H10: 0 | I10: 0 | J10: 0 | K10: 0 | L10: 0 | M10: 0 | N10: 0 | O10: 40294
B11: 欠數 | C11: 0 | D11: 3371 | E11: 0 | F11: 0 | G11: 5884 | H11: 11160 | I11: 0 | J11: 0 | K11: 0 | L11: 0 | M11: 0 | N11: 0 | O11: 20415
A13: 備註：

Sheet 2.2月份預計出貨數量
A1: 回到首頁
A2: 各品牌月份預計出貨
A3: 3月份 | B3: 出貨階段 | C3: Total | D3: 1 | E3: 2 | F3: 3 | G3: 4 | H3: 6 | I3: 7 | J3: 8 | K3: 9 | L3: 10 | M3: 11 | N3: 13 | O3: 14 | P3: 15 | Q3: 16 | R3: 17 | S3: 18 | T3: 19 | U3: 20 | V3: 21 | W3: 22 | X3: 23 | Y3: 24 | Z3: 25 | AA3: 26 | AB3: 27 | AC3: 28 | AD3: 30 | AE3: 31
B4: 客人
A5: Converse | B5: 預計出貨數 | C5: 1523053 | D5: 19608 | F5: 6876 | G5: 23004 | I5: 46276 | J5: 8204 | K5: 30864 | L5: 209574 | O5: 1224 | P5: 47964 | Q5: 222996 | R5: 356583 | S5: 16968 | T5: 264 | U5: 9977 | V5: 3060 | W5: 3588 | X5: 3600 | Y5: 124884 | Z5: 6036 | AA5: 156 | AB5: 346551 | AC5: 2210 | AD5: 20544 | AE5: 12042
B6: 實際出貨數 | C6: 1007922 | D6: 2040 | E6: 31656 | F6: 16488 | G6: 5412 | H6: 27588 | I6: 34360 | J6: 239526 | K6: 5796 | L6: 7788 | M6: 7908 | N6: 15612 | P6: 193500 | Q6: 169080 | R6: 55635 | S6: 1914 | U6: 24227 | V6: 169392
B7: 差異數 | C7: 76796 | D7: 17568 | F7: -9612 | G7: 17592 | I7: 11916 | J7: -231322 | K7: 25068 | L7: 201786 | P7: -145536 | Q7: 53916 | R7: 300948 | S7: 15054 | U7: -14250 | V7: -166332

Sheet 3-1.人員刷卡出勤
A1: 回到首頁
A2: 03月人事刷卡出勤報表
A3: 廠別 | B3: 項目 | C3: 1 | D3: 2 | E3: 3 | F3: 4 | G3: 5 | H3: 6 | I3: 7 | J3: 8 | K3: 9 | L3: 10 | M3: 11 | N3: 12 | O3: 13 | P3: 14 | Q3: 15 | R3: 16 | S3: 17 | T3: 18 | U3: 19 | V3: 20 | W3: 21 | X3: 22 | Y3: 23 | Z3: 24 | AA3: 25 | AB3: 26 | AC3: 27 | AD3: 28 | AE3: 29 | AF3: 30 | AG3: 31
A4: 總計 | B4: 刷卡總數 | C4: 19495 | D4: 19516 | E4: 19427 | F4: 15899 | G4: 58 | H4: 18884 | I4: 19260 | J4: 19245 | K4: 19277 | L4: 19326 | M4: 19097 | N4: 61 | O4: 19146 | P4: 19548 | Q4: 19565 | R4: 19437 | S4: 19584 | T4: 19322 | U4: 111 | V4: 19378 | W4: 19422 | X4: 19661 | Y4: 19625 | Z4: 19624 | AA4: 708 | AB4: 0
B5: 刷卡直工 | C5: 16234 | D5: 16240 | E5: 16157 | F5: 13059 | G5: 0 | H5: 15700 | I5: 16027 | J5: 16028 | K5: 16055 | L5: 16084 | M5: 15928 | N5: 0 | O5: 15979 | P5: 16280 | Q5: 16309 | R5: 16211 | S5: 16368 | T5: 16178 | U5: 0 | V5: 16210 | W5: 16256 | X5: 16470 | Y5: 16448 | Z5: 16450 | AA5: 569 | AB5: 0
B6: 刷卡間工 | C6: 3260 | D6: 3275 | E6: 3268 | F6: 2838 | G6: 58 | H6: 3182 | I6: 3231 | J6: 3213 | K6: 3218 | L6: 3238 | M6: 3165 | N6: 61 | O6: 3163 | P6: 3264 | Q6: 3252 | R6: 3222 | S6: 3212 | T6: 3140 | U6: 111 | V6: 3164 | W6: 3162 | X6: 3188 | Y6: 3173 | Z6: 3170 | AA6: 139 | AB6: 0
A7: VP | B7: 刷卡總數 | C7: 427 | D7: 432 | E7: 432 | F7: 415 | G7: 58 | H7: 423 | I7: 424 | J7: 417 | K7: 417 | L7: 429 | M7: 408 | N7: 61 | O7: 419 | P7: 434 | Q7: 427 | R7: 431 | S7: 408 | T7: 386 | U7: 111 | V7: 397 | W7: 390 | X7: 398 | Y7: 395 | Z7: 397 | AA7: 50
B8: 刷卡直工 | C8: 0 | D8: 0 | E8: 0 | F8: 0 | G8: 0 | H8: 0 | I8: 0 | J8: 0 | K8: 0 | L8: 0 | M8: 0 | N8: 0 | O8: 0 | P8: 0 | Q8: 0 | R8: 0 | S8: 0 | T8: 0 | U8: 0 | V8: 0 | W8: 0 | X8: 0 | Y8: 0 | Z8: 1 | AA8: 0
B9: 刷卡間工 | C9: 427 | D9: 432 | E9: 432 | F9: 415 | G9: 58 | H9: 423 | I9: 424 | J9: 417 | K9: 417 | L9: 429 | M9: 408 | N9: 61 | O9: 419 | P9: 434 | Q9: 427 | R9: 431 | S9: 408 | T9: 386 | U9: 111 | V9: 397 | W9: 390 | X9: 398 | Y9: 395 | Z9: 396 | AA9: 50
A10: R3 | B10: 刷卡總數 | C10: 564 | D10: 570 | E10: 565 | F10: 559 | G10: 0 | H10: 557 | I10: 558 | J10: 560 | K10: 561 | L10: 570 | M10: 561 | N10: 0 | O10: 560 | P10: 564 | Q10: 561 | R10: 559 | S10: 560 | T10: 558 | U10: 0 | V10: 550 | W10: 547 | X10: 553 | Y10: 556 | Z10: 556 | AA10: 144 | AB10: 0
B11: 刷卡直工 | C11: 444 | D11: 449 | E11: 443 | F11: 440 | G11: 0 | H11: 437 | I11: 440 | J11: 440 | K11: 440 | L11: 447 | M11: 445 | N11: 0 | O11: 438 | P11: 441 | Q11: 439 | R11: 439 | S11: 439 | T11: 441 | U11: 0 | V11: 436 | W11: 431 | X11: 438 | Y11: 442 | Z11: 439 | AA11: 124 | AB11: 0
B12: 刷卡間工 | C12: 120 | D12: 121 | E12: 122 | F12: 119 | G12: 0 | H12: 120 | I12: 118 | J12: 120 | K12: 121 | L12: 123 | M12: 116 | N12: 0 | O12: 122 | P12: 123 | Q12: 122 | R12: 120 | S12: 121 | T12: 117 | U12: 0 | V12: 114 | W12: 116 | X12: 115 | Y12: 114 | Z12: 117 | AA12: 20 | AB12: 0
A13: R2 | B13: 刷卡總數 | C13: 239 | D13: 241 | E13: 238 | F13: 235 | G13: 0 | H13: 232 | I13: 236 | J13: 234 | K13: 232 | L13: 236 | M13: 232 | N13: 0 | O13: 236 | P13: 238 | Q13: 242 | R13: 238 | S13: 241 | T13: 222 | U13: 0 | V13: 241 | W13: 236 | X13: 243 | Y13: 239 | Z13: 236 | AA13: 77
B14: 刷卡直工 | C14: 193 | D14: 195 | E14: 191 | F14: 188 | G14: 0 | H14: 184 | I14: 189 | J14: 187 | K14: 186 | L14: 187 | M14: 185 | N14: 0 | O14: 190 | P14: 189 | Q14: 194 | R14: 190 | S14: 193 | T14: 176 | U14: 0 | V14: 193 | W14: 190 | X14: 195 | Y14: 191 | Z14: 188 | AA14: 59
B15: 刷卡間工 | C15: 46 | D15: 46 | E15: 47 | F15: 47 | G15: 0 | H15: 48 | I15: 47 | J15: 47 | K15: 46 | L15: 49 | M15: 47 | N15: 0 | O15: 46 | P15: 49 | Q15: 48 | R15: 48 | S15: 48 | T15: 46 | U15: 0 | V15: 48 | W15: 46 | X15: 48 | Y15: 48 | Z15: 48 | AA15: 18
A16: R1 | B16: 刷卡總數 | C16: 14 | D16: 14 | E16: 14 | F16: 14 | G16: 0 | H16: 14 | I16: 13 | J16: 13 | K16: 13 | L16: 13 | M16: 13 | N16: 0 | O16: 12 | P16: 13 | Q16: 13 | R16: 12 | S16: 14 | T16: 14 | U16: 0 | V16: 14 | W16: 13 | X16: 14 | Y16: 12 | Z16: 14 | AA16: 1
B17: 刷卡直工 | C17: 13 | D17: 13 | E17: 13 | F17: 13 | G17: 0 | H17: 13 | I17: 12 | J17: 12 | K17: 12 | L17: 12 | M17: 12 | N17: 0 | O17: 11 | P17: 12 | Q17: 12 | R17: 11 | S17: 13 | T17: 13 | U17: 0 | V17: 13 | W17: 12 | X17: 12 | Y17: 10 | Z17: 12 | AA17: 0
B18: 刷卡間工 | C18: 1 | D18: 1 | E18: 1 | F18: 1 | G18: 0 | H18: 1 | I18: 1 | J18: 1 | K18: 1 | L18: 1 | M18: 1 | N18: 0 | O18: 1 | P18: 1 | Q18: 1 | R18: 1 | S18: 1 | T18: 1 | U18: 0 | V18: 1 | W18: 1 | X18: 2 | Y18: 2 | Z18: 2 | AA18: 1
A19: GC | B19: 刷卡總數 | C19: 449 | D19: 443 | E19: 444 | F19: 446 | G19: 0 | H19: 434 | I19: 450 | J19: 445 | K19: 443 | L19: 454 | M19: 439 | N19: 0 | O19: 440 | P19: 444 | Q19: 439 | R19: 439 | S19: 452 | T19: 442 | U19: 0 | V19: 434 | W19: 438 | X19: 440 | Y19: 447 | Z19: 442 | AA19: 10
B20: 刷卡直工 | C20: 390 | D20: 383 | E20: 384 | F20: 386 | G20: 0 | H20: 377 | I20: 391 | J20: 386 | K20: 384 | L20: 393 | M20: 381 | N20: 0 | O20: 382 | P20: 383 | Q20: 379 | R20: 378 | S20: 392 | T20: 385 | U20: 0 | V20: 378 | W20: 381 | X20: 385 | Y20: 389 | Z20: 383 | AA20: 9
B21: 刷卡間工 | C21: 59 | D21: 60 | E21: 60 | F21: 60 | G21: 0 | H21: 57 | I21: 59 | J21: 59 | K21: 59 | L21: 61 | M21: 58 | N21: 0 | O21: 58 | P21: 61 | Q21: 60 | R21: 61 | S21: 60 | T21: 57 | U21: 0 | V21: 56 | W21: 57 | X21: 55 | Y21: 58 | Z21: 59 | AA21: 1
A22: BR2 | B22: 刷卡總數 | C22: 702 | D22: 701 | E22: 693 | F22: 622 | G22: 0 | H22: 672 | I22: 686 | J22: 691 | K22: 691 | L22: 687 | M22: 682 | N22: 0 | O22: 674 | P22: 689 | Q22: 692 | R22: 686 | S22: 692 | T22: 688 | U22: 0 | V22: 678 | W22: 687 | X22: 701 | Y22: 691 | Z22: 700 | AA22: 0
B23: 刷卡直工 | C23: 677 | D23: 675 | E23: 668 | F23: 596 | G23: 0 | H23: 648 | I23: 661 | J23: 666 | K23: 666 | L23: 663 | M23: 658 | N23: 0 | O23: 650 | P23: 664 | Q23: 669 | R23: 664 | S23: 668 | T23: 663 | U23: 0 | V23: 653 | W23: 662 | X23: 675 | Y23: 667 | Z23: 674 | AA23: 0
B24: 刷卡間工 | C24: 25 | D24: 26 | E24: 25 | F24: 26 | G24: 0 | H24: 24 | I24: 25 | J24: 25 | K24: 25 | L24: 24 | M24: 24 | N24: 0 | O24: 24 | P24: 25 | Q24: 23 | R24: 22 | S24: 24 | T24: 25 | U24: 0 | V24: 25 | W24: 25 | X24: 26 | Y24: 24 | Z24: 26 | AA24: 0
A25: BR1 | B25: 刷卡總數 | C25: 22 | D25: 21 | E25: 22 | F25: 22 | G25: 0 | H25: 21 | I25: 22 | J25: 21 | K25: 22 | L25: 22 | M25: 21 | N25: 0 | O25: 22 | P25: 22 | Q25: 21 | R25: 20 | S25: 21 | T25: 22 | U25: 0 | V25: 20 | W25: 21 | X25: 21 | Y25: 21 | Z25: 22 | AA25: 0
B26: 刷卡直工 | C26: 19 | D26: 18 | E26: 19 | F26: 19 | G26: 0 | H26: 18 | I26: 19 | J26: 18 | K26: 19 | L26: 19 | M26: 18 | N26: 0 | O26: 19 | P26: 19 | Q26: 18 | R26: 17 | S26: 18 | T26: 19 | U26: 0 | V26: 17 | W26: 18 | X26: 18 | Y26: 19 | Z26: 19 | AA26: 0
B27: 刷卡間工 | C27: 3 | D27: 3 | E27: 3 | F27: 3 | G27: 0 | H27: 3 | I27: 3 | J27: 3 | K27: 3 | L27: 3 | M27: 3 | N27: 0 | O27: 3 | P27: 3 | Q27: 3 | R27: 3 | S27: 3 | T27: 3 | U27: 0 | V27: 3 | W27: 3 | X27: 3 | Y27: 2 | Z27: 3 | AA27: 0
A28: BP | B28: 刷卡總數 | C28: 466 | D28: 470 | E28: 466 | F28: 460 | G28: 0 | H28: 447 | I28: 468 | J28: 464 | K28: 462 | L28: 469 | M28: 455 | N28: 0 | O28: 460 | P28: 469 | Q28: 476 | R28: 461 | S28: 478 | T28: 468 | U28: 0 | V28: 482 | W28: 491 | X28: 506 | Y28: 503 | Z28: 504 | AA28: 76
B29: 刷卡直工 | C29: 427 | D29: 433 | E29: 428 | F29: 423 | G29: 0 | H29: 413 | I29: 430 | J29: 426 | K29: 424 | L29: 431 | M29: 418 | N29: 0 | O29: 423 | P29: 430 | Q29: 437 | R29: 422 | S29: 441 | T29: 431 | U29: 0 | V29: 446 | W29: 453 | X29: 470 | Y29: 466 | Z29: 466 | AA29: 76
B30: 刷卡間工 | C30: 39 | D30: 37 | E30: 38 | F30: 37 | G30: 0 | H30: 34 | I30: 38 | J30: 38 | K30: 38 | L30: 38 | M30: 37 | N30: 0 | O30: 37 | P30: 39 | Q30: 39 | R30: 39 | S30: 37 | T30: 37 | U30: 0 | V30: 36 | W30: 38 | X30: 36 | Y30: 37 | Z30: 38 | AA30: 0
A31: B7 | B31: 刷卡總數 | C31: 3439 | D31: 3449 | E31: 3416 | F31: 382 | G31: 0 | H31: 3331 | I31: 3420 | J31: 3418 | K31: 3421 | L31: 3445 | M31: 3426 | N31: 0 | O31: 3413 | P31: 3473 | Q31: 3460 | R31: 3430 | S31: 3505 | T31: 3449 | U31: 0 | V31: 3477 | W31: 3470 | X31: 3507 | Y31: 3515 | Z31: 3515 | AA31: 175
B32: 刷卡直工 | C32: 3137 | D32: 3146 | E32: 3117 | F32: 278 | G32: 0 | H32: 3034 | I32: 3121 | J32: 3120 | K32: 3127 | L32: 3147 | M32: 3134 | N32: 0 | O32: 3114 | P32: 3169 | Q32: 3157 | R32: 3134 | S32: 3205 | T32: 3153 | U32: 0 | V32: 3187 | W32: 3178 | X32: 3213 | Y32: 3220 | Z32: 3226 | AA32: 143
B33: 刷卡間工 | C33: 302 | D33: 303 | E33: 299 | F33: 104 | G33: 0 | H33: 297 | I33: 299 | J33: 298 | K33: 294 | L33: 298 | M33: 292 | N33: 0 | O33: 299 | P33: 304 | Q33: 303 | R33: 296 | S33: 300 | T33: 296 | U33: 0 | V33: 290 | W33: 292 | X33: 294 | Y33: 295 | Z33: 289 | AA33: 32
A34: B6 | B34: 刷卡總數 | C34: 473 | D34: 474 | E34: 475 | F34: 464 | G34: 0 | H34: 462 | I34: 472 | J34: 463 | K34: 472 | L34: 471 | M34: 461 | N34: 0 | O34: 471 | P34: 478 | Q34: 482 | R34: 479 | S34: 498 | T34: 487 | U34: 0 | V34: 491 | W34: 487 | X34: 501 | Y34: 497 | Z34: 536 | AA34: 153
B35: 刷卡直工 | C35: 426 | D35: 427 | E35: 428 | F35: 417 | G35: 0 | H35: 419 | I35: 426 | J35: 416 | K35: 424 | L35: 423 | M35: 418 | N35: 0 | O35: 424 | P35: 431 | Q35: 434 | R35: 433 | S35: 453 | T35: 444 | U35: 0 | V35: 445 | W35: 443 | X35: 456 | Y35: 452 | Z35: 491 | AA35: 146
B36: 刷卡間工 | C36: 47 | D36: 47 | E36: 47 | F36: 47 | G36: 0 | H36: 43 | I36: 46 | J36: 47 | K36: 48 | L36: 48 | M36: 43 | N36: 0 | O36: 47 | P36: 47 | Q36: 48 | R36: 46 | S36: 45 | T36: 43 | U36: 0 | V36: 46 | W36: 44 | X36: 45 | Y36: 45 | Z36: 45 | AA36: 7
A37: B1 | B37: 刷卡總數 | C37: 3099 | D37: 3112 | E37: 3106 | F37: 3066 | G37: 0 | H37: 3029 | I37: 3071 | J37: 3050 | K37: 3049 | L37: 3067 | M37: 3039 | N37: 0 | O37: 3035 | P37: 3097 | Q37: 3110 | R37: 3093 | S37: 3115 | T37: 3092 | U37: 0 | V37: 3082 | W37: 3089 | X37: 3115 | Y37: 3107 | Z37: 3108 | AA37: 2
B38: 刷卡直工 | C38: 2907 | D38: 2917 | E38: 2912 | F38: 2887 | G38: 0 | H38: 2839 | I38: 2882 | J38: 2864 | K38: 2861 | L38: 2874 | M38: 2851 | N38: 0 | O38: 2849 | P38: 2904 | Q38: 2920 | R38: 2907 | S38: 2925 | T38: 2908 | U38: 0 | V38: 2895 | W38: 2907 | X38: 2935 | Y38: 2927 | Z38: 2927 | AA38: 1
B39: 刷卡間工 | C39: 192 | D39: 195 | E39: 194 | F39: 179 | G39: 0 | H39: 190 | I39: 189 | J39: 186 | K39: 188 | L39: 193 | M39: 188 | N39: 0 | O39: 186 | P39: 193 | Q39: 190 | R39: 186 | S39: 190 | T39: 184 | U39: 0 | V39: 187 | W39: 182 | X39: 180 | Y39: 180 | Z39: 181 | AA39: 1
A40: B | B40: 刷卡總數 | C40: 928 | D40: 925 | E40: 924 | F40: 669 | G40: 0 | H40: 903 | I40: 908 | J40: 909 | K40: 908 | L40: 910 | M40: 899 | N40: 0 | O40: 943 | P40: 963 | Q40: 964 | R40: 959 | S40: 977 | T40: 967 | U40: 0 | V40: 982 | W40: 983 | X40: 998 | Y40: 993 | Z40: 995 | AA40: 16
...

Sheet 3.2.A1廠人均時產能-針車
A1: 回到首頁
A2: 2017/03月針車人均時產能報表
A3: Lean線 | B3: 項目 | C3: 總計 | D3: 日平均 | E3: 1 | F3: 2 | G3: 3 | H3: 4 | I3: 5 | J3: 6 | K3: 7 | L3: 8 | M3: 9 | N3: 10 | O3: 11 | P3: 12 | Q3: 13 | R3: 14 | S3: 15 | T3: 16 | U3: 17 | V3: 18 | W3: 19 | X3: 20 | Y3: 21 | Z3: 22 | AA3: 23 | AB3: 24 | AC3: 25 | AD3: 26 | AE3: 27 | AF3: 28 | AG3: 29 | AH3: 30 | AI3: 31
A4: 總計 | B4: 標準產量 | C4: 774152 | D4: 35188.727 | E4: 37296 | F4: 37480 | G4: 37544 | H4: 37144 | J4: 37080 | K4: 37040 | L4: 37080 | M4: 36936 | N4: 36848 | O4: 36720 | Q4: 36616 | R4: 36208 | S4: 35760 | T4: 35080 | U4: 34256 | V4: 34256 | X4: 32760 | Y4: 32376 | Z4: 31880 | AA4: 31672 | AB4: 31248 | AC4: 30872
B5: 目標產量 | C5: 703580 | D5: 31980.909 | E5: 33220 | F5: 34720 | G5: 35240 | H5: 35240 | J5: 34900 | K5: 34900 | L5: 35200 | M5: 35020 | N5: 35020 | O5: 34160 | Q5: 34480 | R5: 33600 | S5: 33440 | T5: 30700 | U5: 30260 | V5: 29720 | X5: 26460 | Y5: 26620 | Z5: 26840 | AA5: 27840 | AB5: 28180 | AC5: 27820 | AE5: 26964 | AF5: 27624 | AG5: 28272 | AH5: 28272 | AI5: 28272
B6: 實際產量 | C6: 693399 | D6: 31518.136 | E6: 33769 | F6: 36021 | G6: 35782 | H6: 35970 | J6: 36950 | K6: 36045 | L6: 35862 | M6: 35254 | N6: 35789 | O6: 33973 | Q6: 33011 | R6: 30336 | S6: 30267 | T6: 29529 | U6: 29108 | V6: 27071 | X6: 27316 | Y6: 25481 | Z6: 25766 | AA6: 27169 | AB6: 27190 | AC6: 25740
B7: 差異 | C7: -10181 | D7: -462.77273 | E7: 549 | F7: 1301 | G7: 542 | H7: 730 | J7: 2050 | K7: 1145 | L7: 662 | M7: 234 | N7: 769 | O7: -187 | Q7: -1469 | R7: -3264 | S7: -3173 | T7: -1171 | U7: -1152 | V7: -2649 | X7: 856 | Y7: -1139 | Z7: -1074 | AA7: -671 | AB7: -990 | AC7: -2080
B8: 工時 | C8: 176 | D8: 8 | E8: 8 | F8: 8 | G8: 8 | H8: 8 | J8: 8 | K8: 8 | L8: 8 | M8: 8 | N8: 8 | O8: 8 | Q8: 8 | R8: 8 | S8: 8 | T8: 8 | U8: 8 | V8: 8 | X8: 8 | Y8: 8 | Z8: 8 | AA8: 8 | AB8: 8 | AC8: 8
B9: 直工人數 | C9: 2101 | D9: 2101 | E9: 2145 | F9: 2140 | G9: 2141 | H9: 2111 | J9: 2041 | K9: 2087 | L9: 2107 | M9: 2103 | N9: 2069 | O9: 2035 | Q9: 2077 | R9: 2127 | S9: 2138 | T9: 2138 | U9: 2132 | V9: 2102 | X9: 2096 | Y9: 2121 | Z9: 2143 | AA9: 2138 | AB9: 2129 | AC9: 2107
B10: 時產能 | C10: 3939.767 | D10: 3939.767 | E10: 4221.125 | F10: 4502.625 | G10: 4472.75 | H10: 4496.25 | J10: 4618.75 | K10: 4505.625 | L10: 4482.75 | M10: 4406.75 | N10: 4473.625 | O10: 4246.625 | Q10: 4126.375 | R10: 3792 | S10: 3783.375 | T10: 3691.125 | U10: 3638.5 | V10: 3383.875 | X10: 3414.5 | Y10: 3185.125 | Z10: 3220.75 | AA10: 3396.125 | AB10: 3398.75 | AC10: 3217.5
B11: 人均時產 | C11: 1.8751866 | D11: 1.8751866 | E11: 1.9678904 | F11: 2.1040304 | G11: 2.0890939 | H11: 2.1299147 | J11: 2.2629838 | K11: 2.1589003 | L11: 2.127551 | M11: 2.0954589 | N11: 2.162216 | O11: 2.0867936 | Q11: 1.9866996 | R11: 1.7827927 | S11: 1.7695861 | T11: 1.7264383 | U11: 1.7066135 | V11: 1.6098359 | X11: 1.6290553 | Y11: 1.5017091 | Z11: 1.5029165 | AA11: 1.5884588 | AB11: 1.5964068 | AC11: 1.5270527
A12: A1_LEAN1-01_M | B12: 標準產量 | C12: 38616 | D12: 1755.2727 | E12: 1696 | F12: 1720 | G12: 1760 | H12: 1760 | J12: 1760 | K12: 1760 | L12: 1760 | M12: 1760 | N12: 1760 | O12: 1760 | Q12: 1760 | R12: 1760 | S12: 1760 | T12: 1760 | U12: 1760 | V12: 1760 | X12: 1760 | Y12: 1760 | Z12: 1760 | AA12: 1760 | AB12: 1760 | AC12: 1760
B13: 目標產量 | C13: 34360 | D13: 1561.8182 | E13: 1320 | F13: 1320 | G13: 1760 | H13: 1760 | J13: 1760 | K13: 1760 | L13: 1760 | M13: 1760 | N13: 1760 | O13: 1760 | Q13: 1760 | R13: 1760 | S13: 1760 | T13: 1760 | U13: 1760 | V13: 1020 | X13: 1020 | Y13: 1360 | Z13: 1360 | AA13: 1360 | AB13: 1360 | AC13: 1360 | AE13: 1360 | AF13: 1360 | AG13: 1360 | AH13: 1360 | AI13: 1360
B14: 實際產量 | C14: 35748 | D14: 1624.9091 | E14: 1896 | F14: 1944 | G14: 1764 | H14: 1764 | J14: 1764 | K14: 1818 | L14: 1788 | M14: 1764 | N14: 1764 | O14: 1764 | Q14: 1764 | R14: 1770 | S14: 1764 | T14: 1764 | U14: 1764 | V14: 1026 | X14: 1020 | Y14: 1362 | Z14: 1362 | AA14: 1362 | AB14: 1398 | AC14: 1362
B15: 差異 | C15: 1388 | D15: 63.090909 | E15: 576 | F15: 624 | G15: 4 | H15: 4 | J15: 4 | K15: 58 | L15: 28 | M15: 4 | N15: 4 | O15: 4 | Q15: 4 | R15: 10 | S15: 4 | T15: 4 | U15: 4 | V15: 6 | X15: 0 | Y15: 2 | Z15: 2 | AA15: 2 | AB15: 38 | AC15: 2
B16: 工時 | C16: 176 | D16: 8 | E16: 8 | F16: 8 | G16: 8 | H16: 8 | J16: 8 | K16: 8 | L16: 8 | M16: 8 | N16: 8 | O16: 8 | Q16: 8 | R16: 8 | S16: 8 | T16: 8 | U16: 8 | V16: 8 | X16: 8 | Y16: 8 | Z16: 8 | AA16: 8 | AB16: 8 | AC16: 8
B17: 直工人數 | C17: 127 | D17: 127 | E17: 123 | F17: 120 | G17: 117 | H17: 117 | J17: 110 | K17: 113 | L17: 116 | M17: 119 | N17: 122 | O17: 120 | Q17: 130 | R17: 137 | S17: 137 | T17: 135 | U17: 139 | V17: 135 | X17: 135 | Y17: 135 | Z17: 138 | AA17: 137 | AB17: 135 | AC17: 133
B18: 時產能 | C18: 203.11364 | D18: 203.11364 | E18: 237 | F18: 243 | G18: 220.5 | H18: 220.5 | J18: 220.5 | K18: 227.25 | L18: 223.5 | M18: 220.5 | N18: 220.5 | O18: 220.5 | Q18: 220.5 | R18: 221.25 | S18: 220.5 | T18: 220.5 | U18: 220.5 | V18: 128.25 | X18: 127.5 | Y18: 170.25 | Z18: 170.25 | AA18: 170.25 | AB18: 174.75 | AC18: 170.25
B19: 人均時產 | C19: 1.5993 | D19: 1.5993 | E19: 1.9268 | F19: 2.025 | G19: 1.8846 | H19: 1.8846 | J19: 2.0045 | K19: 2.0111 | L19: 1.9267 | M19: 1.8529 | N19: 1.8074 | O19: 1.8375 | Q19: 1.6962 | R19: 1.615 | S19: 1.6095 | T19: 1.6333 | U19: 1.5863 | V19: 0.95 | X19: 0.9444 | Y19: 1.2611 | Z19: 1.2337 | AA19: 1.2427 | AB19: 1.2944 | AC19: 1.2801
A20: A1_LEAN1-02_M | B20: 標準產量 | C20: 38960 | D20: 1770.9091 | E20: 1760 | F20: 1760 | G20: 1760 | H20: 1760 | J20: 1760 | K20: 1760 | L20: 1760 | M20: 1760 | N20: 1760 | O20: 1760 | Q20: 1760 | R20: 1760 | S20: 1760 | T20: 1760 | U20: 1800 | V20: 1840 | X20: 1840 | Y20: 1800 | Z20: 1760 | AA20: 1760 | AB20: 1760 | AC20: 1760
B21: 目標產量 | C21: 35300 | D21: 1604.5455 | E21: 1760 | F21: 1760 | G21: 1760 | H21: 1760 | J21: 1760 | K21: 1760 | L21: 1760 | M21: 1760 | N21: 1760 | O21: 1760 | Q21: 1760 | R21: 1760 | S21: 1760 | T21: 1760 | U21: 1760 | V21: 1760 | X21: 1020 | Y21: 1020 | Z21: 1360 | AA21: 1360 | AB21: 1360 | AC21: 1020 | AE21: 1020 | AF21: 1360 | AG21: 1360 | AH21: 1360 | AI21: 1360
B22: 實際產量 | C22: 35711 | D22: 1623.2273 | E22: 1788 | F22: 1764 | G22: 1764 | H22: 1764 | J22: 1764 | K22: 1800 | L22: 1764 | M22: 1764 | N22: 1764 | O22: 1763 | Q22: 1764 | R22: 1764 | S22: 1764 | T22: 1764 | U22: 1764 | V22: 1764 | X22: 1302 | Y22: 1020 | Z22: 1362 | AA22: 1362 | AB22: 1362 | AC22: 1020
B23: 差異 | C23: 411 | D23: 18.681818 | E23: 28 | F23: 4 | G23: 4 | H23: 4 | J23: 4 | K23: 40 | L23: 4 | M23: 4 | N23: 4 | O23: 3 | Q23: 4 | R23: 4 | S23: 4 | T23: 4 | U23: 4 | V23: 4 | X23: 282 | Y23: 0 | Z23: 2 | AA23: 2 | AB23: 2 | AC23: 0
B24: 工時 | C24: 176 | D24: 8 | E24: 8 | F24: 8 | G24: 8 | H24: 8 | J24: 8 | K24: 8 | L24: 8 | M24: 8 | N24: 8 | O24: 8 | Q24: 8 | R24: 8 | S24: 8 | T24: 8 | U24: 8 | V24: 8 | X24: 8 | Y24: 8 | Z24: 8 | AA24: 8 | AB24: 8 | AC24: 8
B25: 直工人數 | C25: 106 | D25: 106 | E25: 116 | F25: 114 | G25: 113 | H25: 109 | J25: 104 | K25: 106 | L25: 109 | M25: 101 | N25: 85 | O25: 83 | Q25: 106 | R25: 108 | S25: 112 | T25: 115 | U25: 102 | V25: 103 | X25: 105 | Y25: 106 | Z25: 110 | AA25: 113 | AB25: 113 | AC25: 110
B26: 時產能 | C26: 202.90341 | D26: 202.90341 | E26: 223.5 | F26: 220.5 | G26: 220.5 | H26: 220.5 | J26: 220.5 | K26: 225 | L26: 220.5 | M26: 220.5 | N26: 220.5 | O26: 220.375 | Q26: 220.5 | R26: 220.5 | S26: 220.5 | T26: 220.5 | U26: 220.5 | V26: 220.5 | X26: 162.75 | Y26: 127.5 | Z26: 170.25 | AA26: 170.25 | AB26: 170.25 | AC26: 127.5
B27: 人均時產 | C27: 1.9142 | D27: 1.9142 | E27: 1.9267 | F27: 1.9342 | G27: 1.9513 | H27: 2.0229 | J27: 2.1202 | K27: 2.1226 | L27: 2.0229 | M27: 2.1832 | N27: 2.5941 | O27: 2.6551 | Q27: 2.0802 | R27: 2.0417 | S27: 1.9688 | T27: 1.9174 | U27: 2.1618 | V27: 2.1408 | X27: 1.55 | Y27: 1.2028 | Z27: 1.5477 | AA27: 1.5066 | AB27: 1.5066 | AC27: 1.1591
A28: A1_LEAN1-03_M | B28: 標準產量 | C28: 38432 | D28: 1746.9091 | E28: 1760 | F28: 1760 | G28: 1760 | H28: 1760 | J28: 1760 | K28: 1760 | L28: 1760 | M28: 1760 | N28: 1760 | O28: 1760 | Q28: 1760 | R28: 1760 | S28: 1760 | T28: 1760 | U28: 1760 | V28: 1760 | X28: 1760 | Y28: 1760 | Z28: 1760 | AA28: 1760 | AB28: 1760 | AC28: 1472
B29: 目標產量 | C29: 34760 | D29: 1580 | E29: 1320 | F29: 1320 | G29: 1760 | H29: 1760 | J29: 1760 | K29: 1760 | L29: 1760 | M29: 1760 | N29: 1760 | O29: 1760 | Q29: 1760 | R29: 1760 | S29: 1760 | T29: 1760 | U29: 1760 | V29: 1760 | X29: 1020 | Y29: 1020 | Z29: 1360 | AA29: 1360 | AB29: 1360 | AC29: 1360 | AE29: 1360 | AF29: 1360 | AG29: 1360 | AH29: 1360 | AI29: 1360
B30: 實際產量 | C30: 34894 | D30: 1586.0909 | E30: 1356 | F30: 1320 | G30: 1764 | H30: 1764 | J30: 1764 | K30: 1764 | L30: 1774 | M30: 1776 | N30: 1764 | O30: 1766 | Q30: 1762 | R30: 1764 | S30: 1764 | T30: 1764 | U30: 1764 | V30: 1764 | X30: 1032 | Y30: 1020 | Z30: 1362 | AA30: 1362 | AB30: 1362 | AC30: 1362
B31: 差異 | C31: 134 | D31: 6.0909091 | E31: 36 | F31: 0 | G31: 4 | H31: 4 | J31: 4 | K31: 4 | L31: 14 | M31: 16 | N31: 4 | O31: 6 | Q31: 2 | R31: 4 | S31: 4 | T31: 4 | U31: 4 | V31: 4 | X31: 12 | Y31: 0 | Z31: 2 | AA31: 2 | AB31: 2 | AC31: 2
B32: 工時 | C32: 176 | D32: 8 | E32: 8 | F32: 8 | G32: 8 | H32: 8 | J32: 8 | K32: 8 | L32: 8 | M32: 8 | N32: 8 | O32: 8 | Q32: 8 | R32: 8 | S32: 8 | T32: 8 | U32: 8 | V32: 8 | X32: 8 | Y32: 8 | Z32: 8 | AA32: 8 | AB32: 8 | AC32: 8
B33: 直工人數 | C33: 121 | D33: 121 | E33: 121 | F33: 122 | G33: 126 | H33: 122 | J33: 120 | K33: 120 | L33: 122 | M33: 124 | N33: 95 | O33: 93 | Q33: 124 | R33: 126 | S33: 126 | T33: 126 | U33: 126 | V33: 122 | X33: 119 | Y33: 123 | Z33: 126 | AA33: 128 | AB33: 128 | AC33: 127
B34: 時產能 | C34: 198.26136 | D34: 198.26136 | E34: 169.5 | F34: 165 | G34: 220.5 | H34: 220.5 | J34: 220.5 | K34: 220.5 | L34: 221.75 | M34: 222 | N34: 220.5 | O34: 220.75 | Q34: 220.25 | R34: 220.5 | S34: 220.5 | T34: 220.5 | U34: 220.5 | V34: 220.5 | X34: 129 | Y34: 127.5 | Z34: 170.25 | AA34: 170.25 | AB34: 170.25 | AC34: 170.25
B35: 人均時產 | C35: 1.6385 | D35: 1.6385 | E35: 1.4008 | F35: 1.3525 | G35: 1.75 | H35: 1.8074 | J35: 1.8375 | K35: 1.8375 | L35: 1.8176 | M35: 1.7903 | N35: 2.3211 | O35: 2.3737 | Q35: 1.7762 | R35: 1.75 | S35: 1.75 | T35: 1.75 | U35: 1.75 | V35: 1.8074 | X35: 1.084 | Y35: 1.0366 | Z35: 1.3512 | AA35: 1.3301 | AB35: 1.3301 | AC35: 1.3406
A36: A1_LEAN1-04_M | B36: 標準產量 | C36: 37304 | D36: 1695.6364 | E36: 1760 | F36: 1760 | G36: 1760 | H36: 1760 | J36: 1760 | K36: 1760 | L36: 1760 | M36: 1760 | N36: 1760 | O36: 1760 | Q36: 1760 | R36: 1760 | S36: 1760 | T36: 1760 | U36: 1760 | V36: 1680 | X36: 1600 | Y36: 1600 | Z36: 1600 | AA36: 1640 | AB36: 1504 | AC36: 1280
B37: 目標產量 | C37: 35720 | D37: 1623.6364 | E37: 1680 | F37: 1680 | G37: 1320 | H37: 1320 | J37: 1760 | K37: 1760 | L37: 1760 | M37: 1760 | N37: 1760 | O37: 1760 | Q37: 1760 | R37: 1760 | S37: 1760 | T37: 1760 | U37: 1760 | V37: 1760 | X37: 1760 | Y37: 1140 | Z37: 1140 | AA37: 1520 | AB37: 1520 | AC37: 1520 | AE37: 984 | AF37: 984 | AG37: 1312 | AH37: 1312 | AI37: 1312
B38: 實際產量 | C38: 35990 | D38: 1635.9091 | E38: 1718 | F38: 1740 | G38: 1326 | H38: 1320 | J38: 1764 | K38: 1764 | L38: 1764 | M38: 1764 | N38: 1764 | O38: 1764 | Q38: 1764 | R38: 1764 | S38: 1764 | T38: 1764 | U38: 1764 | V38: 1764 | X38: 1788 | Y38: 1140 | Z38: 1140 | AA38: 1524 | AB38: 1602 | AC38: 1524
B39: 差異 | C39: 270 | D39: 12.272727 | E39: 38 | F39: 60 | G39: 6 | H39: 0 | J39: 4 | K39: 4 | L39: 4 | M39: 4 | N39: 4 | O39: 4 | Q39: 4 | R39: 4 | S39: 4 | T39: 4 | U39: 4 | V39: 4 | X39: 28 | Y39: 0 | Z39: 0 | AA39: 4 | AB39: 82 | AC39: 4
B40: 工時 | C40: 176 | D40: 8 | E40: 8 | F40: 8 | G40: 8 | H40: 8 | J40: 8 | K40: 8 | L40: 8 | M40: 8 | N40: 8 | O40: 8 | Q40: 8 | R40: 8 | S40: 8 | T40: 8 | U40: 8 | V40: 8 | X40: 8 | Y40: 8 | Z40: 8 | AA40: 8 | AB40: 8 | AC40: 8
...

Sheet 3.3.A2廠人均時產能-針車
A1: 回到首頁
A2: 2017/03月針車人均時產能報表
A3: Lean線 | B3: 項目 | C3: 總計 | D3: 日平均 | E3: 1 | F3: 2 | G3: 3 | H3: 4 | I3: 5 | J3: 6 | K3: 7 | L3: 8 | M3: 9 | N3: 10 | O3: 11 | P3: 12 | Q3: 13 | R3: 14 | S3: 15 | T3: 16 | U3: 17 | V3: 18 | W3: 19 | X3: 20 | Y3: 21 | Z3: 22 | AA3: 23 | AB3: 24 | AC3: 25 | AD3: 26 | AE3: 27 | AF3: 28 | AG3: 29 | AH3: 30 | AI3: 31
A4: 總計 | B4: 標準產量 | C4: 606112 | D4: 28862.476 | E4: 30080 | F4: 30304 | G4: 30096 | H4: 29920 | J4: 29760 | K4: 30080 | L4: 29792 | M4: 29256 | N4: 29440 | O4: 29480 | Q4: 29048 | R4: 28960 | S4: 28464 | T4: 27792 | U4: 27960 | V4: 28240 | X4: 27712 | Y4: 27560 | Z4: 27760 | AA4: 27400 | AB4: 27008
B5: 目標產量 | C5: 561740 | D5: 26749.524 | E5: 27860 | F5: 26750 | G5: 27790 | H5: 28520 | J5: 28520 | K5: 28520 | L5: 28520 | M5: 28000 | N5: 28440 | O5: 27200 | Q5: 26300 | R5: 27000 | S5: 24620 | T5: 25380 | U5: 26520 | V5: 26020 | X5: 25360 | Y5: 24340 | Z5: 24870 | AA5: 25210 | AB5: 26000 | AC5: 25440 | AE5: 25840 | AF5: 24990 | AG5: 24470 | AH5: 24480 | AI5: 24640
B6: 實際產量 | C6: 556851 | D6: 26516.714 | E6: 27944 | F6: 26847 | G6: 27609 | H6: 28137 | J6: 27914 | K6: 28814 | L6: 28372 | M6: 27156 | N6: 27192 | O6: 27366 | Q6: 26456 | R6: 25775 | S6: 23601 | T6: 25014 | U6: 26889 | V6: 26397 | X6: 25146 | Y6: 24342 | Z6: 24718 | AA6: 25296 | AB6: 25866
B7: 差異 | C7: -4889 | D7: -232.80952 | E7: 84 | F7: 97 | G7: -181 | H7: -383 | J7: -606 | K7: 294 | L7: -148 | M7: -844 | N7: -1248 | O7: 166 | Q7: 156 | R7: -1225 | S7: -1019 | T7: -366 | U7: 369 | V7: 377 | X7: -214 | Y7: 2 | Z7: -152 | AA7: 86 | AB7: -134
B8: 工時 | C8: 168 | D8: 8 | E8: 8 | F8: 8 | G8: 8 | H8: 8 | J8: 8 | K8: 8 | L8: 8 | M8: 8 | N8: 8 | O8: 8 | Q8: 8 | R8: 8 | S8: 8 | T8: 8 | U8: 8 | V8: 8 | X8: 8 | Y8: 8 | Z8: 8 | AA8: 8 | AB8: 8
B9: 直工人數 | C9: 1673 | D9: 1673 | E9: 1687 | F9: 1690 | G9: 1670 | H9: 1660 | J9: 1632 | K9: 1655 | L9: 1661 | M9: 1665 | N9: 1679 | O9: 1687 | Q9: 1679 | R9: 1715 | S9: 1711 | T9: 1698 | U9: 1694 | V9: 1678 | X9: 1693 | Y9: 1692 | Z9: 1709 | AA9: 1702 | AB9: 1688
B10: 時產能 | C10: 3314.5893 | D10: 3314.5893 | E10: 3493 | F10: 3355.875 | G10: 3451.125 | H10: 3517.125 | J10: 3489.25 | K10: 3601.75 | L10: 3546.5 | M10: 3394.5 | N10: 3399 | O10: 3420.75 | Q10: 3307 | R10: 3221.875 | S10: 2950.125 | T10: 3126.75 | U10: 3361.125 | V10: 3299.625 | X10: 3143.25 | Y10: 3042.75 | Z10: 3089.75 | AA10: 3162 | AB10: 3233.25
B11: 人均時產 | C11: 1.9812249 | D11: 1.9812249 | E11: 2.0705394 | F11: 1.9857249 | G11: 2.0665419 | H11: 2.11875 | J11: 2.1380208 | K11: 2.176284 | L11: 2.1351595 | M11: 2.0387387 | N11: 2.0244193 | O11: 2.0277119 | Q11: 1.9696248 | R11: 1.8786443 | S11: 1.724211 | T11: 1.8414311 | U11: 1.9841352 | V11: 1.9664035 | X11: 1.8566155 | Y11: 1.7983156 | Z11: 1.8079286 | AA11: 1.8578143 | AB11: 1.9154325
A12: A2_LEAN1-01_M | B12: 標準產量 | C12: 36344 | D12: 1730.6667 | E12: 1760 | F12: 1760 | G12: 1760 | H12: 1760 | J12: 1760 | K12: 1760 | L12: 1760 | M12: 1760 | N12: 1760 | O12: 1760 | Q12: 1760 | R12: 1760 | S12: 1760 | T12: 1704 | U12: 1680 | V12: 1680 | X12: 1680 | Y12: 1680 | Z12: 1680 | AA12: 1680 | AB12: 1680
B13: 目標產量 | C13: 30920 | D13: 1472.381 | E13: 1520 | F13: 1520 | G13: 1520 | H13: 1520 | J13: 1520 | K13: 1520 | L13: 1520 | M13: 1520 | N13: 1520 | O13: 1520 | Q13: 1520 | R13: 1520 | S13: 1520 | T13: 1080 | U13: 1440 | V13: 1440 | X13: 1440 | Y13: 1440 | Z13: 1440 | AA13: 1440 | AB13: 1440 | AC13: 1440 | AE13: 1440 | AF13: 1440 | AG13: 1440 | AH13: 1440 | AI13: 1440
B14: 實際產量 | C14: 31872 | D14: 1517.7143 | E14: 1458 | F14: 1728 | G14: 1512 | H14: 1416 | J14: 1620 | K14: 1548 | L14: 1494 | M14: 1398 | N14: 1500 | O14: 1548 | Q14: 1680 | R14: 1392 | S14: 1560 | T14: 1224 | U14: 1620 | V14: 1446 | X14: 1470 | Y14: 1524 | Z14: 1548 | AA14: 1596 | AB14: 1590
B15: 差異 | C15: 952 | D15: 45.333333 | E15: -62 | F15: 208 | G15: -8 | H15: -104 | J15: 100 | K15: 28 | L15: -26 | M15: -122 | N15: -20 | O15: 28 | Q15: 160 | R15: -128 | S15: 40 | T15: 144 | U15: 180 | V15: 6 | X15: 30 | Y15: 84 | Z15: 108 | AA15: 156 | AB15: 150
B16: 工時 | C16: 168 | D16: 8 | E16: 8 | F16: 8 | G16: 8 | H16: 8 | J16: 8 | K16: 8 | L16: 8 | M16: 8 | N16: 8 | O16: 8 | Q16: 8 | R16: 8 | S16: 8 | T16: 8 | U16: 8 | V16: 8 | X16: 8 | Y16: 8 | Z16: 8 | AA16: 8 | AB16: 8
B17: 直工人數 | C17: 73 | D17: 73 | E17: 77 | F17: 76 | G17: 75 | H17: 74 | J17: 72 | K17: 74 | L17: 72 | M17: 71 | N17: 73 | O17: 70 | Q17: 73 | R17: 75 | S17: 75 | T17: 75 | U17: 72 | V17: 74 | X17: 74 | Y17: 75 | Z17: 74 | AA17: 75 | AB17: 74
B18: 時產能 | C18: 189.71429 | D18: 189.71429 | E18: 182.25 | F18: 216 | G18: 189 | H18: 177 | J18: 202.5 | K18: 193.5 | L18: 186.75 | M18: 174.75 | N18: 187.5 | O18: 193.5 | Q18: 210 | R18: 174 | S18: 195 | T18: 153 | U18: 202.5 | V18: 180.75 | X18: 183.75 | Y18: 190.5 | Z18: 193.5 | AA18: 199.5 | AB18: 198.75
B19: 人均時產 | C19: 2.5988 | D19: 2.5988 | E19: 2.3669 | F19: 2.8421 | G19: 2.52 | H19: 2.3919 | J19: 2.8125 | K19: 2.6149 | L19: 2.5938 | M19: 2.4613 | N19: 2.5685 | O19: 2.7643 | Q19: 2.8767 | R19: 2.32 | S19: 2.6 | T19: 2.04 | U19: 2.8125 | V19: 2.4426 | X19: 2.4831 | Y19: 2.54 | Z19: 2.6149 | AA19: 2.66 | AB19: 2.6858
A20: A2_LEAN1-02_M | B20: 標準產量 | C20: 36960 | D20: 1760 | E20: 1760 | F20: 1760 | G20: 1760 | H20: 1760 | J20: 1760 | K20: 1760 | L20: 1760 | M20: 1760 | N20: 1760 | O20: 1760 | Q20: 1760 | R20: 1760 | S20: 1760 | T20: 1760 | U20: 1760 | V20: 1760 | X20: 1760 | Y20: 1760 | Z20: 1760 | AA20: 1760 | AB20: 1760
B21: 目標產量 | C21: 34860 | D21: 1660 | E21: 1680 | F21: 1680 | G21: 1680 | H21: 1680 | J21: 1680 | K21: 1680 | L21: 1680 | M21: 1680 | N21: 1680 | O21: 1260 | Q21: 1680 | R21: 1680 | S21: 1680 | T21: 1680 | U21: 1680 | V21: 1680 | X21: 1680 | Y21: 1680 | Z21: 1680 | AA21: 1680 | AB21: 1680 | AC21: 1680 | AE21: 1680 | AF21: 1680 | AG21: 1680 | AH21: 1680 | AI21: 1680
B22: 實際產量 | C22: 33812 | D22: 1610.0952 | E22: 1752 | F22: 1632 | G22: 1320 | H22: 1518 | J22: 1542 | K22: 1698 | L22: 1530 | M22: 1656 | N22: 1608 | O22: 1440 | Q22: 1596 | R22: 1580 | S22: 1560 | T22: 1512 | U22: 1728 | V22: 1728 | X22: 1518 | Y22: 1722 | Z22: 1734 | AA22: 1722 | AB22: 1716
B23: 差異 | C23: -1048 | D23: -49.904762 | E23: 72 | F23: -48 | G23: -360 | H23: -162 | J23: -138 | K23: 18 | L23: -150 | M23: -24 | N23: -72 | O23: 180 | Q23: -84 | R23: -100 | S23: -120 | T23: -168 | U23: 48 | V23: 48 | X23: -162 | Y23: 42 | Z23: 54 | AA23: 42 | AB23: 36
B24: 工時 | C24: 168 | D24: 8 | E24: 8 | F24: 8 | G24: 8 | H24: 8 | J24: 8 | K24: 8 | L24: 8 | M24: 8 | N24: 8 | O24: 8 | Q24: 8 | R24: 8 | S24: 8 | T24: 8 | U24: 8 | V24: 8 | X24: 8 | Y24: 8 | Z24: 8 | AA24: 8 | AB24: 8
B25: 直工人數 | C25: 89 | D25: 89 | E25: 91 | F25: 90 | G25: 91 | H25: 92 | J25: 86 | K25: 91 | L25: 90 | M25: 89 | N25: 92 | O25: 88 | Q25: 87 | R25: 89 | S25: 89 | T25: 88 | U25: 89 | V25: 88 | X25: 89 | Y25: 90 | Z25: 88 | AA25: 88 | AB25: 88
B26: 時產能 | C26: 201.2619 | D26: 201.2619 | E26: 219 | F26: 204 | G26: 165 | H26: 189.75 | J26: 192.75 | K26: 212.25 | L26: 191.25 | M26: 207 | N26: 201 | O26: 180 | Q26: 199.5 | R26: 197.5 | S26: 195 | T26: 189 | U26: 216 | V26: 216 | X26: 189.75 | Y26: 215.25 | Z26: 216.75 | AA26: 215.25 | AB26: 214.5
B27: 人均時產 | C27: 2.2614 | D27: 2.2614 | E27: 2.4066 | F27: 2.2667 | G27: 1.8132 | H27: 2.0625 | J27: 2.2413 | K27: 2.3324 | L27: 2.125 | M27: 2.3258 | N27: 2.1848 | O27: 2.0455 | Q27: 2.2931 | R27: 2.2191 | S27: 2.191 | T27: 2.1477 | U27: 2.427 | V27: 2.4545 | X27: 2.132 | Y27: 2.3917 | Z27: 2.4631 | AA27: 2.446 | AB27: 2.4375
A28: A2_LEAN1-03_M | B28: 標準產量 | C28: 36608 | D28: 1743.2381 | E28: 1760 | F28: 1760 | G28: 1760 | H28: 1760 | J28: 1760 | K28: 1760 | L28: 1760 | M28: 1760 | N28: 1760 | O28: 1760 | Q28: 1760 | R28: 1760 | S28: 1520 | T28: 1688 | U28: 1720 | V28: 1760 | X28: 1760 | Y28: 1760 | Z28: 1760 | AA28: 1760 | AB28: 1760
B29: 目標產量 | C29: 34020 | D29: 1620 | E29: 1680 | F29: 1680 | G29: 1680 | H29: 1680 | J29: 1680 | K29: 1680 | L29: 1680 | M29: 1680 | N29: 1680 | O29: 1680 | Q29: 1080 | R29: 1440 | S29: 1260 | T29: 1680 | U29: 1680 | V29: 1680 | X29: 1680 | Y29: 1680 | Z29: 1680 | AA29: 1680 | AB29: 1680 | AC29: 1680 | AE29: 1680 | AF29: 1680 | AG29: 1680 | AH29: 1680 | AI29: 1680
B30: 實際產量 | C30: 33944 | D30: 1616.381 | E30: 1776 | F30: 1572 | G30: 1644 | H30: 1812 | J30: 1728 | K30: 1728 | L30: 1530 | M30: 1842 | N30: 1704 | O30: 1686 | Q30: 1382 | R30: 1350 | S30: 990 | T30: 1506 | U30: 1554 | V30: 1716 | X30: 1518 | Y30: 1722 | Z30: 1728 | AA30: 1728 | AB30: 1728
B31: 差異 | C31: -76 | D31: -3.6190476 | E31: 96 | F31: -108 | G31: -36 | H31: 132 | J31: 48 | K31: 48 | L31: -150 | M31: 162 | N31: 24 | O31: 6 | Q31: 302 | R31: -90 | S31: -270 | T31: -174 | U31: -126 | V31: 36 | X31: -162 | Y31: 42 | Z31: 48 | AA31: 48 | AB31: 48
B32: 工時 | C32: 168 | D32: 8 | E32: 8 | F32: 8 | G32: 8 | H32: 8 | J32: 8 | K32: 8 | L32: 8 | M32: 8 | N32: 8 | O32: 8 | Q32: 8 | R32: 8 | S32: 8 | T32: 8 | U32: 8 | V32: 8 | X32: 8 | Y32: 8 | Z32: 8 | AA32: 8 | AB32: 8
B33: 直工人數 | C33: 86 | D33: 86 | E33: 91 | F33: 92 | G33: 86 | H33: 87 | J33: 88 | K33: 88 | L33: 89 | M33: 86 | N33: 88 | O33: 86 | Q33: 85 | R33: 88 | S33: 85 | T33: 88 | U33: 86 | V33: 85 | X33: 88 | Y33: 86 | Z33: 84 | AA33: 84 | AB33: 83
B34: 時產能 | C34: 202.04762 | D34: 202.04762 | E34: 222 | F34: 196.5 | G34: 205.5 | H34: 226.5 | J34: 216 | K34: 216 | L34: 191.25 | M34: 230.25 | N34: 213 | O34: 210.75 | Q34: 172.75 | R34: 168.75 | S34: 123.75 | T34: 188.25 | U34: 194.25 | V34: 214.5 | X34: 189.75 | Y34: 215.25 | Z34: 216 | AA34: 216 | AB34: 216
B35: 人均時產 | C35: 2.3494 | D35: 2.3494 | E35: 2.4396 | F35: 2.1359 | G35: 2.3895 | H35: 2.6034 | J35: 2.4545 | K35: 2.4545 | L35: 2.1489 | M35: 2.6773 | N35: 2.4205 | O35: 2.4506 | Q35: 2.0324 | R35: 1.9176 | S35: 1.4559 | T35: 2.1392 | U35: 2.2587 | V35: 2.5235 | X35: 2.1563 | Y35: 2.5029 | Z35: 2.5714 | AA35: 2.5714 | AB35: 2.6024
A36: A2_LEAN1-04_M | B36: 標準產量 | C36: 28056 | D36: 1336 | E36: 1760 | F36: 1640 | G36: 1376 | H36: 1280 | J36: 1280 | K36: 1520 | L36: 1280 | M36: 1280 | N36: 1280 | O36: 1280 | Q36: 1280 | R36: 1280 | S36: 1280 | T36: 1280 | U36: 1280 | V36: 1280 | X36: 1280 | Y36: 1280 | Z36: 1280 | AA36: 1280 | AB36: 1280
B37: 目標產量 | C37: 25860 | D37: 1231.4286 | E37: 1680 | F37: 930 | G37: 930 | H37: 1240 | J37: 1240 | K37: 1240 | L37: 1240 | M37: 1240 | N37: 1240 | O37: 1240 | Q37: 1240 | R37: 1240 | S37: 1240 | T37: 1240 | U37: 1240 | V37: 1240 | X37: 1240 | Y37: 1240 | Z37: 1240 | AA37: 1240 | AB37: 1240 | AC37: 1240 | AE37: 1240 | AF37: 1240 | AG37: 1240 | AH37: 1240 | AI37: 1240
B38: 實際產量 | C38: 26359 | D38: 1255.1905 | E38: 1656 | F38: 1059 | G38: 1059 | H38: 1061 | J38: 1130 | K38: 1292 | L38: 1272 | M38: 960 | N38: 1092 | O38: 1260 | Q38: 1176 | R38: 1245 | S38: 909 | T38: 1302 | U38: 1410 | V38: 1542 | X38: 1212 | Y38: 1260 | Z38: 1474 | AA38: 1344 | AB38: 1644
B39: 差異 | C39: 499 | D39: 23.761905 | E39: -24 | F39: 129 | G39: 129 | H39: -179 | J39: -110 | K39: 52 | L39: 32 | M39: -280 | N39: -148 | O39: 20 | Q39: -64 | R39: 5 | S39: -331 | T39: 62 | U39: 170 | V39: 302 | X39: -28 | Y39: 20 | Z39: 234 | AA39: 104 | AB39: 404
B40: 工時 | C40: 168 | D40: 8 | E40: 8 | F40: 8 | G40: 8 | H40: 8 | J40: 8 | K40: 8 | L40: 8 | M40: 8 | N40: 8 | O40: 8 | Q40: 8 | R40: 8 | S40: 8 | T40: 8 | U40: 8 | V40: 8 | X40: 8 | Y40: 8 | Z40: 8 | AA40: 8 | AB40: 8
...

Sheet 3.4 A1廠人均時產能-成型
A1: 回到首頁
A2: 2017/03月成型人均時產能報表
A3: Lean線 | B3: 項目 | C3: 總計 | D3: 日平均 | E3: 1 | F3: 2 | G3: 3 | H3: 4 | I3: 5 | J3: 6 | K3: 7 | L3: 8 | M3: 9 | N3: 10 | O3: 11 | P3: 12 | Q3: 13 | R3: 14 | S3: 15 | T3: 16 | U3: 17 | V3: 18 | W3: 19 | X3: 20 | Y3: 21 | Z3: 22 | AA3: 23 | AB3: 24 | AC3: 25 | AD3: 26 | AE3: 27 | AF3: 28 | AG3: 29 | AH3: 30 | AI3: 31
A4: 總計 | B4: 標準產量 | C4: 783824 | D4: 35628.364 | E4: 37232 | F4: 37024 | G4: 37520 | H4: 37216 | J4: 36968 | K4: 36856 | L4: 37312 | M4: 36976 | N4: 37048 | O4: 37040 | Q4: 36880 | R4: 37128 | S4: 36536 | T4: 35920 | U4: 35256 | V4: 34600 | X4: 34024 | Y4: 33088 | Z4: 33280 | AA4: 32304 | AB4: 32120 | AC4: 31496
B5: 目標產量 | C5: 703580 | D5: 31980.909 | E5: 33220 | F5: 34720 | G5: 35240 | H5: 35240 | J5: 34900 | K5: 34900 | L5: 35200 | M5: 35020 | N5: 35020 | O5: 34160 | Q5: 34480 | R5: 33600 | S5: 33440 | T5: 30700 | U5: 30260 | V5: 29720 | X5: 26460 | Y5: 26620 | Z5: 26840 | AA5: 27840 | AB5: 28180 | AC5: 27820 | AE5: 26964 | AF5: 27624 | AG5: 28272 | AH5: 28272 | AI5: 28272
B6: 實際產量 | C6: 690802 | D6: 31400.091 | E6: 32950 | F6: 35030 | G6: 35346 | H6: 35509 | J6: 36824 | K6: 35486 | L6: 34787 | M6: 33670 | N6: 34263 | O6: 33989 | Q6: 34078 | R6: 30035 | S6: 31537 | T6: 30298 | U6: 30450 | V6: 29240 | X6: 24522 | Y6: 24884 | Z6: 25371 | AA6: 27038 | AB6: 27735 | AC6: 27760
B7: 差異 | C7: -12778 | D7: -580.81818 | E7: -270 | F7: 310 | G7: 106 | H7: 269 | J7: 1924 | K7: 586 | L7: -413 | M7: -1350 | N7: -757 | O7: -171 | Q7: -402 | R7: -3565 | S7: -1903 | T7: -402 | U7: 190 | V7: -480 | X7: -1938 | Y7: -1736 | Z7: -1469 | AA7: -802 | AB7: -445 | AC7: -60
B8: 工時 | C8: 176 | D8: 8 | E8: 8 | F8: 8 | G8: 8 | H8: 8 | J8: 8 | K8: 8 | L8: 8 | M8: 8 | N8: 8 | O8: 8 | Q8: 8 | R8: 8 | S8: 8 | T8: 8 | U8: 8 | V8: 8 | X8: 8 | Y8: 8 | Z8: 8 | AA8: 8 | AB8: 8 | AC8: 8
B9: 直工人數 | C9: 1501 | D9: 1501 | E9: 1524 | F9: 1520 | G9: 1520 | H9: 1510 | J9: 1473 | K9: 1492 | L9: 1499 | M9: 1490 | N9: 1525 | O9: 1519 | Q9: 1507 | R9: 1537 | S9: 1531 | T9: 1522 | U9: 1530 | V9: 1503 | X9: 1496 | Y9: 1503 | Z9: 1506 | AA9: 1511 | AB9: 1502 | AC9: 1480
B10: 時產能 | C10: 3925.0114 | D10: 3925.0114 | E10: 4118.75 | F10: 4378.75 | G10: 4418.25 | H10: 4438.625 | J10: 4603 | K10: 4435.75 | L10: 4348.375 | M10: 4208.75 | N10: 4282.875 | O10: 4248.625 | Q10: 4259.75 | R10: 3754.375 | S10: 3942.125 | T10: 3787.25 | U10: 3806.25 | V10: 3655 | X10: 3065.25 | Y10: 3110.5 | Z10: 3171.375 | AA10: 3379.75 | AB10: 3466.875 | AC10: 3470
B11: 人均時產 | C11: 2.614931 | D11: 2.614931 | E11: 2.7025919 | F11: 2.8807566 | G11: 2.9067434 | H11: 2.9394868 | J11: 3.1249151 | K11: 2.9730228 | L11: 2.9008506 | M11: 2.8246644 | N11: 2.8084426 | O11: 2.7969882 | Q11: 2.8266423 | R11: 2.4426643 | S11: 2.5748694 | T11: 2.4883377 | U11: 2.4877451 | V11: 2.4318031 | X11: 2.0489639 | Y11: 2.0695276 | Z11: 2.1058267 | AA11: 2.2367637 | AB11: 2.3081724 | AC11: 2.3445946
A12: A1_LEAN1-01_G | B12: 標準產量 | C12: 38632 | D12: 1756 | E12: 1696 | F12: 1720 | G12: 1760 | H12: 1760 | J12: 1760 | K12: 1760 | L12: 1760 | M12: 1760 | N12: 1760 | O12: 1760 | Q12: 1760 | R12: 1760 | S12: 1760 | T12: 1760 | U12: 1760 | V12: 1760 | X12: 1760 | Y12: 1776 | Z12: 1760 | AA12: 1760 | AB12: 1760 | AC12: 1760
B13: 目標產量 | C13: 34360 | D13: 1561.8182 | E13: 1320 | F13: 1320 | G13: 1760 | H13: 1760 | J13: 1760 | K13: 1760 | L13: 1760 | M13: 1760 | N13: 1760 | O13: 1760 | Q13: 1760 | R13: 1760 | S13: 1760 | T13: 1760 | U13: 1760 | V13: 1020 | X13: 1020 | Y13: 1360 | Z13: 1360 | AA13: 1360 | AB13: 1360 | AC13: 1360 | AE13: 1360 | AF13: 1360 | AG13: 1360 | AH13: 1360 | AI13: 1360
B14: 實際產量 | C14: 35399 | D14: 1609.0455 | E14: 1818 | F14: 1760 | G14: 1760 | H14: 1761 | J14: 1760 | K14: 1760 | L14: 1760 | M14: 1760 | N14: 1760 | O14: 1760 | Q14: 1760 | R14: 1500 | S14: 1800 | T14: 1760 | U14: 1760 | V14: 1020 | X14: 1020 | Y14: 1360 | Z14: 1360 | AA14: 1360 | AB14: 1520 | AC14: 1520
B15: 差異 | C15: 1039 | D15: 47.227273 | E15: 498 | F15: 440 | G15: 0 | H15: 1 | J15: 0 | K15: 0 | L15: 0 | M15: 0 | N15: 0 | O15: 0 | Q15: 0 | R15: -260 | S15: 40 | T15: 0 | U15: 0 | V15: 0 | X15: 0 | Y15: 0 | Z15: 0 | AA15: 0 | AB15: 160 | AC15: 160
B16: 工時 | C16: 176 | D16: 8 | E16: 8 | F16: 8 | G16: 8 | H16: 8 | J16: 8 | K16: 8 | L16: 8 | M16: 8 | N16: 8 | O16: 8 | Q16: 8 | R16: 8 | S16: 8 | T16: 8 | U16: 8 | V16: 8 | X16: 8 | Y16: 8 | Z16: 8 | AA16: 8 | AB16: 8 | AC16: 8
B17: 直工人數 | C17: 70 | D17: 70 | E17: 73 | F17: 73 | G17: 73 | H17: 72 | J17: 71 | K17: 70 | L17: 72 | M17: 71 | N17: 73 | O17: 72 | Q17: 70 | R17: 73 | S17: 70 | T17: 69 | U17: 70 | V17: 71 | X17: 69 | Y17: 69 | Z17: 67 | AA17: 67 | AB17: 69 | AC17: 66
B18: 時產能 | C18: 201.13068 | D18: 201.13068 | E18: 227.25 | F18: 220 | G18: 220 | H18: 220.125 | J18: 220 | K18: 220 | L18: 220 | M18: 220 | N18: 220 | O18: 220 | Q18: 220 | R18: 187.5 | S18: 225 | T18: 220 | U18: 220 | V18: 127.5 | X18: 127.5 | Y18: 170 | Z18: 170 | AA18: 170 | AB18: 190 | AC18: 190
B19: 人均時產 | C19: 2.8733 | D19: 2.8733 | E19: 3.113 | F19: 3.0137 | G19: 3.0137 | H19: 3.0573 | J19: 3.0986 | K19: 3.1429 | L19: 3.0556 | M19: 3.0986 | N19: 3.0137 | O19: 3.0556 | Q19: 3.1429 | R19: 2.5685 | S19: 3.2143 | T19: 3.1884 | U19: 3.1429 | V19: 1.7958 | X19: 1.8478 | Y19: 2.4638 | Z19: 2.5373 | AA19: 2.5373 | AB19: 2.7536 | AC19: 2.8788
A20: A1_LEAN1-02_G | B20: 標準產量 | C20: 38864 | D20: 1766.5455 | E20: 1760 | F20: 1648 | G20: 1760 | H20: 1760 | J20: 1760 | K20: 1760 | L20: 1760 | M20: 1760 | N20: 1760 | O20: 1760 | Q20: 1760 | R20: 1760 | S20: 1760 | T20: 1760 | U20: 1760 | V20: 1800 | X20: 1776 | Y20: 1840 | Z20: 1800 | AA20: 1800 | AB20: 1800 | AC20: 1760
B21: 目標產量 | C21: 35300 | D21: 1604.5455 | E21: 1760 | F21: 1760 | G21: 1760 | H21: 1760 | J21: 1760 | K21: 1760 | L21: 1760 | M21: 1760 | N21: 1760 | O21: 1760 | Q21: 1760 | R21: 1760 | S21: 1760 | T21: 1760 | U21: 1760 | V21: 1760 | X21: 1020 | Y21: 1020 | Z21: 1360 | AA21: 1360 | AB21: 1360 | AC21: 1020 | AE21: 1020 | AF21: 1360 | AG21: 1360 | AH21: 1360 | AI21: 1360
B22: 實際產量 | C22: 36433 | D22: 1656.0455 | E22: 1766 | F22: 1811 | G22: 1760 | H22: 1760 | J22: 1807 | K22: 1760 | L22: 1760 | M22: 1760 | N22: 1760 | O22: 1794 | Q22: 1760 | R22: 1324 | S22: 1760 | T22: 1760 | U22: 1760 | V22: 1760 | X22: 1060 | Y22: 1172 | Z22: 1460 | AA22: 1408 | AB22: 1791 | AC22: 1680
B23: 差異 | C23: 1133 | D23: 51.5 | E23: 6 | F23: 51 | G23: 0 | H23: 0 | J23: 47 | K23: 0 | L23: 0 | M23: 0 | N23: 0 | O23: 34 | Q23: 0 | R23: -436 | S23: 0 | T23: 0 | U23: 0 | V23: 0 | X23: 40 | Y23: 152 | Z23: 100 | AA23: 48 | AB23: 431 | AC23: 660
B24: 工時 | C24: 176 | D24: 8 | E24: 8 | F24: 8 | G24: 8 | H24: 8 | J24: 8 | K24: 8 | L24: 8 | M24: 8 | N24: 8 | O24: 8 | Q24: 8 | R24: 8 | S24: 8 | T24: 8 | U24: 8 | V24: 8 | X24: 8 | Y24: 8 | Z24: 8 | AA24: 8 | AB24: 8 | AC24: 8
B25: 直工人數 | C25: 71 | D25: 71 | E25: 74 | F25: 74 | G25: 73 | H25: 73 | J25: 72 | K25: 71 | L25: 71 | M25: 73 | N25: 73 | O25: 68 | Q25: 69 | R25: 72 | S25: 73 | T25: 73 | U25: 73 | V25: 71 | X25: 71 | Y25: 70 | Z25: 69 | AA25: 72 | AB25: 70 | AC25: 69
B26: 時產能 | C26: 207.00568 | D26: 207.00568 | E26: 220.75 | F26: 226.375 | G26: 220 | H26: 220 | J26: 225.875 | K26: 220 | L26: 220 | M26: 220 | N26: 220 | O26: 224.25 | Q26: 220 | R26: 165.5 | S26: 220 | T26: 220 | U26: 220 | V26: 220 | X26: 132.5 | Y26: 146.5 | Z26: 182.5 | AA26: 176 | AB26: 223.875 | AC26: 210
B27: 人均時產 | C27: 2.9156 | D27: 2.9156 | E27: 2.9831 | F27: 3.0591 | G27: 3.0137 | H27: 3.0137 | J27: 3.1372 | K27: 3.0986 | L27: 3.0986 | M27: 3.0137 | N27: 3.0137 | O27: 3.2978 | Q27: 3.1884 | R27: 2.2986 | S27: 3.0137 | T27: 3.0137 | U27: 3.0137 | V27: 3.0986 | X27: 1.8662 | Y27: 2.0929 | Z27: 2.6449 | AA27: 2.4444 | AB27: 3.1982 | AC27: 3.0435
A28: A1_LEAN1-03_G | B28: 標準產量 | C28: 38720 | D28: 1760 | E28: 1760 | F28: 1760 | G28: 1760 | H28: 1760 | J28: 1760 | K28: 1760 | L28: 1760 | M28: 1760 | N28: 1760 | O28: 1760 | Q28: 1760 | R28: 1760 | S28: 1760 | T28: 1760 | U28: 1760 | V28: 1760 | X28: 1760 | Y28: 1760 | Z28: 1760 | AA28: 1760 | AB28: 1760 | AC28: 1760
B29: 目標產量 | C29: 34760 | D29: 1580 | E29: 1320 | F29: 1320 | G29: 1760 | H29: 1760 | J29: 1760 | K29: 1760 | L29: 1760 | M29: 1760 | N29: 1760 | O29: 1760 | Q29: 1760 | R29: 1760 | S29: 1760 | T29: 1760 | U29: 1760 | V29: 1760 | X29: 1020 | Y29: 1020 | Z29: 1360 | AA29: 1360 | AB29: 1360 | AC29: 1360 | AE29: 1360 | AF29: 1360 | AG29: 1360 | AH29: 1360 | AI29: 1360
B30: 實際產量 | C30: 35429 | D30: 1610.4091 | E30: 1328 | F30: 1332 | G30: 1760 | H30: 1760 | J30: 1760 | K30: 1760 | L30: 1760 | M30: 1760 | N30: 1763 | O30: 1760 | Q30: 1760 | R30: 1764 | S30: 1760 | T30: 1920 | U30: 1760 | V30: 1761 | X30: 1020 | Y30: 1020 | Z30: 1360 | AA30: 1361 | AB30: 1520 | AC30: 1680
B31: 差異 | C31: 669 | D31: 30.409091 | E31: 8 | F31: 12 | G31: 0 | H31: 0 | J31: 0 | K31: 0 | L31: 0 | M31: 0 | N31: 3 | O31: 0 | Q31: 0 | R31: 4 | S31: 0 | T31: 160 | U31: 0 | V31: 1 | X31: 0 | Y31: 0 | Z31: 0 | AA31: 1 | AB31: 160 | AC31: 320
B32: 工時 | C32: 176 | D32: 8 | E32: 8 | F32: 8 | G32: 8 | H32: 8 | J32: 8 | K32: 8 | L32: 8 | M32: 8 | N32: 8 | O32: 8 | Q32: 8 | R32: 8 | S32: 8 | T32: 8 | U32: 8 | V32: 8 | X32: 8 | Y32: 8 | Z32: 8 | AA32: 8 | AB32: 8 | AC32: 8
B33: 直工人數 | C33: 64 | D33: 64 | E33: 67 | F33: 66 | G33: 68 | H33: 66 | J33: 62 | K33: 67 | L33: 64 | M33: 63 | N33: 63 | O33: 63 | Q33: 65 | R33: 66 | S33: 64 | T33: 65 | U33: 64 | V33: 64 | X33: 63 | Y33: 63 | Z33: 63 | AA33: 63 | AB33: 63 | AC33: 62
B34: 時產能 | C34: 201.30114 | D34: 201.30114 | E34: 166 | F34: 166.5 | G34: 220 | H34: 220 | J34: 220 | K34: 220 | L34: 220 | M34: 220 | N34: 220.375 | O34: 220 | Q34: 220 | R34: 220.5 | S34: 220 | T34: 240 | U34: 220 | V34: 220.125 | X34: 127.5 | Y34: 127.5 | Z34: 170 | AA34: 170.125 | AB34: 190 | AC34: 210
B35: 人均時產 | C35: 3.1453 | D35: 3.1453 | E35: 2.4776 | F35: 2.5227 | G35: 3.2353 | H35: 3.3333 | J35: 3.5484 | K35: 3.2836 | L35: 3.4375 | M35: 3.4921 | N35: 3.498 | O35: 3.4921 | Q35: 3.3846 | R35: 3.3409 | S35: 3.4375 | T35: 3.6923 | U35: 3.4375 | V35: 3.4395 | X35: 2.0238 | Y35: 2.0238 | Z35: 2.6984 | AA35: 2.7004 | AB35: 3.0159 | AC35: 3.3871
A36: A1_LEAN1-04_G | B36: 標準產量 | C36: 38408 | D36: 1745.8182 | E36: 1760 | F36: 1760 | G36: 1760 | H36: 1760 | J36: 1760 | K36: 1760 | L36: 1760 | M36: 1760 | N36: 1760 | O36: 1760 | Q36: 1760 | R36: 1760 | S36: 1760 | T36: 1760 | U36: 1760 | V36: 1760 | X36: 1760 | Y36: 1760 | Z36: 1760 | AA36: 1680 | AB36: 1648 | AC36: 1640
B37: 目標產量 | C37: 35720 | D37: 1623.6364 | E37: 1680 | F37: 1680 | G37: 1320 | H37: 1320 | J37: 1760 | K37: 1760 | L37: 1760 | M37: 1760 | N37: 1760 | O37: 1760 | Q37: 1760 | R37: 1760 | S37: 1760 | T37: 1760 | U37: 1760 | V37: 1760 | X37: 1760 | Y37: 1140 | Z37: 1140 | AA37: 1520 | AB37: 1520 | AC37: 1520 | AE37: 984 | AF37: 984 | AG37: 1312 | AH37: 1312 | AI37: 1312
B38: 實際產量 | C38: 35576 | D38: 1617.0909 | E38: 1686 | F38: 1680 | G38: 1320 | H38: 1320 | J38: 1760 | K38: 1760 | L38: 1760 | M38: 1760 | N38: 1760 | O38: 1760 | Q38: 1770 | R38: 1760 | S38: 1760 | T38: 1600 | U38: 1760 | V38: 1760 | X38: 1760 | Y38: 1140 | Z38: 1140 | AA38: 1520 | AB38: 1520 | AC38: 1520
B39: 差異 | C39: -144 | D39: -6.5454545 | E39: 6 | F39: 0 | G39: 0 | H39: 0 | J39: 0 | K39: 0 | L39: 0 | M39: 0 | N39: 0 | O39: 0 | Q39: 10 | R39: 0 | S39: 0 | T39: -160 | U39: 0 | V39: 0 | X39: 0 | Y39: 0 | Z39: 0 | AA39: 0 | AB39: 0 | AC39: 0
B40: 工時 | C40: 176 | D40: 8 | E40: 8 | F40: 8 | G40: 8 | H40: 8 | J40: 8 | K40: 8 | L40: 8 | M40: 8 | N40: 8 | O40: 8 | Q40: 8 | R40: 8 | S40: 8 | T40: 8 | U40: 8 | V40: 8 | X40: 8 | Y40: 8 | Z40: 8 | AA40: 8 | AB40: 8 | AC40: 8
...

Sheet 3.5.A2廠人均時產能-成型
A1: 回到首頁
A2: 2017/03月成型人均時產能報表
A3: Lean線 | B3: 項目 | C3: 總計 | D3: 日平均 | E3: 1 | F3: 2 | G3: 3 | H3: 4 | I3: 5 | J3: 6 | K3: 7 | L3: 8 | M3: 9 | N3: 10 | O3: 11 | P3: 12 | Q3: 13 | R3: 14 | S3: 15 | T3: 16 | U3: 17 | V3: 18 | W3: 19 | X3: 20 | Y3: 21 | Z3: 22 | AA3: 23 | AB3: 24 | AC3: 25 | AD3: 26 | AE3: 27 | AF3: 28 | AG3: 29 | AH3: 30 | AI3: 31
A4: 總計 | B4: 標準產量 | C4: 611312 | D4: 29110.095 | E4: 29712 | F4: 29984 | G4: 29896 | H4: 29776 | J4: 30040 | K4: 30200 | L4: 30000 | M4: 29960 | N4: 29920 | O4: 29920 | Q4: 29576 | R4: 29128 | S4: 29016 | T4: 28320 | U4: 28512 | V4: 28320 | X4: 28160 | Y4: 27960 | Z4: 27632 | AA4: 27664 | AB4: 27616
B5: 目標產量 | C5: 561740 | D5: 26749.524 | E5: 27860 | F5: 26750 | G5: 27790 | H5: 28520 | J5: 28520 | K5: 28520 | L5: 28520 | M5: 28000 | N5: 28440 | O5: 27200 | Q5: 26300 | R5: 27000 | S5: 24620 | T5: 25380 | U5: 26520 | V5: 26020 | X5: 25360 | Y5: 24340 | Z5: 24870 | AA5: 25210 | AB5: 26000 | AC5: 25440 | AE5: 25840 | AF5: 24990 | AG5: 24470 | AH5: 24480 | AI5: 24640
B6: 實際產量 | C6: 559638 | D6: 26649.429 | E6: 27860 | F6: 26864 | G6: 27570 | H6: 28474 | J6: 28520 | K6: 28520 | L6: 28522 | M6: 26520 | N6: 28104 | O6: 27031 | Q6: 26680 | R6: 26960 | S6: 24388 | T6: 25136 | U6: 26510 | V6: 26079 | X6: 25430 | Y6: 24519 | Z6: 24875 | AA6: 25534 | AB6: 25542
B7: 差異 | C7: -2102 | D7: -100.09524 | E7: 0 | F7: 114 | G7: -220 | H7: -46 | J7: 0 | K7: 0 | L7: 2 | M7: -1480 | N7: -336 | O7: -169 | Q7: 380 | R7: -40 | S7: -232 | T7: -244 | U7: -10 | V7: 59 | X7: 70 | Y7: 179 | Z7: 5 | AA7: 324 | AB7: -458
B8: 工時 | C8: 168 | D8: 8 | E8: 8 | F8: 8 | G8: 8 | H8: 8 | J8: 8 | K8: 8 | L8: 8 | M8: 8 | N8: 8 | O8: 8 | Q8: 8 | R8: 8 | S8: 8 | T8: 8 | U8: 8 | V8: 8 | X8: 8 | Y8: 8 | Z8: 8 | AA8: 8 | AB8: 8
B9: 直工人數 | C9: 1179 | D9: 1179 | E9: 1186 | F9: 1186 | G9: 1192 | H9: 1174 | J9: 1162 | K9: 1174 | L9: 1175 | M9: 1178 | N9: 1184 | O9: 1191 | Q9: 1188 | R9: 1198 | S9: 1196 | T9: 1187 | U9: 1182 | V9: 1180 | X9: 1175 | Y9: 1175 | Z9: 1193 | AA9: 1196 | AB9: 1190
B10: 時產能 | C10: 3331.1786 | D10: 3331.1786 | E10: 3482.5 | F10: 3358 | G10: 3446.25 | H10: 3559.25 | J10: 3565 | K10: 3565 | L10: 3565.25 | M10: 3315 | N10: 3513 | O10: 3378.875 | Q10: 3335 | R10: 3370 | S10: 3048.5 | T10: 3142 | U10: 3313.75 | V10: 3259.875 | X10: 3178.75 | Y10: 3064.875 | Z10: 3109.375 | AA10: 3191.75 | AB10: 3192.75
B11: 人均時產 | C11: 2.8254271 | D11: 2.8254271 | E11: 2.9363406 | F11: 2.8313659 | G11: 2.8911493 | H11: 3.0317291 | J11: 3.0679862 | K11: 3.0366269 | L11: 3.0342553 | M11: 2.8140917 | N11: 2.9670608 | O11: 2.8370067 | Q11: 2.8072391 | R11: 2.8130217 | S11: 2.548913 | T11: 2.6470093 | U11: 2.803511 | V11: 2.7626059 | X11: 2.7053191 | Y11: 2.6084043 | Z11: 2.6063495 | AA11: 2.6686873 | AB11: 2.6829832
A12: A2_LEAN1-01_G | B12: 標準產量 | C12: 36184 | D12: 1723.0476 | E12: 1760 | F12: 1760 | G12: 1760 | H12: 1760 | J12: 1760 | K12: 1760 | L12: 1760 | M12: 1760 | N12: 1760 | O12: 1760 | Q12: 1760 | R12: 1760 | S12: 1760 | T12: 1704 | U12: 1696 | V12: 1680 | X12: 1680 | Y12: 1680 | Z12: 1504 | AA12: 1680 | AB12: 1680
B13: 目標產量 | C13: 30920 | D13: 1472.381 | E13: 1520 | F13: 1520 | G13: 1520 | H13: 1520 | J13: 1520 | K13: 1520 | L13: 1520 | M13: 1520 | N13: 1520 | O13: 1520 | Q13: 1520 | R13: 1520 | S13: 1520 | T13: 1080 | U13: 1440 | V13: 1440 | X13: 1440 | Y13: 1440 | Z13: 1440 | AA13: 1440 | AB13: 1440 | AC13: 1440 | AE13: 1440 | AF13: 1440 | AG13: 1440 | AH13: 1440 | AI13: 1440
B14: 實際產量 | C14: 31466 | D14: 1498.381 | E14: 1520 | F14: 1520 | G14: 1600 | H14: 1520 | J14: 1520 | K14: 1740 | L14: 1520 | M14: 1520 | N14: 1520 | O14: 1520 | Q14: 1520 | R14: 1520 | S14: 1520 | T14: 1280 | U14: 1440 | V14: 1486 | X14: 1440 | Y14: 1440 | Z14: 1440 | AA14: 1440 | AB14: 1440
B15: 差異 | C15: 546 | D15: 26 | E15: 0 | F15: 0 | G15: 80 | H15: 0 | J15: 0 | K15: 220 | L15: 0 | M15: 0 | N15: 0 | O15: 0 | Q15: 0 | R15: 0 | S15: 0 | T15: 200 | U15: 0 | V15: 46 | X15: 0 | Y15: 0 | Z15: 0 | AA15: 0 | AB15: 0
