Workbook

Sheet US PL
A1: [Vendor Name]
A2: [Vendor Address]
A3: [Vendor Contact]
A4: PACKING LIST
A6: COMMODITY: | E6: FOOTWEAR | M6: Actual Ship Date:
A7: SHIP TO COUNTRY: USA | M7: INVOICE NO.:
M8: PO#:
A9: UGG F18 Sale Sample - Goleta
A11: C/NO. | D11: CTNS | E11: STYLE NO. | F11: STYLE NAME | G11: COLOR | H11: SIZE | I11: QTY LEFT (Units) | J11: QTY RIGHT (Units) | K11: TOTAL QTY (Units) | L11: N.W. (KG) (Units) | M11: N.W. (KG) (Carton) | O11: G.W. (KG) (Carton) | Q11: DIM. (CM) | S11: CBM
A12: 1 | B12: - | C12: 5 | D12: 1 | E12: SMF1032 | F12: Pick Pocket | G12: Tan | H12: M's 9# | K12: =I12+J12 -> 0 | M12: =O12-1 -> 6.2 | O12: 7.2 | Q12: 48*48*32 | S12: =0.48*0.48*0.32 -> 0.073728
E13: SMF10137 | F13: Kingston Jute | G13: Natural | H13: M's 9#
E14: SMF10561 | F14: You Got My Back 2 Basics | G14: Camo | H14: M's 9#
E15: SMF10561 | F15: You Got My Back 2 Basics | G15: Dark Brown | H15: M's 9#
E16: SMF10738 | F16: Vagabond Blades | G16: Mossy Oak | H16: M's 9#
E17: SMS10047 | F17: Block Party | G17: Rasta | H17: M's 9#
E18: SMS10412 | F18: Beer Cozy Light | G18: White | H18: M's 9#
A19: 2 | B19: - | C19: 5 | D19: 1 | E19: SMS10544 | F19: Jet Stream | G19: Black | H19: M's 9# | M19: =O19-1 -> 6.4 | O19: 7.4 | Q19: 55*48*32 | S19: =0.55*0.48*0.32 -> 0.08448
E20: SMS10544 | F20: Jet Stream | G20: Brown | H20: M's 9#
E21: SMS10544 | F21: Jet Stream | G21: Grey / Grey | H21: M's 9#
E22: SMS10545 | F22: Camelion | G22: Galaxy | H22: M's 9#
E23: SMS10545 | F23: Camelion | G23: Red Tribal | H23: M's 9#
E24: SMS10545 | F24: Camelion | G24: Washed Camo | H24: M's 9#
E25: SMS10546 | F25: Tarzan Classic | G25: Leopard | H25: M's 9#
E26: SMS10546 | F26: Tarzan Classic | G26: Multi Blanket Stripes | H26: M's 9#
A27: 3 | B27: - | C27: 5 | D27: 1 | E27: SMS10547 | F27: Fur Real Classic | G27: Green | H27: M's 9# | M27: =O27-1 -> 6.3 | O27: 7.3 | Q27: 48*48*32 | S27: =0.48*0.48*0.32 -> 0.073728
E28: SMS10548 | F28: Beer Cozy Primo Light | G28: Brown / Tan | H28: M's 9#
E29: SMS10548 | F29: Beer Cozy Primo Light | G29: Camo / Dark Brown | H29: M's 9#
E30: SMS10548 | F30: Beer Cozy Primo Light | G30: Dark Brown / Brown | H30: M's 9#
E31: SMS10549 | F31: Beer Cozy Light Funk | G31: Black | H31: M's 9#
E32: SMS10549 | F32: Beer Cozy Light Funk | G32: Charcoal | H32: M's 9#
E33: SMS10549 | F33: Beer Cozy Light Funk | G33: Tan | H33: M's 9#
A34: 4 | B34: - | C34: 5 | D34: 1 | E34: SMS10553 | F34: Dr. Fray | G34: Brown | H34: M's 9# | M34: =O34-1 -> 6.5 | O34: 7.5 | Q34: 48*48*32 | S34: =0.48*0.48*0.32 -> 0.073728
E35: SMS10553 | F35: Dr. Fray | G35: Coal | H35: M's 9#
E36: SMS10553 | F36: Dr. Fray | G36: Slate Blue | H36: M's 9#
E37: SMS10553 | F37: Dr. Fray | G37: Tan | H37: M's 9#
E38: SMS10624 | F38: Vineyard | G38: Black | H38: M's 9#
E39: SMS10624 | F39: Vineyard | G39: Dark Brown | H39: M's 9#
E40: SMS10624 | F40: Vineyard | G40: Natural | H40: M's 9#
A41: 5 | B41: - | C41: 5 | D41: 1 | E41: SMS10644 | F41: High Tide | G41: Black | H41: M's 9# | M41: =O41-1 -> 6.65 | O41: 7.65 | Q41: 55*48*32 | S41: =0.55*0.48*0.32 -> 0.08448
E42: SMS10644 | F42: High Tide | G42: Brown | H42: M's 9#
...

Sheet US Pair (Footwear)
A1: [Vendor Name]
A2: [Vendor Address] + [Vendor Contact]
A4: Commercial Invoice
A5: Sold To: | D5: Ship To:
A6: DECKERS OUTDOOR CORPORATION | C6: Company Name | D6: See Brand Shipping file | G6: Invoice No.: | H6: Factory Invoice number
A7: 250 Coromar Dr. | C7: Attention | G7: Actual Ship Date: | H7: =TODAY() -> 45726
A8: Goleta, CA, 93117 | C8: Ship To Address | G8: PO Name: | H8: UGG F21 Inline
A9: United Sates | G9: PO Header: | H9: Sales Meeting
A10: IOR # 95-301586200 | G10: Currency: | H10: USD
A11: Brokerage Account - UPS 20A33X | G11: PO#: | H11: PO Number from PO
A13: Style Name | B13: Style No. | C13: HTS Code | D13: Color | E13: Size | F13: TOTAL QTY (Piece) | G13: Unit Price (Piece) (USD) | H13: Amount (USD)
C14: 9811.00.60 | H14: =F14*G14 -> 0
C15: 9811.00.60 | H15: =F15*G15 -> 0
C16: 9811.00.60 | H16: =F16*G16 -> 0
C17: 9811.00.60 | H17: =F17*G17 -> 0
C18: 9811.00.60 | H18: =F18*G18 -> 0
C19: 9811.00.60 | H19: =F19*G19 -> 0
C20: 9811.00.60 | H20: =F20*G20 -> 0
C21: 9811.00.60 | H21: =F21*G21 -> 0
C22: 9811.00.60 | H22: =F22*G22 -> 0
C23: 9811.00.60 | H23: =F23*G23 -> 0
C24: 9811.00.60 | H24: =F24*G24 -> 0
C25: 9811.00.60 | H25: =F25*G25 -> 0
... C30: 9811.00.60 | H30: =F30*G30 -> 0
A32: TOTAL | F32: =SUM(F14:F30) -> 0 | H32: =SUM(H14:H30) -> 0
A34: SAY TOTAL US DOLLARS ********* ONLY
A36: Description of goods: | B36: PO Name - Footwear Samples
A38: Shipping marks : | B38: As per packing list
A40: Product type: | B40: SAMPLES OF NO COMMERCIAL VALUE; HTS CODE 9811.00.60; NOT FOR SALE; PRICE IS FOR CUSTOMS USE ONLY.
B41: THIS SHIPMENT IS FREE FROM SOLID WOOD PACKING MATERIALS.
B42: THESE ARE CLEARED TO FREE CIRCULATION.
A44: Country of Origin: | B44: COO
A46: Shipped by: | B46: UPS
A48: AWB#: | B48: Tracking Number

Sheet INV
A1: YIH SHUO FOOTWEAR CO., LTD
A2: RESIDENTIAL AREA 1, MY AN TOWNLET, THAP MUOI DISTRICT, DONG THAP PROVINCE, VIETNAM
A3: TEL#: 02773 940 888
A5: Invoice
A7: For account and risk of messers: FLOURISH THRIVE DEVELOPMENTS LIMITED TAIWAN BRANCH
B8: 5 F, No.13, Ln.370, Sec.4, YaTan Rd., Daya Dist., Taichung City, Taiwan
D9: Ship To:
D10: Company Name: | G10: Invoice No.:
D11: Attention: | G11: Date:
D12: Ship To Address: | G12: PO Name:
G13: Order:
G14: Currency: | K14: USD
G15: PO#:
A17: HTS Code | B17: RY# | C17: Style Name | D17: Style No. | E17: Color | F17: COLOR CODE | G17: Size | H17: QTY LEFT (Piece) | I17: QTY RIGHT (Piece) | J17: TOTAL QTY (Piece) | K17: TOTAL QTY (Pair) | L17: Unit Price (Pairs) (USD) | M17: Amount (USD)
A19: TOTAL | K19: =SUM(K18:K18) -> 0 | M19: =SUM(M18:M18) -> 0
G22: YIH SHUO FOOTWEAR CO., LTD
G23: MANAGER
A24: Description of goods:
A26: Shipping marks : | C26: As per packing list
A28: Country of Origin: | C28: VIETNAM
A30: Shipped by: | G30: PHAN THỊ QUYẾN

Sheet PKL
A1: =INV!A1:M1 -> YIH SHUO FOOTWEAR CO., LTD
A2: =INV!A2:M2 -> RESIDENTIAL AREA 1, MY AN TOWNLET, THAP MUOI DISTRICT, DONG THAP PROVINCE, VIETNAM
A3: =INV!A3:M3 -> TEL#: 02773 940 888
A5: PACKING LIST
A7: For account and risk of messers: FLOURISH THRIVE DEVELOPMENTS LIMITED TAIWAN BRANCH | P7: Invoice No.: | R7: =INV!K10 -> 0
A8: COMMODITY: Footwear | P8: Date: | R8: =INV!K11 -> 0
A9: SHIP TO COUNTRY: UNITED STATES | P9: PO#: | R9: =INV!K15 -> 0
A11: =INV!K12&"-"&INV!K13 -> -
A13: C/NO. | D13: CTNS | E13: RY# | F13: STYLE NO. | G13: STYLE NAME | H13: COLOR | I13: COLOR CODE | J13: SIZE | K13: QTY LEFT (Units) | L13: QTY RIGHT (Units) | M13: TOTAL QTY (Pieces) | N13: TOTAL QTY (Pair) | O13: Qty per Carton | P13: N.W. (KG) (Pair) | Q13: N.W. (KG) (Carton) | R13: G.W. (KG) (Carton) | S13: DIM. (CM) | V13: CBM
S14: L | T14: W | U14: H
A16: TOTAL:
Q18: YIH SHUO FOOTWEAR CO., LTD
Q19: MANAGER
Q26: PHAN THỊ QUYẾN

Sheet International PL
A1: [Vendor Name]
A2: [Vendor Address]
A3: [Vendor Contact]
A5: PACKING LIST
A7: COMMODITY: | E7: FOOTWEAR | M7: Actual Ship Date:
A8: SHIP TO COUNTRY: | M8: INVOICE NO.:
M9: PO#:
A10: UGG F18 Global Sample PO - Deckers HK
A12: C/NO. | D12: CTNS | E12: STYLE NO. | F12: STYLE NAME | G12: COLOR | H12: SIZE | I12: QTY LEFT (Units) | J12: QTY RIGHT (Units) | K12: TOTAL QTY (Units) | L12: N.W. (KG) (Units) | M12: N.W. (KG) (Carton) | O12: G.W. (KG) (Carton) | Q12: DIM. (CM) | S12: CBM
A13: 1 | B13: - | C13: 5 | D13: 1 | E13: SMF1032 | F13: Pick Pocket | G13: Tan | H13: M's 9# | K13: =I13+J13 -> 0 | M13: =O13-1 -> 6.2 | O13: 7.2 | Q13: 48*48*32 | S13: =0.48*0.48*0.32 -> 0.073728
E14: SMF10137 | F14: Kingston Jute | G14: Natural | H14: M's 9#
E15: SMF10561 | F15: You Got My Back 2 Basics | G15: Camo | H15: M's 9#
E16: SMF10561 | F16: You Got My Back 2 Basics | G16: Dark Brown | H16: M's 9#
E17: SMF10738 | F17: Vagabond Blades | G17: Mossy Oak | H17: M's 9#
E18: SMS10047 | F18: Block Party | G18: Rasta | H18: M's 9#
E19: SMS10412 | F19: Beer Cozy Light | G19: White | H19: M's 9#
A20: 2 | B20: - | C20: 5 | D20: 1 | E20: SMS10544 | F20: Jet Stream | G20: Black | H20: M's 9# | M20: =O20-1 -> 6.4 | O20: 7.4 | Q20: 55*48*32 | S20: =0.55*0.48*0.32 -> 0.08448
E21: SMS10544 | F21: Jet Stream | G21: Brown | H21: M's 9#
E22: SMS10544 | F22: Jet Stream | G22: Grey / Grey | H22: M's 9#
E23: SMS10545 | F23: Camelion | G23: Galaxy | H23: M's 9#
E24: SMS10545 | F24: Camelion | G24: Red Tribal | H24: M's 9#
E25: SMS10545 | F25: Camelion | G25: Washed Camo | H25: M's 9#
E26: SMS10546 | F26: Tarzan Classic | G26: Leopard | H26: M's 9#
E27: SMS10546 | F27: Tarzan Classic | G27: Multi Blanket Stripes | H27: M's 9#
A28: 3 | B28: - | C28: 5 | D28: 1 | E28: SMS10547 | F28: Fur Real Classic | G28: Green | H28: M's 9# | M28: =O28-1 -> 6.3 | O28: 7.3 | Q28: 48*48*32 | S28: =0.48*0.48*0.32 -> 0.073728
E29: SMS10548 | F29: Beer Cozy Primo Light | G29: Brown / Tan | H29: M's 9#
E30: SMS10548 | F30: Beer Cozy Primo Light | G30: Camo / Dark Brown | H30: M's 9#
E31: SMS10548 | F31: Beer Cozy Primo Light | G31: Dark Brown / Brown | H31: M's 9#
E32: SMS10549 | F32: Beer Cozy Light Funk | G32: Black | H32: M's 9#
E33: SMS10549 | F33: Beer Cozy Light Funk | G33: Charcoal | H33: M's 9#
E34: SMS10549 | F34: Beer Cozy Light Funk | G34: Tan | H34: M's 9#
A35: 4 | B35: - | C35: 5 | D35: 1 | E35: SMS10553 | F35: Dr. Fray | G35: Brown | H35: M's 9# | M35: =O35-1 -> 6.5 | O35: 7.5 | Q35: 48*48*32 | S35: =0.48*0.48*0.32 -> 0.073728
E36: SMS10553 | F36: Dr. Fray | G36: Coal | H36: M's 9#
E37: SMS10553 | F37: Dr. Fray | G37: Slate Blue | H37: M's 9#
E38: SMS10553 | F38: Dr. Fray | G38: Tan | H38: M's 9#
E39: SMS10624 | F39: Vineyard | G39: Black | H39: M's 9#
E40: SMS10624 | F40: Vineyard | G40: Dark Brown | H40: M's 9#
E41: SMS10624 | F41: Vineyard | G41: Natural | H41: M's 9#
A42: 5 | B42: - | C42: 5 | D42: 1 | E42: SMS10644 | F42: High Tide | G42: Black | H42: M's 9# | M42: =O42-1 -> 6.65 | O42: 7.65 | Q42: 55*48*32 | S42: =0.55*0.48*0.32 -> 0.08448
E43: SMS10644 | F43: High Tide | G43: Brown | H43: M's 9#
...

Sheet EMEA CI

Sheet EMEA PL
